2024-12-06 15:35:50,524 - telegram.ext.Application - ERROR - No error handlers are registered, logging exception.
Traceback (most recent call last):
  File "/Users/admin/Library/Python/3.9/lib/python/site-packages/telegram/ext/_updater.py", line 607, in _network_loop_retry
    if not await action_cb():
  File "/Users/admin/Library/Python/3.9/lib/python/site-packages/telegram/ext/_updater.py", line 335, in polling_action_cb
    raise exc
  File "/Users/admin/Library/Python/3.9/lib/python/site-packages/telegram/ext/_updater.py", line 320, in polling_action_cb
    updates = await self.bot.get_updates(
  File "/Users/admin/Library/Python/3.9/lib/python/site-packages/telegram/ext/_extbot.py", line 543, in get_updates
    updates = await super().get_updates(
  File "/Users/admin/Library/Python/3.9/lib/python/site-packages/telegram/_bot.py", line 381, in decorator
    result = await func(self, *args, **kwargs)  # skipcq: PYL-E1102
  File "/Users/admin/Library/Python/3.9/lib/python/site-packages/telegram/_bot.py", line 3661, in get_updates
    await self._post(
  File "/Users/admin/Library/Python/3.9/lib/python/site-packages/telegram/_bot.py", line 469, in _post
    return await self._do_post(
  File "/Users/admin/Library/Python/3.9/lib/python/site-packages/telegram/ext/_extbot.py", line 325, in _do_post
    return await super()._do_post(
  File "/Users/admin/Library/Python/3.9/lib/python/site-packages/telegram/_bot.py", line 497, in _do_post
    return await request.post(
  File "/Users/admin/Library/Python/3.9/lib/python/site-packages/telegram/request/_baserequest.py", line 168, in post
    result = await self._request_wrapper(
  File "/Users/admin/Library/Python/3.9/lib/python/site-packages/telegram/request/_baserequest.py", line 330, in _request_wrapper
    raise Conflict(message)
telegram.error.Conflict: Conflict: terminated by other getUpdates request; make sure that only one bot instance is running
2024-12-06 15:36:24,418 - telegram.ext.Updater - ERROR - Error while getting Updates: Conflict: terminated by other getUpdates request; make sure that only one bot instance is running
2024-12-06 15:36:24,418 - telegram.ext.Application - ERROR - No error handlers are registered, logging exception.
Traceback (most recent call last):
  File "/Users/admin/Library/Python/3.9/lib/python/site-packages/telegram/ext/_updater.py", line 607, in _network_loop_retry
    if not await action_cb():
  File "/Users/admin/Library/Python/3.9/lib/python/site-packages/telegram/ext/_updater.py", line 335, in polling_action_cb
    raise exc
  File "/Users/admin/Library/Python/3.9/lib/python/site-packages/telegram/ext/_updater.py", line 320, in polling_action_cb
    updates = await self.bot.get_updates(
  File "/Users/admin/Library/Python/3.9/lib/python/site-packages/telegram/ext/_extbot.py", line 543, in get_updates
    updates = await super().get_updates(
  File "/Users/admin/Library/Python/3.9/lib/python/site-packages/telegram/_bot.py", line 381, in decorator
    result = await func(self, *args, **kwargs)  # skipcq: PYL-E1102
  File "/Users/admin/Library/Python/3.9/lib/python/site-packages/telegram/_bot.py", line 3661, in get_updates
    await self._post(
  File "/Users/admin/Library/Python/3.9/lib/python/site-packages/telegram/_bot.py", line 469, in _post
    return await self._do_post(
  File "/Users/admin/Library/Python/3.9/lib/python/site-packages/telegram/ext/_extbot.py", line 325, in _do_post
    return await super()._do_post(
  File "/Users/admin/Library/Python/3.9/lib/python/site-packages/telegram/_bot.py", line 497, in _do_post
    return await request.post(
  File "/Users/admin/Library/Python/3.9/lib/python/site-packages/telegram/request/_baserequest.py", line 168, in post
    result = await self._request_wrapper(
  File "/Users/admin/Library/Python/3.9/lib/python/site-packages/telegram/request/_baserequest.py", line 330, in _request_wrapper
    raise Conflict(message)
telegram.error.Conflict: Conflict: terminated by other getUpdates request; make sure that only one bot instance is running
2024-12-06 15:36:58,317 - telegram.ext.Updater - ERROR - Error while getting Updates: Conflict: terminated by other getUpdates request; make sure that only one bot instance is running
2024-12-06 15:36:58,318 - telegram.ext.Application - ERROR - No error handlers are registered, logging exception.
Traceback (most recent call last):
  File "/Users/admin/Library/Python/3.9/lib/python/site-packages/telegram/ext/_updater.py", line 607, in _network_loop_retry
    if not await action_cb():
  File "/Users/admin/Library/Python/3.9/lib/python/site-packages/telegram/ext/_updater.py", line 335, in polling_action_cb
    raise exc
  File "/Users/admin/Library/Python/3.9/lib/python/site-packages/telegram/ext/_updater.py", line 320, in polling_action_cb
    updates = await self.bot.get_updates(
  File "/Users/admin/Library/Python/3.9/lib/python/site-packages/telegram/ext/_extbot.py", line 543, in get_updates
    updates = await super().get_updates(
  File "/Users/admin/Library/Python/3.9/lib/python/site-packages/telegram/_bot.py", line 381, in decorator
    result = await func(self, *args, **kwargs)  # skipcq: PYL-E1102
  File "/Users/admin/Library/Python/3.9/lib/python/site-packages/telegram/_bot.py", line 3661, in get_updates
    await self._post(
  File "/Users/admin/Library/Python/3.9/lib/python/site-packages/telegram/_bot.py", line 469, in _post
    return await self._do_post(
  File "/Users/admin/Library/Python/3.9/lib/python/site-packages/telegram/ext/_extbot.py", line 325, in _do_post
    return await super()._do_post(
  File "/Users/admin/Library/Python/3.9/lib/python/site-packages/telegram/_bot.py", line 497, in _do_post
    return await request.post(
  File "/Users/admin/Library/Python/3.9/lib/python/site-packages/telegram/request/_baserequest.py", line 168, in post
    result = await self._request_wrapper(
  File "/Users/admin/Library/Python/3.9/lib/python/site-packages/telegram/request/_baserequest.py", line 330, in _request_wrapper
    raise Conflict(message)
telegram.error.Conflict: Conflict: terminated by other getUpdates request; make sure that only one bot instance is running
2024-12-06 15:37:32,249 - telegram.ext.Updater - ERROR - Error while getting Updates: Conflict: terminated by other getUpdates request; make sure that only one bot instance is running
2024-12-06 15:37:32,250 - telegram.ext.Application - ERROR - No error handlers are registered, logging exception.
Traceback (most recent call last):
  File "/Users/admin/Library/Python/3.9/lib/python/site-packages/telegram/ext/_updater.py", line 607, in _network_loop_retry
    if not await action_cb():
  File "/Users/admin/Library/Python/3.9/lib/python/site-packages/telegram/ext/_updater.py", line 335, in polling_action_cb
    raise exc
  File "/Users/admin/Library/Python/3.9/lib/python/site-packages/telegram/ext/_updater.py", line 320, in polling_action_cb
    updates = await self.bot.get_updates(
  File "/Users/admin/Library/Python/3.9/lib/python/site-packages/telegram/ext/_extbot.py", line 543, in get_updates
    updates = await super().get_updates(
  File "/Users/admin/Library/Python/3.9/lib/python/site-packages/telegram/_bot.py", line 381, in decorator
    result = await func(self, *args, **kwargs)  # skipcq: PYL-E1102
  File "/Users/admin/Library/Python/3.9/lib/python/site-packages/telegram/_bot.py", line 3661, in get_updates
    await self._post(
  File "/Users/admin/Library/Python/3.9/lib/python/site-packages/telegram/_bot.py", line 469, in _post
    return await self._do_post(
  File "/Users/admin/Library/Python/3.9/lib/python/site-packages/telegram/ext/_extbot.py", line 325, in _do_post
    return await super()._do_post(
  File "/Users/admin/Library/Python/3.9/lib/python/site-packages/telegram/_bot.py", line 497, in _do_post
    return await request.post(
  File "/Users/admin/Library/Python/3.9/lib/python/site-packages/telegram/request/_baserequest.py", line 168, in post
    result = await self._request_wrapper(
  File "/Users/admin/Library/Python/3.9/lib/python/site-packages/telegram/request/_baserequest.py", line 330, in _request_wrapper
    raise Conflict(message)
telegram.error.Conflict: Conflict: terminated by other getUpdates request; make sure that only one bot instance is running
2024-12-06 15:38:06,859 - telegram.ext.Updater - ERROR - Error while getting Updates: Conflict: terminated by other getUpdates request; make sure that only one bot instance is running
2024-12-06 15:38:06,859 - telegram.ext.Application - ERROR - No error handlers are registered, logging exception.
Traceback (most recent call last):
  File "/Users/admin/Library/Python/3.9/lib/python/site-packages/telegram/ext/_updater.py", line 607, in _network_loop_retry
    if not await action_cb():
  File "/Users/admin/Library/Python/3.9/lib/python/site-packages/telegram/ext/_updater.py", line 335, in polling_action_cb
    raise exc
  File "/Users/admin/Library/Python/3.9/lib/python/site-packages/telegram/ext/_updater.py", line 320, in polling_action_cb
    updates = await self.bot.get_updates(
  File "/Users/admin/Library/Python/3.9/lib/python/site-packages/telegram/ext/_extbot.py", line 543, in get_updates
    updates = await super().get_updates(
  File "/Users/admin/Library/Python/3.9/lib/python/site-packages/telegram/_bot.py", line 381, in decorator
    result = await func(self, *args, **kwargs)  # skipcq: PYL-E1102
  File "/Users/admin/Library/Python/3.9/lib/python/site-packages/telegram/_bot.py", line 3661, in get_updates
    await self._post(
  File "/Users/admin/Library/Python/3.9/lib/python/site-packages/telegram/_bot.py", line 469, in _post
    return await self._do_post(
  File "/Users/admin/Library/Python/3.9/lib/python/site-packages/telegram/ext/_extbot.py", line 325, in _do_post
    return await super()._do_post(
  File "/Users/admin/Library/Python/3.9/lib/python/site-packages/telegram/_bot.py", line 497, in _do_post
    return await request.post(
  File "/Users/admin/Library/Python/3.9/lib/python/site-packages/telegram/request/_baserequest.py", line 168, in post
    result = await self._request_wrapper(
  File "/Users/admin/Library/Python/3.9/lib/python/site-packages/telegram/request/_baserequest.py", line 330, in _request_wrapper
    raise Conflict(message)
telegram.error.Conflict: Conflict: terminated by other getUpdates request; make sure that only one bot instance is running
2024-12-06 15:38:41,572 - telegram.ext.Updater - ERROR - Error while getting Updates: Conflict: terminated by other getUpdates request; make sure that only one bot instance is running
2024-12-06 15:38:41,572 - telegram.ext.Application - ERROR - No error handlers are registered, logging exception.
Traceback (most recent call last):
  File "/Users/admin/Library/Python/3.9/lib/python/site-packages/telegram/ext/_updater.py", line 607, in _network_loop_retry
    if not await action_cb():
  File "/Users/admin/Library/Python/3.9/lib/python/site-packages/telegram/ext/_updater.py", line 335, in polling_action_cb
    raise exc
  File "/Users/admin/Library/Python/3.9/lib/python/site-packages/telegram/ext/_updater.py", line 320, in polling_action_cb
    updates = await self.bot.get_updates(
  File "/Users/admin/Library/Python/3.9/lib/python/site-packages/telegram/ext/_extbot.py", line 543, in get_updates
    updates = await super().get_updates(
  File "/Users/admin/Library/Python/3.9/lib/python/site-packages/telegram/_bot.py", line 381, in decorator
    result = await func(self, *args, **kwargs)  # skipcq: PYL-E1102
  File "/Users/admin/Library/Python/3.9/lib/python/site-packages/telegram/_bot.py", line 3661, in get_updates
    await self._post(
  File "/Users/admin/Library/Python/3.9/lib/python/site-packages/telegram/_bot.py", line 469, in _post
    return await self._do_post(
  File "/Users/admin/Library/Python/3.9/lib/python/site-packages/telegram/ext/_extbot.py", line 325, in _do_post
    return await super()._do_post(
  File "/Users/admin/Library/Python/3.9/lib/python/site-packages/telegram/_bot.py", line 497, in _do_post
    return await request.post(
  File "/Users/admin/Library/Python/3.9/lib/python/site-packages/telegram/request/_baserequest.py", line 168, in post
    result = await self._request_wrapper(
  File "/Users/admin/Library/Python/3.9/lib/python/site-packages/telegram/request/_baserequest.py", line 330, in _request_wrapper
    raise Conflict(message)
telegram.error.Conflict: Conflict: terminated by other getUpdates request; make sure that only one bot instance is running
2024-12-06 15:39:16,126 - telegram.ext.Updater - ERROR - Error while getting Updates: Conflict: terminated by other getUpdates request; make sure that only one bot instance is running
2024-12-06 15:39:16,126 - telegram.ext.Application - ERROR - No error handlers are registered, logging exception.
Traceback (most recent call last):
  File "/Users/admin/Library/Python/3.9/lib/python/site-packages/telegram/ext/_updater.py", line 607, in _network_loop_retry
    if not await action_cb():
  File "/Users/admin/Library/Python/3.9/lib/python/site-packages/telegram/ext/_updater.py", line 335, in polling_action_cb
    raise exc
  File "/Users/admin/Library/Python/3.9/lib/python/site-packages/telegram/ext/_updater.py", line 320, in polling_action_cb
    updates = await self.bot.get_updates(
  File "/Users/admin/Library/Python/3.9/lib/python/site-packages/telegram/ext/_extbot.py", line 543, in get_updates
    updates = await super().get_updates(
  File "/Users/admin/Library/Python/3.9/lib/python/site-packages/telegram/_bot.py", line 381, in decorator
    result = await func(self, *args, **kwargs)  # skipcq: PYL-E1102
  File "/Users/admin/Library/Python/3.9/lib/python/site-packages/telegram/_bot.py", line 3661, in get_updates
    await self._post(
  File "/Users/admin/Library/Python/3.9/lib/python/site-packages/telegram/_bot.py", line 469, in _post
    return await self._do_post(
  File "/Users/admin/Library/Python/3.9/lib/python/site-packages/telegram/ext/_extbot.py", line 325, in _do_post
    return await super()._do_post(
  File "/Users/admin/Library/Python/3.9/lib/python/site-packages/telegram/_bot.py", line 497, in _do_post
    return await request.post(
  File "/Users/admin/Library/Python/3.9/lib/python/site-packages/telegram/request/_baserequest.py", line 168, in post
    result = await self._request_wrapper(
  File "/Users/admin/Library/Python/3.9/lib/python/site-packages/telegram/request/_baserequest.py", line 330, in _request_wrapper
    raise Conflict(message)
telegram.error.Conflict: Conflict: terminated by other getUpdates request; make sure that only one bot instance is running
2024-12-06 15:39:50,299 - telegram.ext.Updater - ERROR - Error while getting Updates: Conflict: terminated by other getUpdates request; make sure that only one bot instance is running
2024-12-06 15:39:50,300 - telegram.ext.Application - ERROR - No error handlers are registered, logging exception.
Traceback (most recent call last):
  File "/Users/admin/Library/Python/3.9/lib/python/site-packages/telegram/ext/_updater.py", line 607, in _network_loop_retry
    if not await action_cb():
  File "/Users/admin/Library/Python/3.9/lib/python/site-packages/telegram/ext/_updater.py", line 335, in polling_action_cb
    raise exc
  File "/Users/admin/Library/Python/3.9/lib/python/site-packages/telegram/ext/_updater.py", line 320, in polling_action_cb
    updates = await self.bot.get_updates(
  File "/Users/admin/Library/Python/3.9/lib/python/site-packages/telegram/ext/_extbot.py", line 543, in get_updates
    updates = await super().get_updates(
  File "/Users/admin/Library/Python/3.9/lib/python/site-packages/telegram/_bot.py", line 381, in decorator
    result = await func(self, *args, **kwargs)  # skipcq: PYL-E1102
  File "/Users/admin/Library/Python/3.9/lib/python/site-packages/telegram/_bot.py", line 3661, in get_updates
    await self._post(
  File "/Users/admin/Library/Python/3.9/lib/python/site-packages/telegram/_bot.py", line 469, in _post
    return await self._do_post(
  File "/Users/admin/Library/Python/3.9/lib/python/site-packages/telegram/ext/_extbot.py", line 325, in _do_post
    return await super()._do_post(
  File "/Users/admin/Library/Python/3.9/lib/python/site-packages/telegram/_bot.py", line 497, in _do_post
    return await request.post(
  File "/Users/admin/Library/Python/3.9/lib/python/site-packages/telegram/request/_baserequest.py", line 168, in post
    result = await self._request_wrapper(
  File "/Users/admin/Library/Python/3.9/lib/python/site-packages/telegram/request/_baserequest.py", line 330, in _request_wrapper
    raise Conflict(message)
telegram.error.Conflict: Conflict: terminated by other getUpdates request; make sure that only one bot instance is running
2024-12-06 15:40:26,179 - telegram.ext.Updater - ERROR - Error while getting Updates: Conflict: terminated by other getUpdates request; make sure that only one bot instance is running
2024-12-06 15:40:26,179 - telegram.ext.Application - ERROR - No error handlers are registered, logging exception.
Traceback (most recent call last):
  File "/Users/admin/Library/Python/3.9/lib/python/site-packages/telegram/ext/_updater.py", line 607, in _network_loop_retry
    if not await action_cb():
  File "/Users/admin/Library/Python/3.9/lib/python/site-packages/telegram/ext/_updater.py", line 335, in polling_action_cb
    raise exc
  File "/Users/admin/Library/Python/3.9/lib/python/site-packages/telegram/ext/_updater.py", line 320, in polling_action_cb
    updates = await self.bot.get_updates(
  File "/Users/admin/Library/Python/3.9/lib/python/site-packages/telegram/ext/_extbot.py", line 543, in get_updates
    updates = await super().get_updates(
  File "/Users/admin/Library/Python/3.9/lib/python/site-packages/telegram/_bot.py", line 381, in decorator
    result = await func(self, *args, **kwargs)  # skipcq: PYL-E1102
  File "/Users/admin/Library/Python/3.9/lib/python/site-packages/telegram/_bot.py", line 3661, in get_updates
    await self._post(
  File "/Users/admin/Library/Python/3.9/lib/python/site-packages/telegram/_bot.py", line 469, in _post
    return await self._do_post(
  File "/Users/admin/Library/Python/3.9/lib/python/site-packages/telegram/ext/_extbot.py", line 325, in _do_post
    return await super()._do_post(
  File "/Users/admin/Library/Python/3.9/lib/python/site-packages/telegram/_bot.py", line 497, in _do_post
    return await request.post(
  File "/Users/admin/Library/Python/3.9/lib/python/site-packages/telegram/request/_baserequest.py", line 168, in post
    result = await self._request_wrapper(
  File "/Users/admin/Library/Python/3.9/lib/python/site-packages/telegram/request/_baserequest.py", line 330, in _request_wrapper
    raise Conflict(message)
telegram.error.Conflict: Conflict: terminated by other getUpdates request; make sure that only one bot instance is running
2024-12-06 15:41:00,200 - telegram.ext.Updater - ERROR - Error while getting Updates: Conflict: terminated by other getUpdates request; make sure that only one bot instance is running
2024-12-06 15:41:00,200 - telegram.ext.Application - ERROR - No error handlers are registered, logging exception.
Traceback (most recent call last):
  File "/Users/admin/Library/Python/3.9/lib/python/site-packages/telegram/ext/_updater.py", line 607, in _network_loop_retry
    if not await action_cb():
  File "/Users/admin/Library/Python/3.9/lib/python/site-packages/telegram/ext/_updater.py", line 335, in polling_action_cb
    raise exc
  File "/Users/admin/Library/Python/3.9/lib/python/site-packages/telegram/ext/_updater.py", line 320, in polling_action_cb
    updates = await self.bot.get_updates(
  File "/Users/admin/Library/Python/3.9/lib/python/site-packages/telegram/ext/_extbot.py", line 543, in get_updates
    updates = await super().get_updates(
  File "/Users/admin/Library/Python/3.9/lib/python/site-packages/telegram/_bot.py", line 381, in decorator
    result = await func(self, *args, **kwargs)  # skipcq: PYL-E1102
  File "/Users/admin/Library/Python/3.9/lib/python/site-packages/telegram/_bot.py", line 3661, in get_updates
    await self._post(
  File "/Users/admin/Library/Python/3.9/lib/python/site-packages/telegram/_bot.py", line 469, in _post
    return await self._do_post(
  File "/Users/admin/Library/Python/3.9/lib/python/site-packages/telegram/ext/_extbot.py", line 325, in _do_post
    return await super()._do_post(
  File "/Users/admin/Library/Python/3.9/lib/python/site-packages/telegram/_bot.py", line 497, in _do_post
    return await request.post(
  File "/Users/admin/Library/Python/3.9/lib/python/site-packages/telegram/request/_baserequest.py", line 168, in post
    result = await self._request_wrapper(
  File "/Users/admin/Library/Python/3.9/lib/python/site-packages/telegram/request/_baserequest.py", line 330, in _request_wrapper
    raise Conflict(message)
telegram.error.Conflict: Conflict: terminated by other getUpdates request; make sure that only one bot instance is running
2024-12-06 15:41:34,684 - telegram.ext.Updater - ERROR - Error while getting Updates: Conflict: terminated by other getUpdates request; make sure that only one bot instance is running
2024-12-06 15:41:34,685 - telegram.ext.Application - ERROR - No error handlers are registered, logging exception.
Traceback (most recent call last):
  File "/Users/admin/Library/Python/3.9/lib/python/site-packages/telegram/ext/_updater.py", line 607, in _network_loop_retry
    if not await action_cb():
  File "/Users/admin/Library/Python/3.9/lib/python/site-packages/telegram/ext/_updater.py", line 335, in polling_action_cb
    raise exc
  File "/Users/admin/Library/Python/3.9/lib/python/site-packages/telegram/ext/_updater.py", line 320, in polling_action_cb
    updates = await self.bot.get_updates(
  File "/Users/admin/Library/Python/3.9/lib/python/site-packages/telegram/ext/_extbot.py", line 543, in get_updates
    updates = await super().get_updates(
  File "/Users/admin/Library/Python/3.9/lib/python/site-packages/telegram/_bot.py", line 381, in decorator
    result = await func(self, *args, **kwargs)  # skipcq: PYL-E1102
  File "/Users/admin/Library/Python/3.9/lib/python/site-packages/telegram/_bot.py", line 3661, in get_updates
    await self._post(
  File "/Users/admin/Library/Python/3.9/lib/python/site-packages/telegram/_bot.py", line 469, in _post
    return await self._do_post(
  File "/Users/admin/Library/Python/3.9/lib/python/site-packages/telegram/ext/_extbot.py", line 325, in _do_post
    return await super()._do_post(
  File "/Users/admin/Library/Python/3.9/lib/python/site-packages/telegram/_bot.py", line 497, in _do_post
    return await request.post(
  File "/Users/admin/Library/Python/3.9/lib/python/site-packages/telegram/request/_baserequest.py", line 168, in post
    result = await self._request_wrapper(
  File "/Users/admin/Library/Python/3.9/lib/python/site-packages/telegram/request/_baserequest.py", line 330, in _request_wrapper
    raise Conflict(message)
telegram.error.Conflict: Conflict: terminated by other getUpdates request; make sure that only one bot instance is running
2024-12-06 15:42:08,679 - telegram.ext.Updater - ERROR - Error while getting Updates: Conflict: terminated by other getUpdates request; make sure that only one bot instance is running
2024-12-06 15:42:08,680 - telegram.ext.Application - ERROR - No error handlers are registered, logging exception.
Traceback (most recent call last):
  File "/Users/admin/Library/Python/3.9/lib/python/site-packages/telegram/ext/_updater.py", line 607, in _network_loop_retry
    if not await action_cb():
  File "/Users/admin/Library/Python/3.9/lib/python/site-packages/telegram/ext/_updater.py", line 335, in polling_action_cb
    raise exc
  File "/Users/admin/Library/Python/3.9/lib/python/site-packages/telegram/ext/_updater.py", line 320, in polling_action_cb
    updates = await self.bot.get_updates(
  File "/Users/admin/Library/Python/3.9/lib/python/site-packages/telegram/ext/_extbot.py", line 543, in get_updates
    updates = await super().get_updates(
  File "/Users/admin/Library/Python/3.9/lib/python/site-packages/telegram/_bot.py", line 381, in decorator
    result = await func(self, *args, **kwargs)  # skipcq: PYL-E1102
  File "/Users/admin/Library/Python/3.9/lib/python/site-packages/telegram/_bot.py", line 3661, in get_updates
    await self._post(
  File "/Users/admin/Library/Python/3.9/lib/python/site-packages/telegram/_bot.py", line 469, in _post
    return await self._do_post(
  File "/Users/admin/Library/Python/3.9/lib/python/site-packages/telegram/ext/_extbot.py", line 325, in _do_post
    return await super()._do_post(
  File "/Users/admin/Library/Python/3.9/lib/python/site-packages/telegram/_bot.py", line 497, in _do_post
    return await request.post(
  File "/Users/admin/Library/Python/3.9/lib/python/site-packages/telegram/request/_baserequest.py", line 168, in post
    result = await self._request_wrapper(
  File "/Users/admin/Library/Python/3.9/lib/python/site-packages/telegram/request/_baserequest.py", line 330, in _request_wrapper
    raise Conflict(message)
telegram.error.Conflict: Conflict: terminated by other getUpdates request; make sure that only one bot instance is running
2024-12-06 15:42:43,087 - telegram.ext.Updater - ERROR - Error while getting Updates: Conflict: terminated by other getUpdates request; make sure that only one bot instance is running
2024-12-06 15:42:43,089 - telegram.ext.Application - ERROR - No error handlers are registered, logging exception.
Traceback (most recent call last):
  File "/Users/admin/Library/Python/3.9/lib/python/site-packages/telegram/ext/_updater.py", line 607, in _network_loop_retry
    if not await action_cb():
  File "/Users/admin/Library/Python/3.9/lib/python/site-packages/telegram/ext/_updater.py", line 335, in polling_action_cb
    raise exc
  File "/Users/admin/Library/Python/3.9/lib/python/site-packages/telegram/ext/_updater.py", line 320, in polling_action_cb
    updates = await self.bot.get_updates(
  File "/Users/admin/Library/Python/3.9/lib/python/site-packages/telegram/ext/_extbot.py", line 543, in get_updates
    updates = await super().get_updates(
  File "/Users/admin/Library/Python/3.9/lib/python/site-packages/telegram/_bot.py", line 381, in decorator
    result = await func(self, *args, **kwargs)  # skipcq: PYL-E1102
  File "/Users/admin/Library/Python/3.9/lib/python/site-packages/telegram/_bot.py", line 3661, in get_updates
    await self._post(
  File "/Users/admin/Library/Python/3.9/lib/python/site-packages/telegram/_bot.py", line 469, in _post
    return await self._do_post(
  File "/Users/admin/Library/Python/3.9/lib/python/site-packages/telegram/ext/_extbot.py", line 325, in _do_post
    return await super()._do_post(
  File "/Users/admin/Library/Python/3.9/lib/python/site-packages/telegram/_bot.py", line 497, in _do_post
    return await request.post(
  File "/Users/admin/Library/Python/3.9/lib/python/site-packages/telegram/request/_baserequest.py", line 168, in post
    result = await self._request_wrapper(
  File "/Users/admin/Library/Python/3.9/lib/python/site-packages/telegram/request/_baserequest.py", line 330, in _request_wrapper
    raise Conflict(message)
telegram.error.Conflict: Conflict: terminated by other getUpdates request; make sure that only one bot instance is running
2024-12-06 15:43:17,074 - telegram.ext.Updater - ERROR - Error while getting Updates: Conflict: terminated by other getUpdates request; make sure that only one bot instance is running
2024-12-06 15:43:17,075 - telegram.ext.Application - ERROR - No error handlers are registered, logging exception.
Traceback (most recent call last):
  File "/Users/admin/Library/Python/3.9/lib/python/site-packages/telegram/ext/_updater.py", line 607, in _network_loop_retry
    if not await action_cb():
  File "/Users/admin/Library/Python/3.9/lib/python/site-packages/telegram/ext/_updater.py", line 335, in polling_action_cb
    raise exc
  File "/Users/admin/Library/Python/3.9/lib/python/site-packages/telegram/ext/_updater.py", line 320, in polling_action_cb
    updates = await self.bot.get_updates(
  File "/Users/admin/Library/Python/3.9/lib/python/site-packages/telegram/ext/_extbot.py", line 543, in get_updates
    updates = await super().get_updates(
  File "/Users/admin/Library/Python/3.9/lib/python/site-packages/telegram/_bot.py", line 381, in decorator
    result = await func(self, *args, **kwargs)  # skipcq: PYL-E1102
  File "/Users/admin/Library/Python/3.9/lib/python/site-packages/telegram/_bot.py", line 3661, in get_updates
    await self._post(
  File "/Users/admin/Library/Python/3.9/lib/python/site-packages/telegram/_bot.py", line 469, in _post
    return await self._do_post(
  File "/Users/admin/Library/Python/3.9/lib/python/site-packages/telegram/ext/_extbot.py", line 325, in _do_post
    return await super()._do_post(
  File "/Users/admin/Library/Python/3.9/lib/python/site-packages/telegram/_bot.py", line 497, in _do_post
    return await request.post(
  File "/Users/admin/Library/Python/3.9/lib/python/site-packages/telegram/request/_baserequest.py", line 168, in post
    result = await self._request_wrapper(
  File "/Users/admin/Library/Python/3.9/lib/python/site-packages/telegram/request/_baserequest.py", line 330, in _request_wrapper
    raise Conflict(message)
telegram.error.Conflict: Conflict: terminated by other getUpdates request; make sure that only one bot instance is running
2024-12-06 15:43:51,693 - telegram.ext.Updater - ERROR - Error while getting Updates: Conflict: terminated by other getUpdates request; make sure that only one bot instance is running
2024-12-06 15:43:51,694 - telegram.ext.Application - ERROR - No error handlers are registered, logging exception.
Traceback (most recent call last):
  File "/Users/admin/Library/Python/3.9/lib/python/site-packages/telegram/ext/_updater.py", line 607, in _network_loop_retry
    if not await action_cb():
  File "/Users/admin/Library/Python/3.9/lib/python/site-packages/telegram/ext/_updater.py", line 335, in polling_action_cb
    raise exc
  File "/Users/admin/Library/Python/3.9/lib/python/site-packages/telegram/ext/_updater.py", line 320, in polling_action_cb
    updates = await self.bot.get_updates(
  File "/Users/admin/Library/Python/3.9/lib/python/site-packages/telegram/ext/_extbot.py", line 543, in get_updates
    updates = await super().get_updates(
  File "/Users/admin/Library/Python/3.9/lib/python/site-packages/telegram/_bot.py", line 381, in decorator
    result = await func(self, *args, **kwargs)  # skipcq: PYL-E1102
  File "/Users/admin/Library/Python/3.9/lib/python/site-packages/telegram/_bot.py", line 3661, in get_updates
    await self._post(
  File "/Users/admin/Library/Python/3.9/lib/python/site-packages/telegram/_bot.py", line 469, in _post
    return await self._do_post(
  File "/Users/admin/Library/Python/3.9/lib/python/site-packages/telegram/ext/_extbot.py", line 325, in _do_post
    return await super()._do_post(
  File "/Users/admin/Library/Python/3.9/lib/python/site-packages/telegram/_bot.py", line 497, in _do_post
    return await request.post(
  File "/Users/admin/Library/Python/3.9/lib/python/site-packages/telegram/request/_baserequest.py", line 168, in post
    result = await self._request_wrapper(
  File "/Users/admin/Library/Python/3.9/lib/python/site-packages/telegram/request/_baserequest.py", line 330, in _request_wrapper
    raise Conflict(message)
telegram.error.Conflict: Conflict: terminated by other getUpdates request; make sure that only one bot instance is running
2024-12-06 15:44:25,595 - telegram.ext.Updater - ERROR - Error while getting Updates: Conflict: terminated by other getUpdates request; make sure that only one bot instance is running
2024-12-06 15:44:25,596 - telegram.ext.Application - ERROR - No error handlers are registered, logging exception.
Traceback (most recent call last):
  File "/Users/admin/Library/Python/3.9/lib/python/site-packages/telegram/ext/_updater.py", line 607, in _network_loop_retry
    if not await action_cb():
  File "/Users/admin/Library/Python/3.9/lib/python/site-packages/telegram/ext/_updater.py", line 335, in polling_action_cb
    raise exc
  File "/Users/admin/Library/Python/3.9/lib/python/site-packages/telegram/ext/_updater.py", line 320, in polling_action_cb
    updates = await self.bot.get_updates(
  File "/Users/admin/Library/Python/3.9/lib/python/site-packages/telegram/ext/_extbot.py", line 543, in get_updates
    updates = await super().get_updates(
  File "/Users/admin/Library/Python/3.9/lib/python/site-packages/telegram/_bot.py", line 381, in decorator
    result = await func(self, *args, **kwargs)  # skipcq: PYL-E1102
  File "/Users/admin/Library/Python/3.9/lib/python/site-packages/telegram/_bot.py", line 3661, in get_updates
    await self._post(
  File "/Users/admin/Library/Python/3.9/lib/python/site-packages/telegram/_bot.py", line 469, in _post
    return await self._do_post(
  File "/Users/admin/Library/Python/3.9/lib/python/site-packages/telegram/ext/_extbot.py", line 325, in _do_post
    return await super()._do_post(
  File "/Users/admin/Library/Python/3.9/lib/python/site-packages/telegram/_bot.py", line 497, in _do_post
    return await request.post(
  File "/Users/admin/Library/Python/3.9/lib/python/site-packages/telegram/request/_baserequest.py", line 168, in post
    result = await self._request_wrapper(
  File "/Users/admin/Library/Python/3.9/lib/python/site-packages/telegram/request/_baserequest.py", line 330, in _request_wrapper
    raise Conflict(message)
telegram.error.Conflict: Conflict: terminated by other getUpdates request; make sure that only one bot instance is running
2024-12-06 15:45:00,269 - telegram.ext.Updater - ERROR - Error while getting Updates: Conflict: terminated by other getUpdates request; make sure that only one bot instance is running
2024-12-06 15:45:00,269 - telegram.ext.Application - ERROR - No error handlers are registered, logging exception.
Traceback (most recent call last):
  File "/Users/admin/Library/Python/3.9/lib/python/site-packages/telegram/ext/_updater.py", line 607, in _network_loop_retry
    if not await action_cb():
  File "/Users/admin/Library/Python/3.9/lib/python/site-packages/telegram/ext/_updater.py", line 335, in polling_action_cb
    raise exc
  File "/Users/admin/Library/Python/3.9/lib/python/site-packages/telegram/ext/_updater.py", line 320, in polling_action_cb
    updates = await self.bot.get_updates(
  File "/Users/admin/Library/Python/3.9/lib/python/site-packages/telegram/ext/_extbot.py", line 543, in get_updates
    updates = await super().get_updates(
  File "/Users/admin/Library/Python/3.9/lib/python/site-packages/telegram/_bot.py", line 381, in decorator
    result = await func(self, *args, **kwargs)  # skipcq: PYL-E1102
  File "/Users/admin/Library/Python/3.9/lib/python/site-packages/telegram/_bot.py", line 3661, in get_updates
    await self._post(
  File "/Users/admin/Library/Python/3.9/lib/python/site-packages/telegram/_bot.py", line 469, in _post
    return await self._do_post(
  File "/Users/admin/Library/Python/3.9/lib/python/site-packages/telegram/ext/_extbot.py", line 325, in _do_post
    return await super()._do_post(
  File "/Users/admin/Library/Python/3.9/lib/python/site-packages/telegram/_bot.py", line 497, in _do_post
    return await request.post(
  File "/Users/admin/Library/Python/3.9/lib/python/site-packages/telegram/request/_baserequest.py", line 168, in post
    result = await self._request_wrapper(
  File "/Users/admin/Library/Python/3.9/lib/python/site-packages/telegram/request/_baserequest.py", line 330, in _request_wrapper
    raise Conflict(message)
telegram.error.Conflict: Conflict: terminated by other getUpdates request; make sure that only one bot instance is running
2024-12-06 15:45:34,064 - telegram.ext.Updater - ERROR - Error while getting Updates: Conflict: terminated by other getUpdates request; make sure that only one bot instance is running
2024-12-06 15:45:34,065 - telegram.ext.Application - ERROR - No error handlers are registered, logging exception.
Traceback (most recent call last):
  File "/Users/admin/Library/Python/3.9/lib/python/site-packages/telegram/ext/_updater.py", line 607, in _network_loop_retry
    if not await action_cb():
  File "/Users/admin/Library/Python/3.9/lib/python/site-packages/telegram/ext/_updater.py", line 335, in polling_action_cb
    raise exc
  File "/Users/admin/Library/Python/3.9/lib/python/site-packages/telegram/ext/_updater.py", line 320, in polling_action_cb
    updates = await self.bot.get_updates(
  File "/Users/admin/Library/Python/3.9/lib/python/site-packages/telegram/ext/_extbot.py", line 543, in get_updates
    updates = await super().get_updates(
  File "/Users/admin/Library/Python/3.9/lib/python/site-packages/telegram/_bot.py", line 381, in decorator
    result = await func(self, *args, **kwargs)  # skipcq: PYL-E1102
  File "/Users/admin/Library/Python/3.9/lib/python/site-packages/telegram/_bot.py", line 3661, in get_updates
    await self._post(
  File "/Users/admin/Library/Python/3.9/lib/python/site-packages/telegram/_bot.py", line 469, in _post
    return await self._do_post(
  File "/Users/admin/Library/Python/3.9/lib/python/site-packages/telegram/ext/_extbot.py", line 325, in _do_post
    return await super()._do_post(
  File "/Users/admin/Library/Python/3.9/lib/python/site-packages/telegram/_bot.py", line 497, in _do_post
    return await request.post(
  File "/Users/admin/Library/Python/3.9/lib/python/site-packages/telegram/request/_baserequest.py", line 168, in post
    result = await self._request_wrapper(
  File "/Users/admin/Library/Python/3.9/lib/python/site-packages/telegram/request/_baserequest.py", line 330, in _request_wrapper
    raise Conflict(message)
telegram.error.Conflict: Conflict: terminated by other getUpdates request; make sure that only one bot instance is running
2024-12-06 15:46:08,780 - telegram.ext.Updater - ERROR - Error while getting Updates: Conflict: terminated by other getUpdates request; make sure that only one bot instance is running
2024-12-06 15:46:08,781 - telegram.ext.Application - ERROR - No error handlers are registered, logging exception.
Traceback (most recent call last):
  File "/Users/admin/Library/Python/3.9/lib/python/site-packages/telegram/ext/_updater.py", line 607, in _network_loop_retry
    if not await action_cb():
  File "/Users/admin/Library/Python/3.9/lib/python/site-packages/telegram/ext/_updater.py", line 335, in polling_action_cb
    raise exc
  File "/Users/admin/Library/Python/3.9/lib/python/site-packages/telegram/ext/_updater.py", line 320, in polling_action_cb
    updates = await self.bot.get_updates(
  File "/Users/admin/Library/Python/3.9/lib/python/site-packages/telegram/ext/_extbot.py", line 543, in get_updates
    updates = await super().get_updates(
  File "/Users/admin/Library/Python/3.9/lib/python/site-packages/telegram/_bot.py", line 381, in decorator
    result = await func(self, *args, **kwargs)  # skipcq: PYL-E1102
  File "/Users/admin/Library/Python/3.9/lib/python/site-packages/telegram/_bot.py", line 3661, in get_updates
    await self._post(
  File "/Users/admin/Library/Python/3.9/lib/python/site-packages/telegram/_bot.py", line 469, in _post
    return await self._do_post(
  File "/Users/admin/Library/Python/3.9/lib/python/site-packages/telegram/ext/_extbot.py", line 325, in _do_post
    return await super()._do_post(
  File "/Users/admin/Library/Python/3.9/lib/python/site-packages/telegram/_bot.py", line 497, in _do_post
    return await request.post(
  File "/Users/admin/Library/Python/3.9/lib/python/site-packages/telegram/request/_baserequest.py", line 168, in post
    result = await self._request_wrapper(
  File "/Users/admin/Library/Python/3.9/lib/python/site-packages/telegram/request/_baserequest.py", line 330, in _request_wrapper
    raise Conflict(message)
telegram.error.Conflict: Conflict: terminated by other getUpdates request; make sure that only one bot instance is running
2024-12-06 15:46:42,497 - telegram.ext.Updater - ERROR - Error while getting Updates: Conflict: terminated by other getUpdates request; make sure that only one bot instance is running
2024-12-06 15:46:42,498 - telegram.ext.Application - ERROR - No error handlers are registered, logging exception.
Traceback (most recent call last):
  File "/Users/admin/Library/Python/3.9/lib/python/site-packages/telegram/ext/_updater.py", line 607, in _network_loop_retry
    if not await action_cb():
  File "/Users/admin/Library/Python/3.9/lib/python/site-packages/telegram/ext/_updater.py", line 335, in polling_action_cb
    raise exc
  File "/Users/admin/Library/Python/3.9/lib/python/site-packages/telegram/ext/_updater.py", line 320, in polling_action_cb
    updates = await self.bot.get_updates(
  File "/Users/admin/Library/Python/3.9/lib/python/site-packages/telegram/ext/_extbot.py", line 543, in get_updates
    updates = await super().get_updates(
  File "/Users/admin/Library/Python/3.9/lib/python/site-packages/telegram/_bot.py", line 381, in decorator
    result = await func(self, *args, **kwargs)  # skipcq: PYL-E1102
  File "/Users/admin/Library/Python/3.9/lib/python/site-packages/telegram/_bot.py", line 3661, in get_updates
    await self._post(
  File "/Users/admin/Library/Python/3.9/lib/python/site-packages/telegram/_bot.py", line 469, in _post
    return await self._do_post(
  File "/Users/admin/Library/Python/3.9/lib/python/site-packages/telegram/ext/_extbot.py", line 325, in _do_post
    return await super()._do_post(
  File "/Users/admin/Library/Python/3.9/lib/python/site-packages/telegram/_bot.py", line 497, in _do_post
    return await request.post(
  File "/Users/admin/Library/Python/3.9/lib/python/site-packages/telegram/request/_baserequest.py", line 168, in post
    result = await self._request_wrapper(
  File "/Users/admin/Library/Python/3.9/lib/python/site-packages/telegram/request/_baserequest.py", line 330, in _request_wrapper
    raise Conflict(message)
telegram.error.Conflict: Conflict: terminated by other getUpdates request; make sure that only one bot instance is running
2024-12-06 15:47:17,208 - telegram.ext.Updater - ERROR - Error while getting Updates: Conflict: terminated by other getUpdates request; make sure that only one bot instance is running
2024-12-06 15:47:17,209 - telegram.ext.Application - ERROR - No error handlers are registered, logging exception.
Traceback (most recent call last):
  File "/Users/admin/Library/Python/3.9/lib/python/site-packages/telegram/ext/_updater.py", line 607, in _network_loop_retry
    if not await action_cb():
  File "/Users/admin/Library/Python/3.9/lib/python/site-packages/telegram/ext/_updater.py", line 335, in polling_action_cb
    raise exc
  File "/Users/admin/Library/Python/3.9/lib/python/site-packages/telegram/ext/_updater.py", line 320, in polling_action_cb
    updates = await self.bot.get_updates(
  File "/Users/admin/Library/Python/3.9/lib/python/site-packages/telegram/ext/_extbot.py", line 543, in get_updates
    updates = await super().get_updates(
  File "/Users/admin/Library/Python/3.9/lib/python/site-packages/telegram/_bot.py", line 381, in decorator
    result = await func(self, *args, **kwargs)  # skipcq: PYL-E1102
  File "/Users/admin/Library/Python/3.9/lib/python/site-packages/telegram/_bot.py", line 3661, in get_updates
    await self._post(
  File "/Users/admin/Library/Python/3.9/lib/python/site-packages/telegram/_bot.py", line 469, in _post
    return await self._do_post(
  File "/Users/admin/Library/Python/3.9/lib/python/site-packages/telegram/ext/_extbot.py", line 325, in _do_post
    return await super()._do_post(
  File "/Users/admin/Library/Python/3.9/lib/python/site-packages/telegram/_bot.py", line 497, in _do_post
    return await request.post(
  File "/Users/admin/Library/Python/3.9/lib/python/site-packages/telegram/request/_baserequest.py", line 168, in post
    result = await self._request_wrapper(
  File "/Users/admin/Library/Python/3.9/lib/python/site-packages/telegram/request/_baserequest.py", line 330, in _request_wrapper
    raise Conflict(message)
telegram.error.Conflict: Conflict: terminated by other getUpdates request; make sure that only one bot instance is running
2024-12-06 15:47:49,881 - telegram.ext.Updater - ERROR - Error while getting Updates: Conflict: terminated by other getUpdates request; make sure that only one bot instance is running
2024-12-06 15:47:49,881 - telegram.ext.Application - ERROR - No error handlers are registered, logging exception.
Traceback (most recent call last):
  File "/Users/admin/Library/Python/3.9/lib/python/site-packages/telegram/ext/_updater.py", line 607, in _network_loop_retry
    if not await action_cb():
  File "/Users/admin/Library/Python/3.9/lib/python/site-packages/telegram/ext/_updater.py", line 335, in polling_action_cb
    raise exc
  File "/Users/admin/Library/Python/3.9/lib/python/site-packages/telegram/ext/_updater.py", line 320, in polling_action_cb
    updates = await self.bot.get_updates(
  File "/Users/admin/Library/Python/3.9/lib/python/site-packages/telegram/ext/_extbot.py", line 543, in get_updates
    updates = await super().get_updates(
  File "/Users/admin/Library/Python/3.9/lib/python/site-packages/telegram/_bot.py", line 381, in decorator
    result = await func(self, *args, **kwargs)  # skipcq: PYL-E1102
  File "/Users/admin/Library/Python/3.9/lib/python/site-packages/telegram/_bot.py", line 3661, in get_updates
    await self._post(
  File "/Users/admin/Library/Python/3.9/lib/python/site-packages/telegram/_bot.py", line 469, in _post
    return await self._do_post(
  File "/Users/admin/Library/Python/3.9/lib/python/site-packages/telegram/ext/_extbot.py", line 325, in _do_post
    return await super()._do_post(
  File "/Users/admin/Library/Python/3.9/lib/python/site-packages/telegram/_bot.py", line 497, in _do_post
    return await request.post(
  File "/Users/admin/Library/Python/3.9/lib/python/site-packages/telegram/request/_baserequest.py", line 168, in post
    result = await self._request_wrapper(
  File "/Users/admin/Library/Python/3.9/lib/python/site-packages/telegram/request/_baserequest.py", line 330, in _request_wrapper
    raise Conflict(message)
telegram.error.Conflict: Conflict: terminated by other getUpdates request; make sure that only one bot instance is running
2024-12-06 15:48:24,074 - telegram.ext.Updater - ERROR - Error while getting Updates: Conflict: terminated by other getUpdates request; make sure that only one bot instance is running
2024-12-06 15:48:24,075 - telegram.ext.Application - ERROR - No error handlers are registered, logging exception.
Traceback (most recent call last):
  File "/Users/admin/Library/Python/3.9/lib/python/site-packages/telegram/ext/_updater.py", line 607, in _network_loop_retry
    if not await action_cb():
  File "/Users/admin/Library/Python/3.9/lib/python/site-packages/telegram/ext/_updater.py", line 335, in polling_action_cb
    raise exc
  File "/Users/admin/Library/Python/3.9/lib/python/site-packages/telegram/ext/_updater.py", line 320, in polling_action_cb
    updates = await self.bot.get_updates(
  File "/Users/admin/Library/Python/3.9/lib/python/site-packages/telegram/ext/_extbot.py", line 543, in get_updates
    updates = await super().get_updates(
  File "/Users/admin/Library/Python/3.9/lib/python/site-packages/telegram/_bot.py", line 381, in decorator
    result = await func(self, *args, **kwargs)  # skipcq: PYL-E1102
  File "/Users/admin/Library/Python/3.9/lib/python/site-packages/telegram/_bot.py", line 3661, in get_updates
    await self._post(
  File "/Users/admin/Library/Python/3.9/lib/python/site-packages/telegram/_bot.py", line 469, in _post
    return await self._do_post(
  File "/Users/admin/Library/Python/3.9/lib/python/site-packages/telegram/ext/_extbot.py", line 325, in _do_post
    return await super()._do_post(
  File "/Users/admin/Library/Python/3.9/lib/python/site-packages/telegram/_bot.py", line 497, in _do_post
    return await request.post(
  File "/Users/admin/Library/Python/3.9/lib/python/site-packages/telegram/request/_baserequest.py", line 168, in post
    result = await self._request_wrapper(
  File "/Users/admin/Library/Python/3.9/lib/python/site-packages/telegram/request/_baserequest.py", line 330, in _request_wrapper
    raise Conflict(message)
telegram.error.Conflict: Conflict: terminated by other getUpdates request; make sure that only one bot instance is running
2024-12-06 15:48:58,480 - telegram.ext.Updater - ERROR - Error while getting Updates: Conflict: terminated by other getUpdates request; make sure that only one bot instance is running
2024-12-06 15:48:58,481 - telegram.ext.Application - ERROR - No error handlers are registered, logging exception.
Traceback (most recent call last):
  File "/Users/admin/Library/Python/3.9/lib/python/site-packages/telegram/ext/_updater.py", line 607, in _network_loop_retry
    if not await action_cb():
  File "/Users/admin/Library/Python/3.9/lib/python/site-packages/telegram/ext/_updater.py", line 335, in polling_action_cb
    raise exc
  File "/Users/admin/Library/Python/3.9/lib/python/site-packages/telegram/ext/_updater.py", line 320, in polling_action_cb
    updates = await self.bot.get_updates(
  File "/Users/admin/Library/Python/3.9/lib/python/site-packages/telegram/ext/_extbot.py", line 543, in get_updates
    updates = await super().get_updates(
  File "/Users/admin/Library/Python/3.9/lib/python/site-packages/telegram/_bot.py", line 381, in decorator
    result = await func(self, *args, **kwargs)  # skipcq: PYL-E1102
  File "/Users/admin/Library/Python/3.9/lib/python/site-packages/telegram/_bot.py", line 3661, in get_updates
    await self._post(
  File "/Users/admin/Library/Python/3.9/lib/python/site-packages/telegram/_bot.py", line 469, in _post
    return await self._do_post(
  File "/Users/admin/Library/Python/3.9/lib/python/site-packages/telegram/ext/_extbot.py", line 325, in _do_post
    return await super()._do_post(
  File "/Users/admin/Library/Python/3.9/lib/python/site-packages/telegram/_bot.py", line 497, in _do_post
    return await request.post(
  File "/Users/admin/Library/Python/3.9/lib/python/site-packages/telegram/request/_baserequest.py", line 168, in post
    result = await self._request_wrapper(
  File "/Users/admin/Library/Python/3.9/lib/python/site-packages/telegram/request/_baserequest.py", line 330, in _request_wrapper
    raise Conflict(message)
telegram.error.Conflict: Conflict: terminated by other getUpdates request; make sure that only one bot instance is running
2024-12-06 15:49:32,580 - telegram.ext.Updater - ERROR - Error while getting Updates: Conflict: terminated by other getUpdates request; make sure that only one bot instance is running
2024-12-06 15:49:32,581 - telegram.ext.Application - ERROR - No error handlers are registered, logging exception.
Traceback (most recent call last):
  File "/Users/admin/Library/Python/3.9/lib/python/site-packages/telegram/ext/_updater.py", line 607, in _network_loop_retry
    if not await action_cb():
  File "/Users/admin/Library/Python/3.9/lib/python/site-packages/telegram/ext/_updater.py", line 335, in polling_action_cb
    raise exc
  File "/Users/admin/Library/Python/3.9/lib/python/site-packages/telegram/ext/_updater.py", line 320, in polling_action_cb
    updates = await self.bot.get_updates(
  File "/Users/admin/Library/Python/3.9/lib/python/site-packages/telegram/ext/_extbot.py", line 543, in get_updates
    updates = await super().get_updates(
  File "/Users/admin/Library/Python/3.9/lib/python/site-packages/telegram/_bot.py", line 381, in decorator
    result = await func(self, *args, **kwargs)  # skipcq: PYL-E1102
  File "/Users/admin/Library/Python/3.9/lib/python/site-packages/telegram/_bot.py", line 3661, in get_updates
    await self._post(
  File "/Users/admin/Library/Python/3.9/lib/python/site-packages/telegram/_bot.py", line 469, in _post
    return await self._do_post(
  File "/Users/admin/Library/Python/3.9/lib/python/site-packages/telegram/ext/_extbot.py", line 325, in _do_post
    return await super()._do_post(
  File "/Users/admin/Library/Python/3.9/lib/python/site-packages/telegram/_bot.py", line 497, in _do_post
    return await request.post(
  File "/Users/admin/Library/Python/3.9/lib/python/site-packages/telegram/request/_baserequest.py", line 168, in post
    result = await self._request_wrapper(
  File "/Users/admin/Library/Python/3.9/lib/python/site-packages/telegram/request/_baserequest.py", line 330, in _request_wrapper
    raise Conflict(message)
telegram.error.Conflict: Conflict: terminated by other getUpdates request; make sure that only one bot instance is running
2024-12-06 15:50:06,985 - telegram.ext.Updater - ERROR - Error while getting Updates: Conflict: terminated by other getUpdates request; make sure that only one bot instance is running
2024-12-06 15:50:06,987 - telegram.ext.Application - ERROR - No error handlers are registered, logging exception.
Traceback (most recent call last):
  File "/Users/admin/Library/Python/3.9/lib/python/site-packages/telegram/ext/_updater.py", line 607, in _network_loop_retry
    if not await action_cb():
  File "/Users/admin/Library/Python/3.9/lib/python/site-packages/telegram/ext/_updater.py", line 335, in polling_action_cb
    raise exc
  File "/Users/admin/Library/Python/3.9/lib/python/site-packages/telegram/ext/_updater.py", line 320, in polling_action_cb
    updates = await self.bot.get_updates(
  File "/Users/admin/Library/Python/3.9/lib/python/site-packages/telegram/ext/_extbot.py", line 543, in get_updates
    updates = await super().get_updates(
  File "/Users/admin/Library/Python/3.9/lib/python/site-packages/telegram/_bot.py", line 381, in decorator
    result = await func(self, *args, **kwargs)  # skipcq: PYL-E1102
  File "/Users/admin/Library/Python/3.9/lib/python/site-packages/telegram/_bot.py", line 3661, in get_updates
    await self._post(
  File "/Users/admin/Library/Python/3.9/lib/python/site-packages/telegram/_bot.py", line 469, in _post
    return await self._do_post(
  File "/Users/admin/Library/Python/3.9/lib/python/site-packages/telegram/ext/_extbot.py", line 325, in _do_post
    return await super()._do_post(
  File "/Users/admin/Library/Python/3.9/lib/python/site-packages/telegram/_bot.py", line 497, in _do_post
    return await request.post(
  File "/Users/admin/Library/Python/3.9/lib/python/site-packages/telegram/request/_baserequest.py", line 168, in post
    result = await self._request_wrapper(
  File "/Users/admin/Library/Python/3.9/lib/python/site-packages/telegram/request/_baserequest.py", line 330, in _request_wrapper
    raise Conflict(message)
telegram.error.Conflict: Conflict: terminated by other getUpdates request; make sure that only one bot instance is running
2024-12-06 15:50:41,015 - telegram.ext.Updater - ERROR - Error while getting Updates: Conflict: terminated by other getUpdates request; make sure that only one bot instance is running
2024-12-06 15:50:41,016 - telegram.ext.Application - ERROR - No error handlers are registered, logging exception.
Traceback (most recent call last):
  File "/Users/admin/Library/Python/3.9/lib/python/site-packages/telegram/ext/_updater.py", line 607, in _network_loop_retry
    if not await action_cb():
  File "/Users/admin/Library/Python/3.9/lib/python/site-packages/telegram/ext/_updater.py", line 335, in polling_action_cb
    raise exc
  File "/Users/admin/Library/Python/3.9/lib/python/site-packages/telegram/ext/_updater.py", line 320, in polling_action_cb
    updates = await self.bot.get_updates(
  File "/Users/admin/Library/Python/3.9/lib/python/site-packages/telegram/ext/_extbot.py", line 543, in get_updates
    updates = await super().get_updates(
  File "/Users/admin/Library/Python/3.9/lib/python/site-packages/telegram/_bot.py", line 381, in decorator
    result = await func(self, *args, **kwargs)  # skipcq: PYL-E1102
  File "/Users/admin/Library/Python/3.9/lib/python/site-packages/telegram/_bot.py", line 3661, in get_updates
    await self._post(
  File "/Users/admin/Library/Python/3.9/lib/python/site-packages/telegram/_bot.py", line 469, in _post
    return await self._do_post(
  File "/Users/admin/Library/Python/3.9/lib/python/site-packages/telegram/ext/_extbot.py", line 325, in _do_post
    return await super()._do_post(
  File "/Users/admin/Library/Python/3.9/lib/python/site-packages/telegram/_bot.py", line 497, in _do_post
    return await request.post(
  File "/Users/admin/Library/Python/3.9/lib/python/site-packages/telegram/request/_baserequest.py", line 168, in post
    result = await self._request_wrapper(
  File "/Users/admin/Library/Python/3.9/lib/python/site-packages/telegram/request/_baserequest.py", line 330, in _request_wrapper
    raise Conflict(message)
telegram.error.Conflict: Conflict: terminated by other getUpdates request; make sure that only one bot instance is running
2024-12-06 15:51:14,876 - telegram.ext.Updater - ERROR - Error while getting Updates: Conflict: terminated by other getUpdates request; make sure that only one bot instance is running
2024-12-06 15:51:14,876 - telegram.ext.Application - ERROR - No error handlers are registered, logging exception.
Traceback (most recent call last):
  File "/Users/admin/Library/Python/3.9/lib/python/site-packages/telegram/ext/_updater.py", line 607, in _network_loop_retry
    if not await action_cb():
  File "/Users/admin/Library/Python/3.9/lib/python/site-packages/telegram/ext/_updater.py", line 335, in polling_action_cb
    raise exc
  File "/Users/admin/Library/Python/3.9/lib/python/site-packages/telegram/ext/_updater.py", line 320, in polling_action_cb
    updates = await self.bot.get_updates(
  File "/Users/admin/Library/Python/3.9/lib/python/site-packages/telegram/ext/_extbot.py", line 543, in get_updates
    updates = await super().get_updates(
  File "/Users/admin/Library/Python/3.9/lib/python/site-packages/telegram/_bot.py", line 381, in decorator
    result = await func(self, *args, **kwargs)  # skipcq: PYL-E1102
  File "/Users/admin/Library/Python/3.9/lib/python/site-packages/telegram/_bot.py", line 3661, in get_updates
    await self._post(
  File "/Users/admin/Library/Python/3.9/lib/python/site-packages/telegram/_bot.py", line 469, in _post
    return await self._do_post(
  File "/Users/admin/Library/Python/3.9/lib/python/site-packages/telegram/ext/_extbot.py", line 325, in _do_post
    return await super()._do_post(
  File "/Users/admin/Library/Python/3.9/lib/python/site-packages/telegram/_bot.py", line 497, in _do_post
    return await request.post(
  File "/Users/admin/Library/Python/3.9/lib/python/site-packages/telegram/request/_baserequest.py", line 168, in post
    result = await self._request_wrapper(
  File "/Users/admin/Library/Python/3.9/lib/python/site-packages/telegram/request/_baserequest.py", line 330, in _request_wrapper
    raise Conflict(message)
telegram.error.Conflict: Conflict: terminated by other getUpdates request; make sure that only one bot instance is running
2024-12-06 15:51:50,306 - telegram.ext.Updater - ERROR - Error while getting Updates: Conflict: terminated by other getUpdates request; make sure that only one bot instance is running
2024-12-06 15:51:50,307 - telegram.ext.Application - ERROR - No error handlers are registered, logging exception.
Traceback (most recent call last):
  File "/Users/admin/Library/Python/3.9/lib/python/site-packages/telegram/ext/_updater.py", line 607, in _network_loop_retry
    if not await action_cb():
  File "/Users/admin/Library/Python/3.9/lib/python/site-packages/telegram/ext/_updater.py", line 335, in polling_action_cb
    raise exc
  File "/Users/admin/Library/Python/3.9/lib/python/site-packages/telegram/ext/_updater.py", line 320, in polling_action_cb
    updates = await self.bot.get_updates(
  File "/Users/admin/Library/Python/3.9/lib/python/site-packages/telegram/ext/_extbot.py", line 543, in get_updates
    updates = await super().get_updates(
  File "/Users/admin/Library/Python/3.9/lib/python/site-packages/telegram/_bot.py", line 381, in decorator
    result = await func(self, *args, **kwargs)  # skipcq: PYL-E1102
  File "/Users/admin/Library/Python/3.9/lib/python/site-packages/telegram/_bot.py", line 3661, in get_updates
    await self._post(
  File "/Users/admin/Library/Python/3.9/lib/python/site-packages/telegram/_bot.py", line 469, in _post
    return await self._do_post(
  File "/Users/admin/Library/Python/3.9/lib/python/site-packages/telegram/ext/_extbot.py", line 325, in _do_post
    return await super()._do_post(
  File "/Users/admin/Library/Python/3.9/lib/python/site-packages/telegram/_bot.py", line 497, in _do_post
    return await request.post(
  File "/Users/admin/Library/Python/3.9/lib/python/site-packages/telegram/request/_baserequest.py", line 168, in post
    result = await self._request_wrapper(
  File "/Users/admin/Library/Python/3.9/lib/python/site-packages/telegram/request/_baserequest.py", line 330, in _request_wrapper
    raise Conflict(message)
telegram.error.Conflict: Conflict: terminated by other getUpdates request; make sure that only one bot instance is running
2024-12-06 15:52:24,201 - telegram.ext.Updater - ERROR - Error while getting Updates: Conflict: terminated by other getUpdates request; make sure that only one bot instance is running
2024-12-06 15:52:24,202 - telegram.ext.Application - ERROR - No error handlers are registered, logging exception.
Traceback (most recent call last):
  File "/Users/admin/Library/Python/3.9/lib/python/site-packages/telegram/ext/_updater.py", line 607, in _network_loop_retry
    if not await action_cb():
  File "/Users/admin/Library/Python/3.9/lib/python/site-packages/telegram/ext/_updater.py", line 335, in polling_action_cb
    raise exc
  File "/Users/admin/Library/Python/3.9/lib/python/site-packages/telegram/ext/_updater.py", line 320, in polling_action_cb
    updates = await self.bot.get_updates(
  File "/Users/admin/Library/Python/3.9/lib/python/site-packages/telegram/ext/_extbot.py", line 543, in get_updates
    updates = await super().get_updates(
  File "/Users/admin/Library/Python/3.9/lib/python/site-packages/telegram/_bot.py", line 381, in decorator
    result = await func(self, *args, **kwargs)  # skipcq: PYL-E1102
  File "/Users/admin/Library/Python/3.9/lib/python/site-packages/telegram/_bot.py", line 3661, in get_updates
    await self._post(
  File "/Users/admin/Library/Python/3.9/lib/python/site-packages/telegram/_bot.py", line 469, in _post
    return await self._do_post(
  File "/Users/admin/Library/Python/3.9/lib/python/site-packages/telegram/ext/_extbot.py", line 325, in _do_post
    return await super()._do_post(
  File "/Users/admin/Library/Python/3.9/lib/python/site-packages/telegram/_bot.py", line 497, in _do_post
    return await request.post(
  File "/Users/admin/Library/Python/3.9/lib/python/site-packages/telegram/request/_baserequest.py", line 168, in post
    result = await self._request_wrapper(
  File "/Users/admin/Library/Python/3.9/lib/python/site-packages/telegram/request/_baserequest.py", line 330, in _request_wrapper
    raise Conflict(message)
telegram.error.Conflict: Conflict: terminated by other getUpdates request; make sure that only one bot instance is running
2024-12-06 15:52:58,896 - telegram.ext.Updater - ERROR - Error while getting Updates: Conflict: terminated by other getUpdates request; make sure that only one bot instance is running
2024-12-06 15:52:58,897 - telegram.ext.Application - ERROR - No error handlers are registered, logging exception.
Traceback (most recent call last):
  File "/Users/admin/Library/Python/3.9/lib/python/site-packages/telegram/ext/_updater.py", line 607, in _network_loop_retry
    if not await action_cb():
  File "/Users/admin/Library/Python/3.9/lib/python/site-packages/telegram/ext/_updater.py", line 335, in polling_action_cb
    raise exc
  File "/Users/admin/Library/Python/3.9/lib/python/site-packages/telegram/ext/_updater.py", line 320, in polling_action_cb
    updates = await self.bot.get_updates(
  File "/Users/admin/Library/Python/3.9/lib/python/site-packages/telegram/ext/_extbot.py", line 543, in get_updates
    updates = await super().get_updates(
  File "/Users/admin/Library/Python/3.9/lib/python/site-packages/telegram/_bot.py", line 381, in decorator
    result = await func(self, *args, **kwargs)  # skipcq: PYL-E1102
  File "/Users/admin/Library/Python/3.9/lib/python/site-packages/telegram/_bot.py", line 3661, in get_updates
    await self._post(
  File "/Users/admin/Library/Python/3.9/lib/python/site-packages/telegram/_bot.py", line 469, in _post
    return await self._do_post(
  File "/Users/admin/Library/Python/3.9/lib/python/site-packages/telegram/ext/_extbot.py", line 325, in _do_post
    return await super()._do_post(
  File "/Users/admin/Library/Python/3.9/lib/python/site-packages/telegram/_bot.py", line 497, in _do_post
    return await request.post(
  File "/Users/admin/Library/Python/3.9/lib/python/site-packages/telegram/request/_baserequest.py", line 168, in post
    result = await self._request_wrapper(
  File "/Users/admin/Library/Python/3.9/lib/python/site-packages/telegram/request/_baserequest.py", line 330, in _request_wrapper
    raise Conflict(message)
telegram.error.Conflict: Conflict: terminated by other getUpdates request; make sure that only one bot instance is running
2024-12-06 15:53:32,681 - telegram.ext.Updater - ERROR - Error while getting Updates: Conflict: terminated by other getUpdates request; make sure that only one bot instance is running
2024-12-06 15:53:32,683 - telegram.ext.Application - ERROR - No error handlers are registered, logging exception.
Traceback (most recent call last):
  File "/Users/admin/Library/Python/3.9/lib/python/site-packages/telegram/ext/_updater.py", line 607, in _network_loop_retry
    if not await action_cb():
  File "/Users/admin/Library/Python/3.9/lib/python/site-packages/telegram/ext/_updater.py", line 335, in polling_action_cb
    raise exc
  File "/Users/admin/Library/Python/3.9/lib/python/site-packages/telegram/ext/_updater.py", line 320, in polling_action_cb
    updates = await self.bot.get_updates(
  File "/Users/admin/Library/Python/3.9/lib/python/site-packages/telegram/ext/_extbot.py", line 543, in get_updates
    updates = await super().get_updates(
  File "/Users/admin/Library/Python/3.9/lib/python/site-packages/telegram/_bot.py", line 381, in decorator
    result = await func(self, *args, **kwargs)  # skipcq: PYL-E1102
  File "/Users/admin/Library/Python/3.9/lib/python/site-packages/telegram/_bot.py", line 3661, in get_updates
    await self._post(
  File "/Users/admin/Library/Python/3.9/lib/python/site-packages/telegram/_bot.py", line 469, in _post
    return await self._do_post(
  File "/Users/admin/Library/Python/3.9/lib/python/site-packages/telegram/ext/_extbot.py", line 325, in _do_post
    return await super()._do_post(
  File "/Users/admin/Library/Python/3.9/lib/python/site-packages/telegram/_bot.py", line 497, in _do_post
    return await request.post(
  File "/Users/admin/Library/Python/3.9/lib/python/site-packages/telegram/request/_baserequest.py", line 168, in post
    result = await self._request_wrapper(
  File "/Users/admin/Library/Python/3.9/lib/python/site-packages/telegram/request/_baserequest.py", line 330, in _request_wrapper
    raise Conflict(message)
telegram.error.Conflict: Conflict: terminated by other getUpdates request; make sure that only one bot instance is running
2024-12-06 15:54:06,684 - telegram.ext.Updater - ERROR - Error while getting Updates: Conflict: terminated by other getUpdates request; make sure that only one bot instance is running
2024-12-06 15:54:06,685 - telegram.ext.Application - ERROR - No error handlers are registered, logging exception.
Traceback (most recent call last):
  File "/Users/admin/Library/Python/3.9/lib/python/site-packages/telegram/ext/_updater.py", line 607, in _network_loop_retry
    if not await action_cb():
  File "/Users/admin/Library/Python/3.9/lib/python/site-packages/telegram/ext/_updater.py", line 335, in polling_action_cb
    raise exc
  File "/Users/admin/Library/Python/3.9/lib/python/site-packages/telegram/ext/_updater.py", line 320, in polling_action_cb
    updates = await self.bot.get_updates(
  File "/Users/admin/Library/Python/3.9/lib/python/site-packages/telegram/ext/_extbot.py", line 543, in get_updates
    updates = await super().get_updates(
  File "/Users/admin/Library/Python/3.9/lib/python/site-packages/telegram/_bot.py", line 381, in decorator
    result = await func(self, *args, **kwargs)  # skipcq: PYL-E1102
  File "/Users/admin/Library/Python/3.9/lib/python/site-packages/telegram/_bot.py", line 3661, in get_updates
    await self._post(
  File "/Users/admin/Library/Python/3.9/lib/python/site-packages/telegram/_bot.py", line 469, in _post
    return await self._do_post(
  File "/Users/admin/Library/Python/3.9/lib/python/site-packages/telegram/ext/_extbot.py", line 325, in _do_post
    return await super()._do_post(
  File "/Users/admin/Library/Python/3.9/lib/python/site-packages/telegram/_bot.py", line 497, in _do_post
    return await request.post(
  File "/Users/admin/Library/Python/3.9/lib/python/site-packages/telegram/request/_baserequest.py", line 168, in post
    result = await self._request_wrapper(
  File "/Users/admin/Library/Python/3.9/lib/python/site-packages/telegram/request/_baserequest.py", line 330, in _request_wrapper
    raise Conflict(message)
telegram.error.Conflict: Conflict: terminated by other getUpdates request; make sure that only one bot instance is running
2024-12-06 15:54:40,698 - telegram.ext.Updater - ERROR - Error while getting Updates: Conflict: terminated by other getUpdates request; make sure that only one bot instance is running
2024-12-06 15:54:40,699 - telegram.ext.Application - ERROR - No error handlers are registered, logging exception.
Traceback (most recent call last):
  File "/Users/admin/Library/Python/3.9/lib/python/site-packages/telegram/ext/_updater.py", line 607, in _network_loop_retry
    if not await action_cb():
  File "/Users/admin/Library/Python/3.9/lib/python/site-packages/telegram/ext/_updater.py", line 335, in polling_action_cb
    raise exc
  File "/Users/admin/Library/Python/3.9/lib/python/site-packages/telegram/ext/_updater.py", line 320, in polling_action_cb
    updates = await self.bot.get_updates(
  File "/Users/admin/Library/Python/3.9/lib/python/site-packages/telegram/ext/_extbot.py", line 543, in get_updates
    updates = await super().get_updates(
  File "/Users/admin/Library/Python/3.9/lib/python/site-packages/telegram/_bot.py", line 381, in decorator
    result = await func(self, *args, **kwargs)  # skipcq: PYL-E1102
  File "/Users/admin/Library/Python/3.9/lib/python/site-packages/telegram/_bot.py", line 3661, in get_updates
    await self._post(
  File "/Users/admin/Library/Python/3.9/lib/python/site-packages/telegram/_bot.py", line 469, in _post
    return await self._do_post(
  File "/Users/admin/Library/Python/3.9/lib/python/site-packages/telegram/ext/_extbot.py", line 325, in _do_post
    return await super()._do_post(
  File "/Users/admin/Library/Python/3.9/lib/python/site-packages/telegram/_bot.py", line 497, in _do_post
    return await request.post(
  File "/Users/admin/Library/Python/3.9/lib/python/site-packages/telegram/request/_baserequest.py", line 168, in post
    result = await self._request_wrapper(
  File "/Users/admin/Library/Python/3.9/lib/python/site-packages/telegram/request/_baserequest.py", line 330, in _request_wrapper
    raise Conflict(message)
telegram.error.Conflict: Conflict: terminated by other getUpdates request; make sure that only one bot instance is running
2024-12-06 15:55:14,586 - telegram.ext.Updater - ERROR - Error while getting Updates: Conflict: terminated by other getUpdates request; make sure that only one bot instance is running
2024-12-06 15:55:14,587 - telegram.ext.Application - ERROR - No error handlers are registered, logging exception.
Traceback (most recent call last):
  File "/Users/admin/Library/Python/3.9/lib/python/site-packages/telegram/ext/_updater.py", line 607, in _network_loop_retry
    if not await action_cb():
  File "/Users/admin/Library/Python/3.9/lib/python/site-packages/telegram/ext/_updater.py", line 335, in polling_action_cb
    raise exc
  File "/Users/admin/Library/Python/3.9/lib/python/site-packages/telegram/ext/_updater.py", line 320, in polling_action_cb
    updates = await self.bot.get_updates(
  File "/Users/admin/Library/Python/3.9/lib/python/site-packages/telegram/ext/_extbot.py", line 543, in get_updates
    updates = await super().get_updates(
  File "/Users/admin/Library/Python/3.9/lib/python/site-packages/telegram/_bot.py", line 381, in decorator
    result = await func(self, *args, **kwargs)  # skipcq: PYL-E1102
  File "/Users/admin/Library/Python/3.9/lib/python/site-packages/telegram/_bot.py", line 3661, in get_updates
    await self._post(
  File "/Users/admin/Library/Python/3.9/lib/python/site-packages/telegram/_bot.py", line 469, in _post
    return await self._do_post(
  File "/Users/admin/Library/Python/3.9/lib/python/site-packages/telegram/ext/_extbot.py", line 325, in _do_post
    return await super()._do_post(
  File "/Users/admin/Library/Python/3.9/lib/python/site-packages/telegram/_bot.py", line 497, in _do_post
    return await request.post(
  File "/Users/admin/Library/Python/3.9/lib/python/site-packages/telegram/request/_baserequest.py", line 168, in post
    result = await self._request_wrapper(
  File "/Users/admin/Library/Python/3.9/lib/python/site-packages/telegram/request/_baserequest.py", line 330, in _request_wrapper
    raise Conflict(message)
telegram.error.Conflict: Conflict: terminated by other getUpdates request; make sure that only one bot instance is running
2024-12-06 17:55:44,283 - telegram.ext.Updater - ERROR - Error while getting Updates: Conflict: terminated by other getUpdates request; make sure that only one bot instance is running
2024-12-06 17:55:44,284 - telegram.ext.Application - ERROR - No error handlers are registered, logging exception.
Traceback (most recent call last):
  File "/Users/admin/Library/Python/3.9/lib/python/site-packages/telegram/ext/_updater.py", line 607, in _network_loop_retry
    if not await action_cb():
  File "/Users/admin/Library/Python/3.9/lib/python/site-packages/telegram/ext/_updater.py", line 335, in polling_action_cb
    raise exc
  File "/Users/admin/Library/Python/3.9/lib/python/site-packages/telegram/ext/_updater.py", line 320, in polling_action_cb
    updates = await self.bot.get_updates(
  File "/Users/admin/Library/Python/3.9/lib/python/site-packages/telegram/ext/_extbot.py", line 543, in get_updates
    updates = await super().get_updates(
  File "/Users/admin/Library/Python/3.9/lib/python/site-packages/telegram/_bot.py", line 381, in decorator
    result = await func(self, *args, **kwargs)  # skipcq: PYL-E1102
  File "/Users/admin/Library/Python/3.9/lib/python/site-packages/telegram/_bot.py", line 3661, in get_updates
    await self._post(
  File "/Users/admin/Library/Python/3.9/lib/python/site-packages/telegram/_bot.py", line 469, in _post
    return await self._do_post(
  File "/Users/admin/Library/Python/3.9/lib/python/site-packages/telegram/ext/_extbot.py", line 325, in _do_post
    return await super()._do_post(
  File "/Users/admin/Library/Python/3.9/lib/python/site-packages/telegram/_bot.py", line 497, in _do_post
    return await request.post(
  File "/Users/admin/Library/Python/3.9/lib/python/site-packages/telegram/request/_baserequest.py", line 168, in post
    result = await self._request_wrapper(
  File "/Users/admin/Library/Python/3.9/lib/python/site-packages/telegram/request/_baserequest.py", line 330, in _request_wrapper
    raise Conflict(message)
telegram.error.Conflict: Conflict: terminated by other getUpdates request; make sure that only one bot instance is running
2024-12-06 19:56:28,130 - telegram.ext.Updater - ERROR - Error while getting Updates: Conflict: terminated by other getUpdates request; make sure that only one bot instance is running
2024-12-06 19:56:28,133 - telegram.ext.Application - ERROR - No error handlers are registered, logging exception.
Traceback (most recent call last):
  File "/Users/admin/Library/Python/3.9/lib/python/site-packages/telegram/ext/_updater.py", line 607, in _network_loop_retry
    if not await action_cb():
  File "/Users/admin/Library/Python/3.9/lib/python/site-packages/telegram/ext/_updater.py", line 335, in polling_action_cb
    raise exc
  File "/Users/admin/Library/Python/3.9/lib/python/site-packages/telegram/ext/_updater.py", line 320, in polling_action_cb
    updates = await self.bot.get_updates(
  File "/Users/admin/Library/Python/3.9/lib/python/site-packages/telegram/ext/_extbot.py", line 543, in get_updates
    updates = await super().get_updates(
  File "/Users/admin/Library/Python/3.9/lib/python/site-packages/telegram/_bot.py", line 381, in decorator
    result = await func(self, *args, **kwargs)  # skipcq: PYL-E1102
  File "/Users/admin/Library/Python/3.9/lib/python/site-packages/telegram/_bot.py", line 3661, in get_updates
    await self._post(
  File "/Users/admin/Library/Python/3.9/lib/python/site-packages/telegram/_bot.py", line 469, in _post
    return await self._do_post(
  File "/Users/admin/Library/Python/3.9/lib/python/site-packages/telegram/ext/_extbot.py", line 325, in _do_post
    return await super()._do_post(
  File "/Users/admin/Library/Python/3.9/lib/python/site-packages/telegram/_bot.py", line 497, in _do_post
    return await request.post(
  File "/Users/admin/Library/Python/3.9/lib/python/site-packages/telegram/request/_baserequest.py", line 168, in post
    result = await self._request_wrapper(
  File "/Users/admin/Library/Python/3.9/lib/python/site-packages/telegram/request/_baserequest.py", line 330, in _request_wrapper
    raise Conflict(message)
telegram.error.Conflict: Conflict: terminated by other getUpdates request; make sure that only one bot instance is running
2024-12-06 19:57:02,631 - telegram.ext.Updater - ERROR - Error while getting Updates: Conflict: terminated by other getUpdates request; make sure that only one bot instance is running
2024-12-06 19:57:02,631 - telegram.ext.Application - ERROR - No error handlers are registered, logging exception.
Traceback (most recent call last):
  File "/Users/admin/Library/Python/3.9/lib/python/site-packages/telegram/ext/_updater.py", line 607, in _network_loop_retry
    if not await action_cb():
  File "/Users/admin/Library/Python/3.9/lib/python/site-packages/telegram/ext/_updater.py", line 335, in polling_action_cb
    raise exc
  File "/Users/admin/Library/Python/3.9/lib/python/site-packages/telegram/ext/_updater.py", line 320, in polling_action_cb
    updates = await self.bot.get_updates(
  File "/Users/admin/Library/Python/3.9/lib/python/site-packages/telegram/ext/_extbot.py", line 543, in get_updates
    updates = await super().get_updates(
  File "/Users/admin/Library/Python/3.9/lib/python/site-packages/telegram/_bot.py", line 381, in decorator
    result = await func(self, *args, **kwargs)  # skipcq: PYL-E1102
  File "/Users/admin/Library/Python/3.9/lib/python/site-packages/telegram/_bot.py", line 3661, in get_updates
    await self._post(
  File "/Users/admin/Library/Python/3.9/lib/python/site-packages/telegram/_bot.py", line 469, in _post
    return await self._do_post(
  File "/Users/admin/Library/Python/3.9/lib/python/site-packages/telegram/ext/_extbot.py", line 325, in _do_post
    return await super()._do_post(
  File "/Users/admin/Library/Python/3.9/lib/python/site-packages/telegram/_bot.py", line 497, in _do_post
    return await request.post(
  File "/Users/admin/Library/Python/3.9/lib/python/site-packages/telegram/request/_baserequest.py", line 168, in post
    result = await self._request_wrapper(
  File "/Users/admin/Library/Python/3.9/lib/python/site-packages/telegram/request/_baserequest.py", line 330, in _request_wrapper
    raise Conflict(message)
telegram.error.Conflict: Conflict: terminated by other getUpdates request; make sure that only one bot instance is running
2024-12-06 20:57:46,126 - telegram.ext.Updater - ERROR - Error while getting Updates: Conflict: terminated by other getUpdates request; make sure that only one bot instance is running
2024-12-06 20:57:46,128 - telegram.ext.Application - ERROR - No error handlers are registered, logging exception.
Traceback (most recent call last):
  File "/Users/admin/Library/Python/3.9/lib/python/site-packages/telegram/ext/_updater.py", line 607, in _network_loop_retry
    if not await action_cb():
  File "/Users/admin/Library/Python/3.9/lib/python/site-packages/telegram/ext/_updater.py", line 335, in polling_action_cb
    raise exc
  File "/Users/admin/Library/Python/3.9/lib/python/site-packages/telegram/ext/_updater.py", line 320, in polling_action_cb
    updates = await self.bot.get_updates(
  File "/Users/admin/Library/Python/3.9/lib/python/site-packages/telegram/ext/_extbot.py", line 543, in get_updates
    updates = await super().get_updates(
  File "/Users/admin/Library/Python/3.9/lib/python/site-packages/telegram/_bot.py", line 381, in decorator
    result = await func(self, *args, **kwargs)  # skipcq: PYL-E1102
  File "/Users/admin/Library/Python/3.9/lib/python/site-packages/telegram/_bot.py", line 3661, in get_updates
    await self._post(
  File "/Users/admin/Library/Python/3.9/lib/python/site-packages/telegram/_bot.py", line 469, in _post
    return await self._do_post(
  File "/Users/admin/Library/Python/3.9/lib/python/site-packages/telegram/ext/_extbot.py", line 325, in _do_post
    return await super()._do_post(
  File "/Users/admin/Library/Python/3.9/lib/python/site-packages/telegram/_bot.py", line 497, in _do_post
    return await request.post(
  File "/Users/admin/Library/Python/3.9/lib/python/site-packages/telegram/request/_baserequest.py", line 168, in post
    result = await self._request_wrapper(
  File "/Users/admin/Library/Python/3.9/lib/python/site-packages/telegram/request/_baserequest.py", line 330, in _request_wrapper
    raise Conflict(message)
telegram.error.Conflict: Conflict: terminated by other getUpdates request; make sure that only one bot instance is running
2024-12-06 21:04:07,038 - telegram.ext.Updater - ERROR - Error while getting Updates: Conflict: terminated by other getUpdates request; make sure that only one bot instance is running
2024-12-06 21:04:07,043 - telegram.ext.Application - ERROR - No error handlers are registered, logging exception.
Traceback (most recent call last):
  File "/Users/admin/Library/Python/3.9/lib/python/site-packages/telegram/ext/_updater.py", line 607, in _network_loop_retry
    if not await action_cb():
  File "/Users/admin/Library/Python/3.9/lib/python/site-packages/telegram/ext/_updater.py", line 335, in polling_action_cb
    raise exc
  File "/Users/admin/Library/Python/3.9/lib/python/site-packages/telegram/ext/_updater.py", line 320, in polling_action_cb
    updates = await self.bot.get_updates(
  File "/Users/admin/Library/Python/3.9/lib/python/site-packages/telegram/ext/_extbot.py", line 543, in get_updates
    updates = await super().get_updates(
  File "/Users/admin/Library/Python/3.9/lib/python/site-packages/telegram/_bot.py", line 381, in decorator
    result = await func(self, *args, **kwargs)  # skipcq: PYL-E1102
  File "/Users/admin/Library/Python/3.9/lib/python/site-packages/telegram/_bot.py", line 3661, in get_updates
    await self._post(
  File "/Users/admin/Library/Python/3.9/lib/python/site-packages/telegram/_bot.py", line 469, in _post
    return await self._do_post(
  File "/Users/admin/Library/Python/3.9/lib/python/site-packages/telegram/ext/_extbot.py", line 325, in _do_post
    return await super()._do_post(
  File "/Users/admin/Library/Python/3.9/lib/python/site-packages/telegram/_bot.py", line 497, in _do_post
    return await request.post(
  File "/Users/admin/Library/Python/3.9/lib/python/site-packages/telegram/request/_baserequest.py", line 168, in post
    result = await self._request_wrapper(
  File "/Users/admin/Library/Python/3.9/lib/python/site-packages/telegram/request/_baserequest.py", line 330, in _request_wrapper
    raise Conflict(message)
telegram.error.Conflict: Conflict: terminated by other getUpdates request; make sure that only one bot instance is running
2024-12-06 21:04:42,087 - telegram.ext.Updater - ERROR - Error while getting Updates: Conflict: terminated by other getUpdates request; make sure that only one bot instance is running
2024-12-06 21:04:42,087 - telegram.ext.Application - ERROR - No error handlers are registered, logging exception.
Traceback (most recent call last):
  File "/Users/admin/Library/Python/3.9/lib/python/site-packages/telegram/ext/_updater.py", line 607, in _network_loop_retry
    if not await action_cb():
  File "/Users/admin/Library/Python/3.9/lib/python/site-packages/telegram/ext/_updater.py", line 335, in polling_action_cb
    raise exc
  File "/Users/admin/Library/Python/3.9/lib/python/site-packages/telegram/ext/_updater.py", line 320, in polling_action_cb
    updates = await self.bot.get_updates(
  File "/Users/admin/Library/Python/3.9/lib/python/site-packages/telegram/ext/_extbot.py", line 543, in get_updates
    updates = await super().get_updates(
  File "/Users/admin/Library/Python/3.9/lib/python/site-packages/telegram/_bot.py", line 381, in decorator
    result = await func(self, *args, **kwargs)  # skipcq: PYL-E1102
  File "/Users/admin/Library/Python/3.9/lib/python/site-packages/telegram/_bot.py", line 3661, in get_updates
    await self._post(
  File "/Users/admin/Library/Python/3.9/lib/python/site-packages/telegram/_bot.py", line 469, in _post
    return await self._do_post(
  File "/Users/admin/Library/Python/3.9/lib/python/site-packages/telegram/ext/_extbot.py", line 325, in _do_post
    return await super()._do_post(
  File "/Users/admin/Library/Python/3.9/lib/python/site-packages/telegram/_bot.py", line 497, in _do_post
    return await request.post(
  File "/Users/admin/Library/Python/3.9/lib/python/site-packages/telegram/request/_baserequest.py", line 168, in post
    result = await self._request_wrapper(
  File "/Users/admin/Library/Python/3.9/lib/python/site-packages/telegram/request/_baserequest.py", line 330, in _request_wrapper
    raise Conflict(message)
telegram.error.Conflict: Conflict: terminated by other getUpdates request; make sure that only one bot instance is running
2024-12-06 21:05:16,560 - telegram.ext.Updater - ERROR - Error while getting Updates: Conflict: terminated by other getUpdates request; make sure that only one bot instance is running
2024-12-06 21:05:16,560 - telegram.ext.Application - ERROR - No error handlers are registered, logging exception.
Traceback (most recent call last):
  File "/Users/admin/Library/Python/3.9/lib/python/site-packages/telegram/ext/_updater.py", line 607, in _network_loop_retry
    if not await action_cb():
  File "/Users/admin/Library/Python/3.9/lib/python/site-packages/telegram/ext/_updater.py", line 335, in polling_action_cb
    raise exc
  File "/Users/admin/Library/Python/3.9/lib/python/site-packages/telegram/ext/_updater.py", line 320, in polling_action_cb
    updates = await self.bot.get_updates(
  File "/Users/admin/Library/Python/3.9/lib/python/site-packages/telegram/ext/_extbot.py", line 543, in get_updates
    updates = await super().get_updates(
  File "/Users/admin/Library/Python/3.9/lib/python/site-packages/telegram/_bot.py", line 381, in decorator
    result = await func(self, *args, **kwargs)  # skipcq: PYL-E1102
  File "/Users/admin/Library/Python/3.9/lib/python/site-packages/telegram/_bot.py", line 3661, in get_updates
    await self._post(
  File "/Users/admin/Library/Python/3.9/lib/python/site-packages/telegram/_bot.py", line 469, in _post
    return await self._do_post(
  File "/Users/admin/Library/Python/3.9/lib/python/site-packages/telegram/ext/_extbot.py", line 325, in _do_post
    return await super()._do_post(
  File "/Users/admin/Library/Python/3.9/lib/python/site-packages/telegram/_bot.py", line 497, in _do_post
    return await request.post(
  File "/Users/admin/Library/Python/3.9/lib/python/site-packages/telegram/request/_baserequest.py", line 168, in post
    result = await self._request_wrapper(
  File "/Users/admin/Library/Python/3.9/lib/python/site-packages/telegram/request/_baserequest.py", line 330, in _request_wrapper
    raise Conflict(message)
telegram.error.Conflict: Conflict: terminated by other getUpdates request; make sure that only one bot instance is running
2024-12-06 21:05:48,328 - telegram.ext.Updater - ERROR - Error while getting Updates: Conflict: terminated by other getUpdates request; make sure that only one bot instance is running
2024-12-06 21:05:48,329 - telegram.ext.Application - ERROR - No error handlers are registered, logging exception.
Traceback (most recent call last):
  File "/Users/admin/Library/Python/3.9/lib/python/site-packages/telegram/ext/_updater.py", line 607, in _network_loop_retry
    if not await action_cb():
  File "/Users/admin/Library/Python/3.9/lib/python/site-packages/telegram/ext/_updater.py", line 335, in polling_action_cb
    raise exc
  File "/Users/admin/Library/Python/3.9/lib/python/site-packages/telegram/ext/_updater.py", line 320, in polling_action_cb
    updates = await self.bot.get_updates(
  File "/Users/admin/Library/Python/3.9/lib/python/site-packages/telegram/ext/_extbot.py", line 543, in get_updates
    updates = await super().get_updates(
  File "/Users/admin/Library/Python/3.9/lib/python/site-packages/telegram/_bot.py", line 381, in decorator
    result = await func(self, *args, **kwargs)  # skipcq: PYL-E1102
  File "/Users/admin/Library/Python/3.9/lib/python/site-packages/telegram/_bot.py", line 3661, in get_updates
    await self._post(
  File "/Users/admin/Library/Python/3.9/lib/python/site-packages/telegram/_bot.py", line 469, in _post
    return await self._do_post(
  File "/Users/admin/Library/Python/3.9/lib/python/site-packages/telegram/ext/_extbot.py", line 325, in _do_post
    return await super()._do_post(
  File "/Users/admin/Library/Python/3.9/lib/python/site-packages/telegram/_bot.py", line 497, in _do_post
    return await request.post(
  File "/Users/admin/Library/Python/3.9/lib/python/site-packages/telegram/request/_baserequest.py", line 168, in post
    result = await self._request_wrapper(
  File "/Users/admin/Library/Python/3.9/lib/python/site-packages/telegram/request/_baserequest.py", line 330, in _request_wrapper
    raise Conflict(message)
telegram.error.Conflict: Conflict: terminated by other getUpdates request; make sure that only one bot instance is running
2024-12-06 21:06:22,151 - telegram.ext.Updater - ERROR - Error while getting Updates: Conflict: terminated by other getUpdates request; make sure that only one bot instance is running
2024-12-06 21:06:22,152 - telegram.ext.Application - ERROR - No error handlers are registered, logging exception.
Traceback (most recent call last):
  File "/Users/admin/Library/Python/3.9/lib/python/site-packages/telegram/ext/_updater.py", line 607, in _network_loop_retry
    if not await action_cb():
  File "/Users/admin/Library/Python/3.9/lib/python/site-packages/telegram/ext/_updater.py", line 335, in polling_action_cb
    raise exc
  File "/Users/admin/Library/Python/3.9/lib/python/site-packages/telegram/ext/_updater.py", line 320, in polling_action_cb
    updates = await self.bot.get_updates(
  File "/Users/admin/Library/Python/3.9/lib/python/site-packages/telegram/ext/_extbot.py", line 543, in get_updates
    updates = await super().get_updates(
  File "/Users/admin/Library/Python/3.9/lib/python/site-packages/telegram/_bot.py", line 381, in decorator
    result = await func(self, *args, **kwargs)  # skipcq: PYL-E1102
  File "/Users/admin/Library/Python/3.9/lib/python/site-packages/telegram/_bot.py", line 3661, in get_updates
    await self._post(
  File "/Users/admin/Library/Python/3.9/lib/python/site-packages/telegram/_bot.py", line 469, in _post
    return await self._do_post(
  File "/Users/admin/Library/Python/3.9/lib/python/site-packages/telegram/ext/_extbot.py", line 325, in _do_post
    return await super()._do_post(
  File "/Users/admin/Library/Python/3.9/lib/python/site-packages/telegram/_bot.py", line 497, in _do_post
    return await request.post(
  File "/Users/admin/Library/Python/3.9/lib/python/site-packages/telegram/request/_baserequest.py", line 168, in post
    result = await self._request_wrapper(
  File "/Users/admin/Library/Python/3.9/lib/python/site-packages/telegram/request/_baserequest.py", line 330, in _request_wrapper
    raise Conflict(message)
telegram.error.Conflict: Conflict: terminated by other getUpdates request; make sure that only one bot instance is running
2024-12-06 21:06:57,152 - telegram.ext.Updater - ERROR - Error while getting Updates: Conflict: terminated by other getUpdates request; make sure that only one bot instance is running
2024-12-06 21:06:57,152 - telegram.ext.Application - ERROR - No error handlers are registered, logging exception.
Traceback (most recent call last):
  File "/Users/admin/Library/Python/3.9/lib/python/site-packages/telegram/ext/_updater.py", line 607, in _network_loop_retry
    if not await action_cb():
  File "/Users/admin/Library/Python/3.9/lib/python/site-packages/telegram/ext/_updater.py", line 335, in polling_action_cb
    raise exc
  File "/Users/admin/Library/Python/3.9/lib/python/site-packages/telegram/ext/_updater.py", line 320, in polling_action_cb
    updates = await self.bot.get_updates(
  File "/Users/admin/Library/Python/3.9/lib/python/site-packages/telegram/ext/_extbot.py", line 543, in get_updates
    updates = await super().get_updates(
  File "/Users/admin/Library/Python/3.9/lib/python/site-packages/telegram/_bot.py", line 381, in decorator
    result = await func(self, *args, **kwargs)  # skipcq: PYL-E1102
  File "/Users/admin/Library/Python/3.9/lib/python/site-packages/telegram/_bot.py", line 3661, in get_updates
    await self._post(
  File "/Users/admin/Library/Python/3.9/lib/python/site-packages/telegram/_bot.py", line 469, in _post
    return await self._do_post(
  File "/Users/admin/Library/Python/3.9/lib/python/site-packages/telegram/ext/_extbot.py", line 325, in _do_post
    return await super()._do_post(
  File "/Users/admin/Library/Python/3.9/lib/python/site-packages/telegram/_bot.py", line 497, in _do_post
    return await request.post(
  File "/Users/admin/Library/Python/3.9/lib/python/site-packages/telegram/request/_baserequest.py", line 168, in post
    result = await self._request_wrapper(
  File "/Users/admin/Library/Python/3.9/lib/python/site-packages/telegram/request/_baserequest.py", line 330, in _request_wrapper
    raise Conflict(message)
telegram.error.Conflict: Conflict: terminated by other getUpdates request; make sure that only one bot instance is running
2024-12-06 21:07:31,278 - telegram.ext.Updater - ERROR - Error while getting Updates: Conflict: terminated by other getUpdates request; make sure that only one bot instance is running
2024-12-06 21:07:31,278 - telegram.ext.Application - ERROR - No error handlers are registered, logging exception.
Traceback (most recent call last):
  File "/Users/admin/Library/Python/3.9/lib/python/site-packages/telegram/ext/_updater.py", line 607, in _network_loop_retry
    if not await action_cb():
  File "/Users/admin/Library/Python/3.9/lib/python/site-packages/telegram/ext/_updater.py", line 335, in polling_action_cb
    raise exc
  File "/Users/admin/Library/Python/3.9/lib/python/site-packages/telegram/ext/_updater.py", line 320, in polling_action_cb
    updates = await self.bot.get_updates(
  File "/Users/admin/Library/Python/3.9/lib/python/site-packages/telegram/ext/_extbot.py", line 543, in get_updates
    updates = await super().get_updates(
  File "/Users/admin/Library/Python/3.9/lib/python/site-packages/telegram/_bot.py", line 381, in decorator
    result = await func(self, *args, **kwargs)  # skipcq: PYL-E1102
  File "/Users/admin/Library/Python/3.9/lib/python/site-packages/telegram/_bot.py", line 3661, in get_updates
    await self._post(
  File "/Users/admin/Library/Python/3.9/lib/python/site-packages/telegram/_bot.py", line 469, in _post
    return await self._do_post(
  File "/Users/admin/Library/Python/3.9/lib/python/site-packages/telegram/ext/_extbot.py", line 325, in _do_post
    return await super()._do_post(
  File "/Users/admin/Library/Python/3.9/lib/python/site-packages/telegram/_bot.py", line 497, in _do_post
    return await request.post(
  File "/Users/admin/Library/Python/3.9/lib/python/site-packages/telegram/request/_baserequest.py", line 168, in post
    result = await self._request_wrapper(
  File "/Users/admin/Library/Python/3.9/lib/python/site-packages/telegram/request/_baserequest.py", line 330, in _request_wrapper
    raise Conflict(message)
telegram.error.Conflict: Conflict: terminated by other getUpdates request; make sure that only one bot instance is running
2024-12-06 21:08:05,111 - telegram.ext.Updater - ERROR - Error while getting Updates: Conflict: terminated by other getUpdates request; make sure that only one bot instance is running
2024-12-06 21:08:05,111 - telegram.ext.Application - ERROR - No error handlers are registered, logging exception.
Traceback (most recent call last):
  File "/Users/admin/Library/Python/3.9/lib/python/site-packages/telegram/ext/_updater.py", line 607, in _network_loop_retry
    if not await action_cb():
  File "/Users/admin/Library/Python/3.9/lib/python/site-packages/telegram/ext/_updater.py", line 335, in polling_action_cb
    raise exc
  File "/Users/admin/Library/Python/3.9/lib/python/site-packages/telegram/ext/_updater.py", line 320, in polling_action_cb
    updates = await self.bot.get_updates(
  File "/Users/admin/Library/Python/3.9/lib/python/site-packages/telegram/ext/_extbot.py", line 543, in get_updates
    updates = await super().get_updates(
  File "/Users/admin/Library/Python/3.9/lib/python/site-packages/telegram/_bot.py", line 381, in decorator
    result = await func(self, *args, **kwargs)  # skipcq: PYL-E1102
  File "/Users/admin/Library/Python/3.9/lib/python/site-packages/telegram/_bot.py", line 3661, in get_updates
    await self._post(
  File "/Users/admin/Library/Python/3.9/lib/python/site-packages/telegram/_bot.py", line 469, in _post
    return await self._do_post(
  File "/Users/admin/Library/Python/3.9/lib/python/site-packages/telegram/ext/_extbot.py", line 325, in _do_post
    return await super()._do_post(
  File "/Users/admin/Library/Python/3.9/lib/python/site-packages/telegram/_bot.py", line 497, in _do_post
    return await request.post(
  File "/Users/admin/Library/Python/3.9/lib/python/site-packages/telegram/request/_baserequest.py", line 168, in post
    result = await self._request_wrapper(
  File "/Users/admin/Library/Python/3.9/lib/python/site-packages/telegram/request/_baserequest.py", line 330, in _request_wrapper
    raise Conflict(message)
telegram.error.Conflict: Conflict: terminated by other getUpdates request; make sure that only one bot instance is running
2024-12-06 21:08:39,200 - telegram.ext.Updater - ERROR - Error while getting Updates: Conflict: terminated by other getUpdates request; make sure that only one bot instance is running
2024-12-06 21:08:39,200 - telegram.ext.Application - ERROR - No error handlers are registered, logging exception.
Traceback (most recent call last):
  File "/Users/admin/Library/Python/3.9/lib/python/site-packages/telegram/ext/_updater.py", line 607, in _network_loop_retry
    if not await action_cb():
  File "/Users/admin/Library/Python/3.9/lib/python/site-packages/telegram/ext/_updater.py", line 335, in polling_action_cb
    raise exc
  File "/Users/admin/Library/Python/3.9/lib/python/site-packages/telegram/ext/_updater.py", line 320, in polling_action_cb
    updates = await self.bot.get_updates(
  File "/Users/admin/Library/Python/3.9/lib/python/site-packages/telegram/ext/_extbot.py", line 543, in get_updates
    updates = await super().get_updates(
  File "/Users/admin/Library/Python/3.9/lib/python/site-packages/telegram/_bot.py", line 381, in decorator
    result = await func(self, *args, **kwargs)  # skipcq: PYL-E1102
  File "/Users/admin/Library/Python/3.9/lib/python/site-packages/telegram/_bot.py", line 3661, in get_updates
    await self._post(
  File "/Users/admin/Library/Python/3.9/lib/python/site-packages/telegram/_bot.py", line 469, in _post
    return await self._do_post(
  File "/Users/admin/Library/Python/3.9/lib/python/site-packages/telegram/ext/_extbot.py", line 325, in _do_post
    return await super()._do_post(
  File "/Users/admin/Library/Python/3.9/lib/python/site-packages/telegram/_bot.py", line 497, in _do_post
    return await request.post(
  File "/Users/admin/Library/Python/3.9/lib/python/site-packages/telegram/request/_baserequest.py", line 168, in post
    result = await self._request_wrapper(
  File "/Users/admin/Library/Python/3.9/lib/python/site-packages/telegram/request/_baserequest.py", line 330, in _request_wrapper
    raise Conflict(message)
telegram.error.Conflict: Conflict: terminated by other getUpdates request; make sure that only one bot instance is running
2024-12-06 21:09:14,288 - telegram.ext.Updater - ERROR - Error while getting Updates: Conflict: terminated by other getUpdates request; make sure that only one bot instance is running
2024-12-06 21:09:14,288 - telegram.ext.Application - ERROR - No error handlers are registered, logging exception.
Traceback (most recent call last):
  File "/Users/admin/Library/Python/3.9/lib/python/site-packages/telegram/ext/_updater.py", line 607, in _network_loop_retry
    if not await action_cb():
  File "/Users/admin/Library/Python/3.9/lib/python/site-packages/telegram/ext/_updater.py", line 335, in polling_action_cb
    raise exc
  File "/Users/admin/Library/Python/3.9/lib/python/site-packages/telegram/ext/_updater.py", line 320, in polling_action_cb
    updates = await self.bot.get_updates(
  File "/Users/admin/Library/Python/3.9/lib/python/site-packages/telegram/ext/_extbot.py", line 543, in get_updates
    updates = await super().get_updates(
  File "/Users/admin/Library/Python/3.9/lib/python/site-packages/telegram/_bot.py", line 381, in decorator
    result = await func(self, *args, **kwargs)  # skipcq: PYL-E1102
  File "/Users/admin/Library/Python/3.9/lib/python/site-packages/telegram/_bot.py", line 3661, in get_updates
    await self._post(
  File "/Users/admin/Library/Python/3.9/lib/python/site-packages/telegram/_bot.py", line 469, in _post
    return await self._do_post(
  File "/Users/admin/Library/Python/3.9/lib/python/site-packages/telegram/ext/_extbot.py", line 325, in _do_post
    return await super()._do_post(
  File "/Users/admin/Library/Python/3.9/lib/python/site-packages/telegram/_bot.py", line 497, in _do_post
    return await request.post(
  File "/Users/admin/Library/Python/3.9/lib/python/site-packages/telegram/request/_baserequest.py", line 168, in post
    result = await self._request_wrapper(
  File "/Users/admin/Library/Python/3.9/lib/python/site-packages/telegram/request/_baserequest.py", line 330, in _request_wrapper
    raise Conflict(message)
telegram.error.Conflict: Conflict: terminated by other getUpdates request; make sure that only one bot instance is running
