2024-12-06 15:35:43,584 - telegram.ext.Application - ERROR - No error handlers are registered, logging exception.
Traceback (most recent call last):
  File "/Users/admin/Library/Python/3.9/lib/python/site-packages/telegram/ext/_updater.py", line 607, in _network_loop_retry
    if not await action_cb():
  File "/Users/admin/Library/Python/3.9/lib/python/site-packages/telegram/ext/_updater.py", line 335, in polling_action_cb
    raise exc
  File "/Users/admin/Library/Python/3.9/lib/python/site-packages/telegram/ext/_updater.py", line 320, in polling_action_cb
    updates = await self.bot.get_updates(
  File "/Users/admin/Library/Python/3.9/lib/python/site-packages/telegram/ext/_extbot.py", line 543, in get_updates
    updates = await super().get_updates(
  File "/Users/admin/Library/Python/3.9/lib/python/site-packages/telegram/_bot.py", line 381, in decorator
    result = await func(self, *args, **kwargs)  # skipcq: PYL-E1102
  File "/Users/admin/Library/Python/3.9/lib/python/site-packages/telegram/_bot.py", line 3661, in get_updates
    await self._post(
  File "/Users/admin/Library/Python/3.9/lib/python/site-packages/telegram/_bot.py", line 469, in _post
    return await self._do_post(
  File "/Users/admin/Library/Python/3.9/lib/python/site-packages/telegram/ext/_extbot.py", line 325, in _do_post
    return await super()._do_post(
  File "/Users/admin/Library/Python/3.9/lib/python/site-packages/telegram/_bot.py", line 497, in _do_post
    return await request.post(
  File "/Users/admin/Library/Python/3.9/lib/python/site-packages/telegram/request/_baserequest.py", line 168, in post
    result = await self._request_wrapper(
  File "/Users/admin/Library/Python/3.9/lib/python/site-packages/telegram/request/_baserequest.py", line 330, in _request_wrapper
    raise Conflict(message)
telegram.error.Conflict: Conflict: terminated by other getUpdates request; make sure that only one bot instance is running
2024-12-06 15:36:19,428 - telegram.ext.Updater - ERROR - Error while getting Updates: Conflict: terminated by other getUpdates request; make sure that only one bot instance is running
2024-12-06 15:36:19,428 - telegram.ext.Application - ERROR - No error handlers are registered, logging exception.
Traceback (most recent call last):
  File "/Users/admin/Library/Python/3.9/lib/python/site-packages/telegram/ext/_updater.py", line 607, in _network_loop_retry
    if not await action_cb():
  File "/Users/admin/Library/Python/3.9/lib/python/site-packages/telegram/ext/_updater.py", line 335, in polling_action_cb
    raise exc
  File "/Users/admin/Library/Python/3.9/lib/python/site-packages/telegram/ext/_updater.py", line 320, in polling_action_cb
    updates = await self.bot.get_updates(
  File "/Users/admin/Library/Python/3.9/lib/python/site-packages/telegram/ext/_extbot.py", line 543, in get_updates
    updates = await super().get_updates(
  File "/Users/admin/Library/Python/3.9/lib/python/site-packages/telegram/_bot.py", line 381, in decorator
    result = await func(self, *args, **kwargs)  # skipcq: PYL-E1102
  File "/Users/admin/Library/Python/3.9/lib/python/site-packages/telegram/_bot.py", line 3661, in get_updates
    await self._post(
  File "/Users/admin/Library/Python/3.9/lib/python/site-packages/telegram/_bot.py", line 469, in _post
    return await self._do_post(
  File "/Users/admin/Library/Python/3.9/lib/python/site-packages/telegram/ext/_extbot.py", line 325, in _do_post
    return await super()._do_post(
  File "/Users/admin/Library/Python/3.9/lib/python/site-packages/telegram/_bot.py", line 497, in _do_post
    return await request.post(
  File "/Users/admin/Library/Python/3.9/lib/python/site-packages/telegram/request/_baserequest.py", line 168, in post
    result = await self._request_wrapper(
  File "/Users/admin/Library/Python/3.9/lib/python/site-packages/telegram/request/_baserequest.py", line 330, in _request_wrapper
    raise Conflict(message)
telegram.error.Conflict: Conflict: terminated by other getUpdates request; make sure that only one bot instance is running
2024-12-06 15:36:55,282 - telegram.ext.Updater - ERROR - Error while getting Updates: Conflict: terminated by other getUpdates request; make sure that only one bot instance is running
2024-12-06 15:36:55,282 - telegram.ext.Application - ERROR - No error handlers are registered, logging exception.
Traceback (most recent call last):
  File "/Users/admin/Library/Python/3.9/lib/python/site-packages/telegram/ext/_updater.py", line 607, in _network_loop_retry
    if not await action_cb():
  File "/Users/admin/Library/Python/3.9/lib/python/site-packages/telegram/ext/_updater.py", line 335, in polling_action_cb
    raise exc
  File "/Users/admin/Library/Python/3.9/lib/python/site-packages/telegram/ext/_updater.py", line 320, in polling_action_cb
    updates = await self.bot.get_updates(
  File "/Users/admin/Library/Python/3.9/lib/python/site-packages/telegram/ext/_extbot.py", line 543, in get_updates
    updates = await super().get_updates(
  File "/Users/admin/Library/Python/3.9/lib/python/site-packages/telegram/_bot.py", line 381, in decorator
    result = await func(self, *args, **kwargs)  # skipcq: PYL-E1102
  File "/Users/admin/Library/Python/3.9/lib/python/site-packages/telegram/_bot.py", line 3661, in get_updates
    await self._post(
  File "/Users/admin/Library/Python/3.9/lib/python/site-packages/telegram/_bot.py", line 469, in _post
    return await self._do_post(
  File "/Users/admin/Library/Python/3.9/lib/python/site-packages/telegram/ext/_extbot.py", line 325, in _do_post
    return await super()._do_post(
  File "/Users/admin/Library/Python/3.9/lib/python/site-packages/telegram/_bot.py", line 497, in _do_post
    return await request.post(
  File "/Users/admin/Library/Python/3.9/lib/python/site-packages/telegram/request/_baserequest.py", line 168, in post
    result = await self._request_wrapper(
  File "/Users/admin/Library/Python/3.9/lib/python/site-packages/telegram/request/_baserequest.py", line 330, in _request_wrapper
    raise Conflict(message)
telegram.error.Conflict: Conflict: terminated by other getUpdates request; make sure that only one bot instance is running
2024-12-06 15:37:31,033 - telegram.ext.Updater - ERROR - Error while getting Updates: Conflict: terminated by other getUpdates request; make sure that only one bot instance is running
2024-12-06 15:37:31,033 - telegram.ext.Application - ERROR - No error handlers are registered, logging exception.
Traceback (most recent call last):
  File "/Users/admin/Library/Python/3.9/lib/python/site-packages/telegram/ext/_updater.py", line 607, in _network_loop_retry
    if not await action_cb():
  File "/Users/admin/Library/Python/3.9/lib/python/site-packages/telegram/ext/_updater.py", line 335, in polling_action_cb
    raise exc
  File "/Users/admin/Library/Python/3.9/lib/python/site-packages/telegram/ext/_updater.py", line 320, in polling_action_cb
    updates = await self.bot.get_updates(
  File "/Users/admin/Library/Python/3.9/lib/python/site-packages/telegram/ext/_extbot.py", line 543, in get_updates
    updates = await super().get_updates(
  File "/Users/admin/Library/Python/3.9/lib/python/site-packages/telegram/_bot.py", line 381, in decorator
    result = await func(self, *args, **kwargs)  # skipcq: PYL-E1102
  File "/Users/admin/Library/Python/3.9/lib/python/site-packages/telegram/_bot.py", line 3661, in get_updates
    await self._post(
  File "/Users/admin/Library/Python/3.9/lib/python/site-packages/telegram/_bot.py", line 469, in _post
    return await self._do_post(
  File "/Users/admin/Library/Python/3.9/lib/python/site-packages/telegram/ext/_extbot.py", line 325, in _do_post
    return await super()._do_post(
  File "/Users/admin/Library/Python/3.9/lib/python/site-packages/telegram/_bot.py", line 497, in _do_post
    return await request.post(
  File "/Users/admin/Library/Python/3.9/lib/python/site-packages/telegram/request/_baserequest.py", line 168, in post
    result = await self._request_wrapper(
  File "/Users/admin/Library/Python/3.9/lib/python/site-packages/telegram/request/_baserequest.py", line 330, in _request_wrapper
    raise Conflict(message)
telegram.error.Conflict: Conflict: terminated by other getUpdates request; make sure that only one bot instance is running
2024-12-06 15:38:05,732 - telegram.ext.Updater - ERROR - Error while getting Updates: Conflict: terminated by other getUpdates request; make sure that only one bot instance is running
2024-12-06 15:38:05,733 - telegram.ext.Application - ERROR - No error handlers are registered, logging exception.
Traceback (most recent call last):
  File "/Users/admin/Library/Python/3.9/lib/python/site-packages/telegram/ext/_updater.py", line 607, in _network_loop_retry
    if not await action_cb():
  File "/Users/admin/Library/Python/3.9/lib/python/site-packages/telegram/ext/_updater.py", line 335, in polling_action_cb
    raise exc
  File "/Users/admin/Library/Python/3.9/lib/python/site-packages/telegram/ext/_updater.py", line 320, in polling_action_cb
    updates = await self.bot.get_updates(
  File "/Users/admin/Library/Python/3.9/lib/python/site-packages/telegram/ext/_extbot.py", line 543, in get_updates
    updates = await super().get_updates(
  File "/Users/admin/Library/Python/3.9/lib/python/site-packages/telegram/_bot.py", line 381, in decorator
    result = await func(self, *args, **kwargs)  # skipcq: PYL-E1102
  File "/Users/admin/Library/Python/3.9/lib/python/site-packages/telegram/_bot.py", line 3661, in get_updates
    await self._post(
  File "/Users/admin/Library/Python/3.9/lib/python/site-packages/telegram/_bot.py", line 469, in _post
    return await self._do_post(
  File "/Users/admin/Library/Python/3.9/lib/python/site-packages/telegram/ext/_extbot.py", line 325, in _do_post
    return await super()._do_post(
  File "/Users/admin/Library/Python/3.9/lib/python/site-packages/telegram/_bot.py", line 497, in _do_post
    return await request.post(
  File "/Users/admin/Library/Python/3.9/lib/python/site-packages/telegram/request/_baserequest.py", line 168, in post
    result = await self._request_wrapper(
  File "/Users/admin/Library/Python/3.9/lib/python/site-packages/telegram/request/_baserequest.py", line 330, in _request_wrapper
    raise Conflict(message)
telegram.error.Conflict: Conflict: terminated by other getUpdates request; make sure that only one bot instance is running
2024-12-06 15:38:40,344 - telegram.ext.Updater - ERROR - Error while getting Updates: Conflict: terminated by other getUpdates request; make sure that only one bot instance is running
2024-12-06 15:38:40,344 - telegram.ext.Application - ERROR - No error handlers are registered, logging exception.
Traceback (most recent call last):
  File "/Users/admin/Library/Python/3.9/lib/python/site-packages/telegram/ext/_updater.py", line 607, in _network_loop_retry
    if not await action_cb():
  File "/Users/admin/Library/Python/3.9/lib/python/site-packages/telegram/ext/_updater.py", line 335, in polling_action_cb
    raise exc
  File "/Users/admin/Library/Python/3.9/lib/python/site-packages/telegram/ext/_updater.py", line 320, in polling_action_cb
    updates = await self.bot.get_updates(
  File "/Users/admin/Library/Python/3.9/lib/python/site-packages/telegram/ext/_extbot.py", line 543, in get_updates
    updates = await super().get_updates(
  File "/Users/admin/Library/Python/3.9/lib/python/site-packages/telegram/_bot.py", line 381, in decorator
    result = await func(self, *args, **kwargs)  # skipcq: PYL-E1102
  File "/Users/admin/Library/Python/3.9/lib/python/site-packages/telegram/_bot.py", line 3661, in get_updates
    await self._post(
  File "/Users/admin/Library/Python/3.9/lib/python/site-packages/telegram/_bot.py", line 469, in _post
    return await self._do_post(
  File "/Users/admin/Library/Python/3.9/lib/python/site-packages/telegram/ext/_extbot.py", line 325, in _do_post
    return await super()._do_post(
  File "/Users/admin/Library/Python/3.9/lib/python/site-packages/telegram/_bot.py", line 497, in _do_post
    return await request.post(
  File "/Users/admin/Library/Python/3.9/lib/python/site-packages/telegram/request/_baserequest.py", line 168, in post
    result = await self._request_wrapper(
  File "/Users/admin/Library/Python/3.9/lib/python/site-packages/telegram/request/_baserequest.py", line 330, in _request_wrapper
    raise Conflict(message)
telegram.error.Conflict: Conflict: terminated by other getUpdates request; make sure that only one bot instance is running
2024-12-06 15:39:14,954 - telegram.ext.Updater - ERROR - Error while getting Updates: Conflict: terminated by other getUpdates request; make sure that only one bot instance is running
2024-12-06 15:39:14,954 - telegram.ext.Application - ERROR - No error handlers are registered, logging exception.
Traceback (most recent call last):
  File "/Users/admin/Library/Python/3.9/lib/python/site-packages/telegram/ext/_updater.py", line 607, in _network_loop_retry
    if not await action_cb():
  File "/Users/admin/Library/Python/3.9/lib/python/site-packages/telegram/ext/_updater.py", line 335, in polling_action_cb
    raise exc
  File "/Users/admin/Library/Python/3.9/lib/python/site-packages/telegram/ext/_updater.py", line 320, in polling_action_cb
    updates = await self.bot.get_updates(
  File "/Users/admin/Library/Python/3.9/lib/python/site-packages/telegram/ext/_extbot.py", line 543, in get_updates
    updates = await super().get_updates(
  File "/Users/admin/Library/Python/3.9/lib/python/site-packages/telegram/_bot.py", line 381, in decorator
    result = await func(self, *args, **kwargs)  # skipcq: PYL-E1102
  File "/Users/admin/Library/Python/3.9/lib/python/site-packages/telegram/_bot.py", line 3661, in get_updates
    await self._post(
  File "/Users/admin/Library/Python/3.9/lib/python/site-packages/telegram/_bot.py", line 469, in _post
    return await self._do_post(
  File "/Users/admin/Library/Python/3.9/lib/python/site-packages/telegram/ext/_extbot.py", line 325, in _do_post
    return await super()._do_post(
  File "/Users/admin/Library/Python/3.9/lib/python/site-packages/telegram/_bot.py", line 497, in _do_post
    return await request.post(
  File "/Users/admin/Library/Python/3.9/lib/python/site-packages/telegram/request/_baserequest.py", line 168, in post
    result = await self._request_wrapper(
  File "/Users/admin/Library/Python/3.9/lib/python/site-packages/telegram/request/_baserequest.py", line 330, in _request_wrapper
    raise Conflict(message)
telegram.error.Conflict: Conflict: terminated by other getUpdates request; make sure that only one bot instance is running
2024-12-06 15:39:49,591 - telegram.ext.Updater - ERROR - Error while getting Updates: Conflict: terminated by other getUpdates request; make sure that only one bot instance is running
2024-12-06 15:39:49,594 - telegram.ext.Application - ERROR - No error handlers are registered, logging exception.
Traceback (most recent call last):
  File "/Users/admin/Library/Python/3.9/lib/python/site-packages/telegram/ext/_updater.py", line 607, in _network_loop_retry
    if not await action_cb():
  File "/Users/admin/Library/Python/3.9/lib/python/site-packages/telegram/ext/_updater.py", line 335, in polling_action_cb
    raise exc
  File "/Users/admin/Library/Python/3.9/lib/python/site-packages/telegram/ext/_updater.py", line 320, in polling_action_cb
    updates = await self.bot.get_updates(
  File "/Users/admin/Library/Python/3.9/lib/python/site-packages/telegram/ext/_extbot.py", line 543, in get_updates
    updates = await super().get_updates(
  File "/Users/admin/Library/Python/3.9/lib/python/site-packages/telegram/_bot.py", line 381, in decorator
    result = await func(self, *args, **kwargs)  # skipcq: PYL-E1102
  File "/Users/admin/Library/Python/3.9/lib/python/site-packages/telegram/_bot.py", line 3661, in get_updates
    await self._post(
  File "/Users/admin/Library/Python/3.9/lib/python/site-packages/telegram/_bot.py", line 469, in _post
    return await self._do_post(
  File "/Users/admin/Library/Python/3.9/lib/python/site-packages/telegram/ext/_extbot.py", line 325, in _do_post
    return await super()._do_post(
  File "/Users/admin/Library/Python/3.9/lib/python/site-packages/telegram/_bot.py", line 497, in _do_post
    return await request.post(
  File "/Users/admin/Library/Python/3.9/lib/python/site-packages/telegram/request/_baserequest.py", line 168, in post
    result = await self._request_wrapper(
  File "/Users/admin/Library/Python/3.9/lib/python/site-packages/telegram/request/_baserequest.py", line 330, in _request_wrapper
    raise Conflict(message)
telegram.error.Conflict: Conflict: terminated by other getUpdates request; make sure that only one bot instance is running
2024-12-06 15:40:25,193 - telegram.ext.Updater - ERROR - Error while getting Updates: Conflict: terminated by other getUpdates request; make sure that only one bot instance is running
2024-12-06 15:40:25,194 - telegram.ext.Application - ERROR - No error handlers are registered, logging exception.
Traceback (most recent call last):
  File "/Users/admin/Library/Python/3.9/lib/python/site-packages/telegram/ext/_updater.py", line 607, in _network_loop_retry
    if not await action_cb():
  File "/Users/admin/Library/Python/3.9/lib/python/site-packages/telegram/ext/_updater.py", line 335, in polling_action_cb
    raise exc
  File "/Users/admin/Library/Python/3.9/lib/python/site-packages/telegram/ext/_updater.py", line 320, in polling_action_cb
    updates = await self.bot.get_updates(
  File "/Users/admin/Library/Python/3.9/lib/python/site-packages/telegram/ext/_extbot.py", line 543, in get_updates
    updates = await super().get_updates(
  File "/Users/admin/Library/Python/3.9/lib/python/site-packages/telegram/_bot.py", line 381, in decorator
    result = await func(self, *args, **kwargs)  # skipcq: PYL-E1102
  File "/Users/admin/Library/Python/3.9/lib/python/site-packages/telegram/_bot.py", line 3661, in get_updates
    await self._post(
  File "/Users/admin/Library/Python/3.9/lib/python/site-packages/telegram/_bot.py", line 469, in _post
    return await self._do_post(
  File "/Users/admin/Library/Python/3.9/lib/python/site-packages/telegram/ext/_extbot.py", line 325, in _do_post
    return await super()._do_post(
  File "/Users/admin/Library/Python/3.9/lib/python/site-packages/telegram/_bot.py", line 497, in _do_post
    return await request.post(
  File "/Users/admin/Library/Python/3.9/lib/python/site-packages/telegram/request/_baserequest.py", line 168, in post
    result = await self._request_wrapper(
  File "/Users/admin/Library/Python/3.9/lib/python/site-packages/telegram/request/_baserequest.py", line 330, in _request_wrapper
    raise Conflict(message)
telegram.error.Conflict: Conflict: terminated by other getUpdates request; make sure that only one bot instance is running
2024-12-06 15:40:59,560 - telegram.ext.Updater - ERROR - Error while getting Updates: Conflict: terminated by other getUpdates request; make sure that only one bot instance is running
2024-12-06 15:40:59,561 - telegram.ext.Application - ERROR - No error handlers are registered, logging exception.
Traceback (most recent call last):
  File "/Users/admin/Library/Python/3.9/lib/python/site-packages/telegram/ext/_updater.py", line 607, in _network_loop_retry
    if not await action_cb():
  File "/Users/admin/Library/Python/3.9/lib/python/site-packages/telegram/ext/_updater.py", line 335, in polling_action_cb
    raise exc
  File "/Users/admin/Library/Python/3.9/lib/python/site-packages/telegram/ext/_updater.py", line 320, in polling_action_cb
    updates = await self.bot.get_updates(
  File "/Users/admin/Library/Python/3.9/lib/python/site-packages/telegram/ext/_extbot.py", line 543, in get_updates
    updates = await super().get_updates(
  File "/Users/admin/Library/Python/3.9/lib/python/site-packages/telegram/_bot.py", line 381, in decorator
    result = await func(self, *args, **kwargs)  # skipcq: PYL-E1102
  File "/Users/admin/Library/Python/3.9/lib/python/site-packages/telegram/_bot.py", line 3661, in get_updates
    await self._post(
  File "/Users/admin/Library/Python/3.9/lib/python/site-packages/telegram/_bot.py", line 469, in _post
    return await self._do_post(
  File "/Users/admin/Library/Python/3.9/lib/python/site-packages/telegram/ext/_extbot.py", line 325, in _do_post
    return await super()._do_post(
  File "/Users/admin/Library/Python/3.9/lib/python/site-packages/telegram/_bot.py", line 497, in _do_post
    return await request.post(
  File "/Users/admin/Library/Python/3.9/lib/python/site-packages/telegram/request/_baserequest.py", line 168, in post
    result = await self._request_wrapper(
  File "/Users/admin/Library/Python/3.9/lib/python/site-packages/telegram/request/_baserequest.py", line 330, in _request_wrapper
    raise Conflict(message)
telegram.error.Conflict: Conflict: terminated by other getUpdates request; make sure that only one bot instance is running
2024-12-06 15:41:33,580 - telegram.ext.Updater - ERROR - Error while getting Updates: Conflict: terminated by other getUpdates request; make sure that only one bot instance is running
2024-12-06 15:41:33,581 - telegram.ext.Application - ERROR - No error handlers are registered, logging exception.
Traceback (most recent call last):
  File "/Users/admin/Library/Python/3.9/lib/python/site-packages/telegram/ext/_updater.py", line 607, in _network_loop_retry
    if not await action_cb():
  File "/Users/admin/Library/Python/3.9/lib/python/site-packages/telegram/ext/_updater.py", line 335, in polling_action_cb
    raise exc
  File "/Users/admin/Library/Python/3.9/lib/python/site-packages/telegram/ext/_updater.py", line 320, in polling_action_cb
    updates = await self.bot.get_updates(
  File "/Users/admin/Library/Python/3.9/lib/python/site-packages/telegram/ext/_extbot.py", line 543, in get_updates
    updates = await super().get_updates(
  File "/Users/admin/Library/Python/3.9/lib/python/site-packages/telegram/_bot.py", line 381, in decorator
    result = await func(self, *args, **kwargs)  # skipcq: PYL-E1102
  File "/Users/admin/Library/Python/3.9/lib/python/site-packages/telegram/_bot.py", line 3661, in get_updates
    await self._post(
  File "/Users/admin/Library/Python/3.9/lib/python/site-packages/telegram/_bot.py", line 469, in _post
    return await self._do_post(
  File "/Users/admin/Library/Python/3.9/lib/python/site-packages/telegram/ext/_extbot.py", line 325, in _do_post
    return await super()._do_post(
  File "/Users/admin/Library/Python/3.9/lib/python/site-packages/telegram/_bot.py", line 497, in _do_post
    return await request.post(
  File "/Users/admin/Library/Python/3.9/lib/python/site-packages/telegram/request/_baserequest.py", line 168, in post
    result = await self._request_wrapper(
  File "/Users/admin/Library/Python/3.9/lib/python/site-packages/telegram/request/_baserequest.py", line 330, in _request_wrapper
    raise Conflict(message)
telegram.error.Conflict: Conflict: terminated by other getUpdates request; make sure that only one bot instance is running
2024-12-06 15:42:08,092 - telegram.ext.Updater - ERROR - Error while getting Updates: Conflict: terminated by other getUpdates request; make sure that only one bot instance is running
2024-12-06 15:42:08,092 - telegram.ext.Application - ERROR - No error handlers are registered, logging exception.
Traceback (most recent call last):
  File "/Users/admin/Library/Python/3.9/lib/python/site-packages/telegram/ext/_updater.py", line 607, in _network_loop_retry
    if not await action_cb():
  File "/Users/admin/Library/Python/3.9/lib/python/site-packages/telegram/ext/_updater.py", line 335, in polling_action_cb
    raise exc
  File "/Users/admin/Library/Python/3.9/lib/python/site-packages/telegram/ext/_updater.py", line 320, in polling_action_cb
    updates = await self.bot.get_updates(
  File "/Users/admin/Library/Python/3.9/lib/python/site-packages/telegram/ext/_extbot.py", line 543, in get_updates
    updates = await super().get_updates(
  File "/Users/admin/Library/Python/3.9/lib/python/site-packages/telegram/_bot.py", line 381, in decorator
    result = await func(self, *args, **kwargs)  # skipcq: PYL-E1102
  File "/Users/admin/Library/Python/3.9/lib/python/site-packages/telegram/_bot.py", line 3661, in get_updates
    await self._post(
  File "/Users/admin/Library/Python/3.9/lib/python/site-packages/telegram/_bot.py", line 469, in _post
    return await self._do_post(
  File "/Users/admin/Library/Python/3.9/lib/python/site-packages/telegram/ext/_extbot.py", line 325, in _do_post
    return await super()._do_post(
  File "/Users/admin/Library/Python/3.9/lib/python/site-packages/telegram/_bot.py", line 497, in _do_post
    return await request.post(
  File "/Users/admin/Library/Python/3.9/lib/python/site-packages/telegram/request/_baserequest.py", line 168, in post
    result = await self._request_wrapper(
  File "/Users/admin/Library/Python/3.9/lib/python/site-packages/telegram/request/_baserequest.py", line 330, in _request_wrapper
    raise Conflict(message)
telegram.error.Conflict: Conflict: terminated by other getUpdates request; make sure that only one bot instance is running
2024-12-06 15:42:42,059 - telegram.ext.Updater - ERROR - Error while getting Updates: Conflict: terminated by other getUpdates request; make sure that only one bot instance is running
2024-12-06 15:42:42,060 - telegram.ext.Application - ERROR - No error handlers are registered, logging exception.
Traceback (most recent call last):
  File "/Users/admin/Library/Python/3.9/lib/python/site-packages/telegram/ext/_updater.py", line 607, in _network_loop_retry
    if not await action_cb():
  File "/Users/admin/Library/Python/3.9/lib/python/site-packages/telegram/ext/_updater.py", line 335, in polling_action_cb
    raise exc
  File "/Users/admin/Library/Python/3.9/lib/python/site-packages/telegram/ext/_updater.py", line 320, in polling_action_cb
    updates = await self.bot.get_updates(
  File "/Users/admin/Library/Python/3.9/lib/python/site-packages/telegram/ext/_extbot.py", line 543, in get_updates
    updates = await super().get_updates(
  File "/Users/admin/Library/Python/3.9/lib/python/site-packages/telegram/_bot.py", line 381, in decorator
    result = await func(self, *args, **kwargs)  # skipcq: PYL-E1102
  File "/Users/admin/Library/Python/3.9/lib/python/site-packages/telegram/_bot.py", line 3661, in get_updates
    await self._post(
  File "/Users/admin/Library/Python/3.9/lib/python/site-packages/telegram/_bot.py", line 469, in _post
    return await self._do_post(
  File "/Users/admin/Library/Python/3.9/lib/python/site-packages/telegram/ext/_extbot.py", line 325, in _do_post
    return await super()._do_post(
  File "/Users/admin/Library/Python/3.9/lib/python/site-packages/telegram/_bot.py", line 497, in _do_post
    return await request.post(
  File "/Users/admin/Library/Python/3.9/lib/python/site-packages/telegram/request/_baserequest.py", line 168, in post
    result = await self._request_wrapper(
  File "/Users/admin/Library/Python/3.9/lib/python/site-packages/telegram/request/_baserequest.py", line 330, in _request_wrapper
    raise Conflict(message)
telegram.error.Conflict: Conflict: terminated by other getUpdates request; make sure that only one bot instance is running
2024-12-06 15:43:16,571 - telegram.ext.Updater - ERROR - Error while getting Updates: Conflict: terminated by other getUpdates request; make sure that only one bot instance is running
2024-12-06 15:43:16,572 - telegram.ext.Application - ERROR - No error handlers are registered, logging exception.
Traceback (most recent call last):
  File "/Users/admin/Library/Python/3.9/lib/python/site-packages/telegram/ext/_updater.py", line 607, in _network_loop_retry
    if not await action_cb():
  File "/Users/admin/Library/Python/3.9/lib/python/site-packages/telegram/ext/_updater.py", line 335, in polling_action_cb
    raise exc
  File "/Users/admin/Library/Python/3.9/lib/python/site-packages/telegram/ext/_updater.py", line 320, in polling_action_cb
    updates = await self.bot.get_updates(
  File "/Users/admin/Library/Python/3.9/lib/python/site-packages/telegram/ext/_extbot.py", line 543, in get_updates
    updates = await super().get_updates(
  File "/Users/admin/Library/Python/3.9/lib/python/site-packages/telegram/_bot.py", line 381, in decorator
    result = await func(self, *args, **kwargs)  # skipcq: PYL-E1102
  File "/Users/admin/Library/Python/3.9/lib/python/site-packages/telegram/_bot.py", line 3661, in get_updates
    await self._post(
  File "/Users/admin/Library/Python/3.9/lib/python/site-packages/telegram/_bot.py", line 469, in _post
    return await self._do_post(
  File "/Users/admin/Library/Python/3.9/lib/python/site-packages/telegram/ext/_extbot.py", line 325, in _do_post
    return await super()._do_post(
  File "/Users/admin/Library/Python/3.9/lib/python/site-packages/telegram/_bot.py", line 497, in _do_post
    return await request.post(
  File "/Users/admin/Library/Python/3.9/lib/python/site-packages/telegram/request/_baserequest.py", line 168, in post
    result = await self._request_wrapper(
  File "/Users/admin/Library/Python/3.9/lib/python/site-packages/telegram/request/_baserequest.py", line 330, in _request_wrapper
    raise Conflict(message)
telegram.error.Conflict: Conflict: terminated by other getUpdates request; make sure that only one bot instance is running
2024-12-06 15:43:50,567 - telegram.ext.Updater - ERROR - Error while getting Updates: Conflict: terminated by other getUpdates request; make sure that only one bot instance is running
2024-12-06 15:43:50,569 - telegram.ext.Application - ERROR - No error handlers are registered, logging exception.
Traceback (most recent call last):
  File "/Users/admin/Library/Python/3.9/lib/python/site-packages/telegram/ext/_updater.py", line 607, in _network_loop_retry
    if not await action_cb():
  File "/Users/admin/Library/Python/3.9/lib/python/site-packages/telegram/ext/_updater.py", line 335, in polling_action_cb
    raise exc
  File "/Users/admin/Library/Python/3.9/lib/python/site-packages/telegram/ext/_updater.py", line 320, in polling_action_cb
    updates = await self.bot.get_updates(
  File "/Users/admin/Library/Python/3.9/lib/python/site-packages/telegram/ext/_extbot.py", line 543, in get_updates
    updates = await super().get_updates(
  File "/Users/admin/Library/Python/3.9/lib/python/site-packages/telegram/_bot.py", line 381, in decorator
    result = await func(self, *args, **kwargs)  # skipcq: PYL-E1102
  File "/Users/admin/Library/Python/3.9/lib/python/site-packages/telegram/_bot.py", line 3661, in get_updates
    await self._post(
  File "/Users/admin/Library/Python/3.9/lib/python/site-packages/telegram/_bot.py", line 469, in _post
    return await self._do_post(
  File "/Users/admin/Library/Python/3.9/lib/python/site-packages/telegram/ext/_extbot.py", line 325, in _do_post
    return await super()._do_post(
  File "/Users/admin/Library/Python/3.9/lib/python/site-packages/telegram/_bot.py", line 497, in _do_post
    return await request.post(
  File "/Users/admin/Library/Python/3.9/lib/python/site-packages/telegram/request/_baserequest.py", line 168, in post
    result = await self._request_wrapper(
  File "/Users/admin/Library/Python/3.9/lib/python/site-packages/telegram/request/_baserequest.py", line 330, in _request_wrapper
    raise Conflict(message)
telegram.error.Conflict: Conflict: terminated by other getUpdates request; make sure that only one bot instance is running
2024-12-06 15:44:25,281 - telegram.ext.Updater - ERROR - Error while getting Updates: Conflict: terminated by other getUpdates request; make sure that only one bot instance is running
2024-12-06 15:44:25,283 - telegram.ext.Application - ERROR - No error handlers are registered, logging exception.
Traceback (most recent call last):
  File "/Users/admin/Library/Python/3.9/lib/python/site-packages/telegram/ext/_updater.py", line 607, in _network_loop_retry
    if not await action_cb():
  File "/Users/admin/Library/Python/3.9/lib/python/site-packages/telegram/ext/_updater.py", line 335, in polling_action_cb
    raise exc
  File "/Users/admin/Library/Python/3.9/lib/python/site-packages/telegram/ext/_updater.py", line 320, in polling_action_cb
    updates = await self.bot.get_updates(
  File "/Users/admin/Library/Python/3.9/lib/python/site-packages/telegram/ext/_extbot.py", line 543, in get_updates
    updates = await super().get_updates(
  File "/Users/admin/Library/Python/3.9/lib/python/site-packages/telegram/_bot.py", line 381, in decorator
    result = await func(self, *args, **kwargs)  # skipcq: PYL-E1102
  File "/Users/admin/Library/Python/3.9/lib/python/site-packages/telegram/_bot.py", line 3661, in get_updates
    await self._post(
  File "/Users/admin/Library/Python/3.9/lib/python/site-packages/telegram/_bot.py", line 469, in _post
    return await self._do_post(
  File "/Users/admin/Library/Python/3.9/lib/python/site-packages/telegram/ext/_extbot.py", line 325, in _do_post
    return await super()._do_post(
  File "/Users/admin/Library/Python/3.9/lib/python/site-packages/telegram/_bot.py", line 497, in _do_post
    return await request.post(
  File "/Users/admin/Library/Python/3.9/lib/python/site-packages/telegram/request/_baserequest.py", line 168, in post
    result = await self._request_wrapper(
  File "/Users/admin/Library/Python/3.9/lib/python/site-packages/telegram/request/_baserequest.py", line 330, in _request_wrapper
    raise Conflict(message)
telegram.error.Conflict: Conflict: terminated by other getUpdates request; make sure that only one bot instance is running
2024-12-06 15:44:59,074 - telegram.ext.Updater - ERROR - Error while getting Updates: Conflict: terminated by other getUpdates request; make sure that only one bot instance is running
2024-12-06 15:44:59,075 - telegram.ext.Application - ERROR - No error handlers are registered, logging exception.
Traceback (most recent call last):
  File "/Users/admin/Library/Python/3.9/lib/python/site-packages/telegram/ext/_updater.py", line 607, in _network_loop_retry
    if not await action_cb():
  File "/Users/admin/Library/Python/3.9/lib/python/site-packages/telegram/ext/_updater.py", line 335, in polling_action_cb
    raise exc
  File "/Users/admin/Library/Python/3.9/lib/python/site-packages/telegram/ext/_updater.py", line 320, in polling_action_cb
    updates = await self.bot.get_updates(
  File "/Users/admin/Library/Python/3.9/lib/python/site-packages/telegram/ext/_extbot.py", line 543, in get_updates
    updates = await super().get_updates(
  File "/Users/admin/Library/Python/3.9/lib/python/site-packages/telegram/_bot.py", line 381, in decorator
    result = await func(self, *args, **kwargs)  # skipcq: PYL-E1102
  File "/Users/admin/Library/Python/3.9/lib/python/site-packages/telegram/_bot.py", line 3661, in get_updates
    await self._post(
  File "/Users/admin/Library/Python/3.9/lib/python/site-packages/telegram/_bot.py", line 469, in _post
    return await self._do_post(
  File "/Users/admin/Library/Python/3.9/lib/python/site-packages/telegram/ext/_extbot.py", line 325, in _do_post
    return await super()._do_post(
  File "/Users/admin/Library/Python/3.9/lib/python/site-packages/telegram/_bot.py", line 497, in _do_post
    return await request.post(
  File "/Users/admin/Library/Python/3.9/lib/python/site-packages/telegram/request/_baserequest.py", line 168, in post
    result = await self._request_wrapper(
  File "/Users/admin/Library/Python/3.9/lib/python/site-packages/telegram/request/_baserequest.py", line 330, in _request_wrapper
    raise Conflict(message)
telegram.error.Conflict: Conflict: terminated by other getUpdates request; make sure that only one bot instance is running
2024-12-06 15:45:33,707 - telegram.ext.Updater - ERROR - Error while getting Updates: Conflict: terminated by other getUpdates request; make sure that only one bot instance is running
2024-12-06 15:45:33,708 - telegram.ext.Application - ERROR - No error handlers are registered, logging exception.
Traceback (most recent call last):
  File "/Users/admin/Library/Python/3.9/lib/python/site-packages/telegram/ext/_updater.py", line 607, in _network_loop_retry
    if not await action_cb():
  File "/Users/admin/Library/Python/3.9/lib/python/site-packages/telegram/ext/_updater.py", line 335, in polling_action_cb
    raise exc
  File "/Users/admin/Library/Python/3.9/lib/python/site-packages/telegram/ext/_updater.py", line 320, in polling_action_cb
    updates = await self.bot.get_updates(
  File "/Users/admin/Library/Python/3.9/lib/python/site-packages/telegram/ext/_extbot.py", line 543, in get_updates
    updates = await super().get_updates(
  File "/Users/admin/Library/Python/3.9/lib/python/site-packages/telegram/_bot.py", line 381, in decorator
    result = await func(self, *args, **kwargs)  # skipcq: PYL-E1102
  File "/Users/admin/Library/Python/3.9/lib/python/site-packages/telegram/_bot.py", line 3661, in get_updates
    await self._post(
  File "/Users/admin/Library/Python/3.9/lib/python/site-packages/telegram/_bot.py", line 469, in _post
    return await self._do_post(
  File "/Users/admin/Library/Python/3.9/lib/python/site-packages/telegram/ext/_extbot.py", line 325, in _do_post
    return await super()._do_post(
  File "/Users/admin/Library/Python/3.9/lib/python/site-packages/telegram/_bot.py", line 497, in _do_post
    return await request.post(
  File "/Users/admin/Library/Python/3.9/lib/python/site-packages/telegram/request/_baserequest.py", line 168, in post
    result = await self._request_wrapper(
  File "/Users/admin/Library/Python/3.9/lib/python/site-packages/telegram/request/_baserequest.py", line 330, in _request_wrapper
    raise Conflict(message)
telegram.error.Conflict: Conflict: terminated by other getUpdates request; make sure that only one bot instance is running
2024-12-06 15:46:07,476 - telegram.ext.Updater - ERROR - Error while getting Updates: Conflict: terminated by other getUpdates request; make sure that only one bot instance is running
2024-12-06 15:46:07,477 - telegram.ext.Application - ERROR - No error handlers are registered, logging exception.
Traceback (most recent call last):
  File "/Users/admin/Library/Python/3.9/lib/python/site-packages/telegram/ext/_updater.py", line 607, in _network_loop_retry
    if not await action_cb():
  File "/Users/admin/Library/Python/3.9/lib/python/site-packages/telegram/ext/_updater.py", line 335, in polling_action_cb
    raise exc
  File "/Users/admin/Library/Python/3.9/lib/python/site-packages/telegram/ext/_updater.py", line 320, in polling_action_cb
    updates = await self.bot.get_updates(
  File "/Users/admin/Library/Python/3.9/lib/python/site-packages/telegram/ext/_extbot.py", line 543, in get_updates
    updates = await super().get_updates(
  File "/Users/admin/Library/Python/3.9/lib/python/site-packages/telegram/_bot.py", line 381, in decorator
    result = await func(self, *args, **kwargs)  # skipcq: PYL-E1102
  File "/Users/admin/Library/Python/3.9/lib/python/site-packages/telegram/_bot.py", line 3661, in get_updates
    await self._post(
  File "/Users/admin/Library/Python/3.9/lib/python/site-packages/telegram/_bot.py", line 469, in _post
    return await self._do_post(
  File "/Users/admin/Library/Python/3.9/lib/python/site-packages/telegram/ext/_extbot.py", line 325, in _do_post
    return await super()._do_post(
  File "/Users/admin/Library/Python/3.9/lib/python/site-packages/telegram/_bot.py", line 497, in _do_post
    return await request.post(
  File "/Users/admin/Library/Python/3.9/lib/python/site-packages/telegram/request/_baserequest.py", line 168, in post
    result = await self._request_wrapper(
  File "/Users/admin/Library/Python/3.9/lib/python/site-packages/telegram/request/_baserequest.py", line 330, in _request_wrapper
    raise Conflict(message)
telegram.error.Conflict: Conflict: terminated by other getUpdates request; make sure that only one bot instance is running
2024-12-06 15:46:42,162 - telegram.ext.Updater - ERROR - Error while getting Updates: Conflict: terminated by other getUpdates request; make sure that only one bot instance is running
2024-12-06 15:46:42,163 - telegram.ext.Application - ERROR - No error handlers are registered, logging exception.
Traceback (most recent call last):
  File "/Users/admin/Library/Python/3.9/lib/python/site-packages/telegram/ext/_updater.py", line 607, in _network_loop_retry
    if not await action_cb():
  File "/Users/admin/Library/Python/3.9/lib/python/site-packages/telegram/ext/_updater.py", line 335, in polling_action_cb
    raise exc
  File "/Users/admin/Library/Python/3.9/lib/python/site-packages/telegram/ext/_updater.py", line 320, in polling_action_cb
    updates = await self.bot.get_updates(
  File "/Users/admin/Library/Python/3.9/lib/python/site-packages/telegram/ext/_extbot.py", line 543, in get_updates
    updates = await super().get_updates(
  File "/Users/admin/Library/Python/3.9/lib/python/site-packages/telegram/_bot.py", line 381, in decorator
    result = await func(self, *args, **kwargs)  # skipcq: PYL-E1102
  File "/Users/admin/Library/Python/3.9/lib/python/site-packages/telegram/_bot.py", line 3661, in get_updates
    await self._post(
  File "/Users/admin/Library/Python/3.9/lib/python/site-packages/telegram/_bot.py", line 469, in _post
    return await self._do_post(
  File "/Users/admin/Library/Python/3.9/lib/python/site-packages/telegram/ext/_extbot.py", line 325, in _do_post
    return await super()._do_post(
  File "/Users/admin/Library/Python/3.9/lib/python/site-packages/telegram/_bot.py", line 497, in _do_post
    return await request.post(
  File "/Users/admin/Library/Python/3.9/lib/python/site-packages/telegram/request/_baserequest.py", line 168, in post
    result = await self._request_wrapper(
  File "/Users/admin/Library/Python/3.9/lib/python/site-packages/telegram/request/_baserequest.py", line 330, in _request_wrapper
    raise Conflict(message)
telegram.error.Conflict: Conflict: terminated by other getUpdates request; make sure that only one bot instance is running
2024-12-06 15:47:15,980 - telegram.ext.Updater - ERROR - Error while getting Updates: Conflict: terminated by other getUpdates request; make sure that only one bot instance is running
2024-12-06 15:47:15,981 - telegram.ext.Application - ERROR - No error handlers are registered, logging exception.
Traceback (most recent call last):
  File "/Users/admin/Library/Python/3.9/lib/python/site-packages/telegram/ext/_updater.py", line 607, in _network_loop_retry
    if not await action_cb():
  File "/Users/admin/Library/Python/3.9/lib/python/site-packages/telegram/ext/_updater.py", line 335, in polling_action_cb
    raise exc
  File "/Users/admin/Library/Python/3.9/lib/python/site-packages/telegram/ext/_updater.py", line 320, in polling_action_cb
    updates = await self.bot.get_updates(
  File "/Users/admin/Library/Python/3.9/lib/python/site-packages/telegram/ext/_extbot.py", line 543, in get_updates
    updates = await super().get_updates(
  File "/Users/admin/Library/Python/3.9/lib/python/site-packages/telegram/_bot.py", line 381, in decorator
    result = await func(self, *args, **kwargs)  # skipcq: PYL-E1102
  File "/Users/admin/Library/Python/3.9/lib/python/site-packages/telegram/_bot.py", line 3661, in get_updates
    await self._post(
  File "/Users/admin/Library/Python/3.9/lib/python/site-packages/telegram/_bot.py", line 469, in _post
    return await self._do_post(
  File "/Users/admin/Library/Python/3.9/lib/python/site-packages/telegram/ext/_extbot.py", line 325, in _do_post
    return await super()._do_post(
  File "/Users/admin/Library/Python/3.9/lib/python/site-packages/telegram/_bot.py", line 497, in _do_post
    return await request.post(
  File "/Users/admin/Library/Python/3.9/lib/python/site-packages/telegram/request/_baserequest.py", line 168, in post
    result = await self._request_wrapper(
  File "/Users/admin/Library/Python/3.9/lib/python/site-packages/telegram/request/_baserequest.py", line 330, in _request_wrapper
    raise Conflict(message)
telegram.error.Conflict: Conflict: terminated by other getUpdates request; make sure that only one bot instance is running
2024-12-06 15:47:50,595 - telegram.ext.Updater - ERROR - Error while getting Updates: Conflict: terminated by other getUpdates request; make sure that only one bot instance is running
2024-12-06 15:47:50,595 - telegram.ext.Application - ERROR - No error handlers are registered, logging exception.
Traceback (most recent call last):
  File "/Users/admin/Library/Python/3.9/lib/python/site-packages/telegram/ext/_updater.py", line 607, in _network_loop_retry
    if not await action_cb():
  File "/Users/admin/Library/Python/3.9/lib/python/site-packages/telegram/ext/_updater.py", line 335, in polling_action_cb
    raise exc
  File "/Users/admin/Library/Python/3.9/lib/python/site-packages/telegram/ext/_updater.py", line 320, in polling_action_cb
    updates = await self.bot.get_updates(
  File "/Users/admin/Library/Python/3.9/lib/python/site-packages/telegram/ext/_extbot.py", line 543, in get_updates
    updates = await super().get_updates(
  File "/Users/admin/Library/Python/3.9/lib/python/site-packages/telegram/_bot.py", line 381, in decorator
    result = await func(self, *args, **kwargs)  # skipcq: PYL-E1102
  File "/Users/admin/Library/Python/3.9/lib/python/site-packages/telegram/_bot.py", line 3661, in get_updates
    await self._post(
  File "/Users/admin/Library/Python/3.9/lib/python/site-packages/telegram/_bot.py", line 469, in _post
    return await self._do_post(
  File "/Users/admin/Library/Python/3.9/lib/python/site-packages/telegram/ext/_extbot.py", line 325, in _do_post
    return await super()._do_post(
  File "/Users/admin/Library/Python/3.9/lib/python/site-packages/telegram/_bot.py", line 497, in _do_post
    return await request.post(
  File "/Users/admin/Library/Python/3.9/lib/python/site-packages/telegram/request/_baserequest.py", line 168, in post
    result = await self._request_wrapper(
  File "/Users/admin/Library/Python/3.9/lib/python/site-packages/telegram/request/_baserequest.py", line 330, in _request_wrapper
    raise Conflict(message)
telegram.error.Conflict: Conflict: terminated by other getUpdates request; make sure that only one bot instance is running
2024-12-06 15:48:24,961 - telegram.ext.Updater - ERROR - Error while getting Updates: Conflict: terminated by other getUpdates request; make sure that only one bot instance is running
2024-12-06 15:48:24,967 - telegram.ext.Application - ERROR - No error handlers are registered, logging exception.
Traceback (most recent call last):
  File "/Users/admin/Library/Python/3.9/lib/python/site-packages/telegram/ext/_updater.py", line 607, in _network_loop_retry
    if not await action_cb():
  File "/Users/admin/Library/Python/3.9/lib/python/site-packages/telegram/ext/_updater.py", line 335, in polling_action_cb
    raise exc
  File "/Users/admin/Library/Python/3.9/lib/python/site-packages/telegram/ext/_updater.py", line 320, in polling_action_cb
    updates = await self.bot.get_updates(
  File "/Users/admin/Library/Python/3.9/lib/python/site-packages/telegram/ext/_extbot.py", line 543, in get_updates
    updates = await super().get_updates(
  File "/Users/admin/Library/Python/3.9/lib/python/site-packages/telegram/_bot.py", line 381, in decorator
    result = await func(self, *args, **kwargs)  # skipcq: PYL-E1102
  File "/Users/admin/Library/Python/3.9/lib/python/site-packages/telegram/_bot.py", line 3661, in get_updates
    await self._post(
  File "/Users/admin/Library/Python/3.9/lib/python/site-packages/telegram/_bot.py", line 469, in _post
    return await self._do_post(
  File "/Users/admin/Library/Python/3.9/lib/python/site-packages/telegram/ext/_extbot.py", line 325, in _do_post
    return await super()._do_post(
  File "/Users/admin/Library/Python/3.9/lib/python/site-packages/telegram/_bot.py", line 497, in _do_post
    return await request.post(
  File "/Users/admin/Library/Python/3.9/lib/python/site-packages/telegram/request/_baserequest.py", line 168, in post
    result = await self._request_wrapper(
  File "/Users/admin/Library/Python/3.9/lib/python/site-packages/telegram/request/_baserequest.py", line 330, in _request_wrapper
    raise Conflict(message)
telegram.error.Conflict: Conflict: terminated by other getUpdates request; make sure that only one bot instance is running
2024-12-06 15:48:59,175 - telegram.ext.Updater - ERROR - Error while getting Updates: Conflict: terminated by other getUpdates request; make sure that only one bot instance is running
2024-12-06 15:48:59,176 - telegram.ext.Application - ERROR - No error handlers are registered, logging exception.
Traceback (most recent call last):
  File "/Users/admin/Library/Python/3.9/lib/python/site-packages/telegram/ext/_updater.py", line 607, in _network_loop_retry
    if not await action_cb():
  File "/Users/admin/Library/Python/3.9/lib/python/site-packages/telegram/ext/_updater.py", line 335, in polling_action_cb
    raise exc
  File "/Users/admin/Library/Python/3.9/lib/python/site-packages/telegram/ext/_updater.py", line 320, in polling_action_cb
    updates = await self.bot.get_updates(
  File "/Users/admin/Library/Python/3.9/lib/python/site-packages/telegram/ext/_extbot.py", line 543, in get_updates
    updates = await super().get_updates(
  File "/Users/admin/Library/Python/3.9/lib/python/site-packages/telegram/_bot.py", line 381, in decorator
    result = await func(self, *args, **kwargs)  # skipcq: PYL-E1102
  File "/Users/admin/Library/Python/3.9/lib/python/site-packages/telegram/_bot.py", line 3661, in get_updates
    await self._post(
  File "/Users/admin/Library/Python/3.9/lib/python/site-packages/telegram/_bot.py", line 469, in _post
    return await self._do_post(
  File "/Users/admin/Library/Python/3.9/lib/python/site-packages/telegram/ext/_extbot.py", line 325, in _do_post
    return await super()._do_post(
  File "/Users/admin/Library/Python/3.9/lib/python/site-packages/telegram/_bot.py", line 497, in _do_post
    return await request.post(
  File "/Users/admin/Library/Python/3.9/lib/python/site-packages/telegram/request/_baserequest.py", line 168, in post
    result = await self._request_wrapper(
  File "/Users/admin/Library/Python/3.9/lib/python/site-packages/telegram/request/_baserequest.py", line 330, in _request_wrapper
    raise Conflict(message)
telegram.error.Conflict: Conflict: terminated by other getUpdates request; make sure that only one bot instance is running
2024-12-06 15:49:33,565 - telegram.ext.Updater - ERROR - Error while getting Updates: Conflict: terminated by other getUpdates request; make sure that only one bot instance is running
2024-12-06 15:49:33,566 - telegram.ext.Application - ERROR - No error handlers are registered, logging exception.
Traceback (most recent call last):
  File "/Users/admin/Library/Python/3.9/lib/python/site-packages/telegram/ext/_updater.py", line 607, in _network_loop_retry
    if not await action_cb():
  File "/Users/admin/Library/Python/3.9/lib/python/site-packages/telegram/ext/_updater.py", line 335, in polling_action_cb
    raise exc
  File "/Users/admin/Library/Python/3.9/lib/python/site-packages/telegram/ext/_updater.py", line 320, in polling_action_cb
    updates = await self.bot.get_updates(
  File "/Users/admin/Library/Python/3.9/lib/python/site-packages/telegram/ext/_extbot.py", line 543, in get_updates
    updates = await super().get_updates(
  File "/Users/admin/Library/Python/3.9/lib/python/site-packages/telegram/_bot.py", line 381, in decorator
    result = await func(self, *args, **kwargs)  # skipcq: PYL-E1102
  File "/Users/admin/Library/Python/3.9/lib/python/site-packages/telegram/_bot.py", line 3661, in get_updates
    await self._post(
  File "/Users/admin/Library/Python/3.9/lib/python/site-packages/telegram/_bot.py", line 469, in _post
    return await self._do_post(
  File "/Users/admin/Library/Python/3.9/lib/python/site-packages/telegram/ext/_extbot.py", line 325, in _do_post
    return await super()._do_post(
  File "/Users/admin/Library/Python/3.9/lib/python/site-packages/telegram/_bot.py", line 497, in _do_post
    return await request.post(
  File "/Users/admin/Library/Python/3.9/lib/python/site-packages/telegram/request/_baserequest.py", line 168, in post
    result = await self._request_wrapper(
  File "/Users/admin/Library/Python/3.9/lib/python/site-packages/telegram/request/_baserequest.py", line 330, in _request_wrapper
    raise Conflict(message)
telegram.error.Conflict: Conflict: terminated by other getUpdates request; make sure that only one bot instance is running
2024-12-06 15:50:07,601 - telegram.ext.Updater - ERROR - Error while getting Updates: Conflict: terminated by other getUpdates request; make sure that only one bot instance is running
2024-12-06 15:50:07,602 - telegram.ext.Application - ERROR - No error handlers are registered, logging exception.
Traceback (most recent call last):
  File "/Users/admin/Library/Python/3.9/lib/python/site-packages/telegram/ext/_updater.py", line 607, in _network_loop_retry
    if not await action_cb():
  File "/Users/admin/Library/Python/3.9/lib/python/site-packages/telegram/ext/_updater.py", line 335, in polling_action_cb
    raise exc
  File "/Users/admin/Library/Python/3.9/lib/python/site-packages/telegram/ext/_updater.py", line 320, in polling_action_cb
    updates = await self.bot.get_updates(
  File "/Users/admin/Library/Python/3.9/lib/python/site-packages/telegram/ext/_extbot.py", line 543, in get_updates
    updates = await super().get_updates(
  File "/Users/admin/Library/Python/3.9/lib/python/site-packages/telegram/_bot.py", line 381, in decorator
    result = await func(self, *args, **kwargs)  # skipcq: PYL-E1102
  File "/Users/admin/Library/Python/3.9/lib/python/site-packages/telegram/_bot.py", line 3661, in get_updates
    await self._post(
  File "/Users/admin/Library/Python/3.9/lib/python/site-packages/telegram/_bot.py", line 469, in _post
    return await self._do_post(
  File "/Users/admin/Library/Python/3.9/lib/python/site-packages/telegram/ext/_extbot.py", line 325, in _do_post
    return await super()._do_post(
  File "/Users/admin/Library/Python/3.9/lib/python/site-packages/telegram/_bot.py", line 497, in _do_post
    return await request.post(
  File "/Users/admin/Library/Python/3.9/lib/python/site-packages/telegram/request/_baserequest.py", line 168, in post
    result = await self._request_wrapper(
  File "/Users/admin/Library/Python/3.9/lib/python/site-packages/telegram/request/_baserequest.py", line 330, in _request_wrapper
    raise Conflict(message)
telegram.error.Conflict: Conflict: terminated by other getUpdates request; make sure that only one bot instance is running
2024-12-06 15:50:41,973 - telegram.ext.Updater - ERROR - Error while getting Updates: Conflict: terminated by other getUpdates request; make sure that only one bot instance is running
2024-12-06 15:50:41,973 - telegram.ext.Application - ERROR - No error handlers are registered, logging exception.
Traceback (most recent call last):
  File "/Users/admin/Library/Python/3.9/lib/python/site-packages/telegram/ext/_updater.py", line 607, in _network_loop_retry
    if not await action_cb():
  File "/Users/admin/Library/Python/3.9/lib/python/site-packages/telegram/ext/_updater.py", line 335, in polling_action_cb
    raise exc
  File "/Users/admin/Library/Python/3.9/lib/python/site-packages/telegram/ext/_updater.py", line 320, in polling_action_cb
    updates = await self.bot.get_updates(
  File "/Users/admin/Library/Python/3.9/lib/python/site-packages/telegram/ext/_extbot.py", line 543, in get_updates
    updates = await super().get_updates(
  File "/Users/admin/Library/Python/3.9/lib/python/site-packages/telegram/_bot.py", line 381, in decorator
    result = await func(self, *args, **kwargs)  # skipcq: PYL-E1102
  File "/Users/admin/Library/Python/3.9/lib/python/site-packages/telegram/_bot.py", line 3661, in get_updates
    await self._post(
  File "/Users/admin/Library/Python/3.9/lib/python/site-packages/telegram/_bot.py", line 469, in _post
    return await self._do_post(
  File "/Users/admin/Library/Python/3.9/lib/python/site-packages/telegram/ext/_extbot.py", line 325, in _do_post
    return await super()._do_post(
  File "/Users/admin/Library/Python/3.9/lib/python/site-packages/telegram/_bot.py", line 497, in _do_post
    return await request.post(
  File "/Users/admin/Library/Python/3.9/lib/python/site-packages/telegram/request/_baserequest.py", line 168, in post
    result = await self._request_wrapper(
  File "/Users/admin/Library/Python/3.9/lib/python/site-packages/telegram/request/_baserequest.py", line 330, in _request_wrapper
    raise Conflict(message)
telegram.error.Conflict: Conflict: terminated by other getUpdates request; make sure that only one bot instance is running
2024-12-06 15:51:16,958 - telegram.ext.Updater - ERROR - Error while getting Updates: Conflict: terminated by other getUpdates request; make sure that only one bot instance is running
2024-12-06 15:51:16,958 - telegram.ext.Application - ERROR - No error handlers are registered, logging exception.
Traceback (most recent call last):
  File "/Users/admin/Library/Python/3.9/lib/python/site-packages/telegram/ext/_updater.py", line 607, in _network_loop_retry
    if not await action_cb():
  File "/Users/admin/Library/Python/3.9/lib/python/site-packages/telegram/ext/_updater.py", line 335, in polling_action_cb
    raise exc
  File "/Users/admin/Library/Python/3.9/lib/python/site-packages/telegram/ext/_updater.py", line 320, in polling_action_cb
    updates = await self.bot.get_updates(
  File "/Users/admin/Library/Python/3.9/lib/python/site-packages/telegram/ext/_extbot.py", line 543, in get_updates
    updates = await super().get_updates(
  File "/Users/admin/Library/Python/3.9/lib/python/site-packages/telegram/_bot.py", line 381, in decorator
    result = await func(self, *args, **kwargs)  # skipcq: PYL-E1102
  File "/Users/admin/Library/Python/3.9/lib/python/site-packages/telegram/_bot.py", line 3661, in get_updates
    await self._post(
  File "/Users/admin/Library/Python/3.9/lib/python/site-packages/telegram/_bot.py", line 469, in _post
    return await self._do_post(
  File "/Users/admin/Library/Python/3.9/lib/python/site-packages/telegram/ext/_extbot.py", line 325, in _do_post
    return await super()._do_post(
  File "/Users/admin/Library/Python/3.9/lib/python/site-packages/telegram/_bot.py", line 497, in _do_post
    return await request.post(
  File "/Users/admin/Library/Python/3.9/lib/python/site-packages/telegram/request/_baserequest.py", line 168, in post
    result = await self._request_wrapper(
  File "/Users/admin/Library/Python/3.9/lib/python/site-packages/telegram/request/_baserequest.py", line 330, in _request_wrapper
    raise Conflict(message)
telegram.error.Conflict: Conflict: terminated by other getUpdates request; make sure that only one bot instance is running
2024-12-06 15:51:53,824 - telegram.ext.Updater - ERROR - Error while getting Updates: Conflict: terminated by other getUpdates request; make sure that only one bot instance is running
2024-12-06 15:51:53,825 - telegram.ext.Application - ERROR - No error handlers are registered, logging exception.
Traceback (most recent call last):
  File "/Users/admin/Library/Python/3.9/lib/python/site-packages/telegram/ext/_updater.py", line 607, in _network_loop_retry
    if not await action_cb():
  File "/Users/admin/Library/Python/3.9/lib/python/site-packages/telegram/ext/_updater.py", line 335, in polling_action_cb
    raise exc
  File "/Users/admin/Library/Python/3.9/lib/python/site-packages/telegram/ext/_updater.py", line 320, in polling_action_cb
    updates = await self.bot.get_updates(
  File "/Users/admin/Library/Python/3.9/lib/python/site-packages/telegram/ext/_extbot.py", line 543, in get_updates
    updates = await super().get_updates(
  File "/Users/admin/Library/Python/3.9/lib/python/site-packages/telegram/_bot.py", line 381, in decorator
    result = await func(self, *args, **kwargs)  # skipcq: PYL-E1102
  File "/Users/admin/Library/Python/3.9/lib/python/site-packages/telegram/_bot.py", line 3661, in get_updates
    await self._post(
  File "/Users/admin/Library/Python/3.9/lib/python/site-packages/telegram/_bot.py", line 469, in _post
    return await self._do_post(
  File "/Users/admin/Library/Python/3.9/lib/python/site-packages/telegram/ext/_extbot.py", line 325, in _do_post
    return await super()._do_post(
  File "/Users/admin/Library/Python/3.9/lib/python/site-packages/telegram/_bot.py", line 497, in _do_post
    return await request.post(
  File "/Users/admin/Library/Python/3.9/lib/python/site-packages/telegram/request/_baserequest.py", line 168, in post
    result = await self._request_wrapper(
  File "/Users/admin/Library/Python/3.9/lib/python/site-packages/telegram/request/_baserequest.py", line 330, in _request_wrapper
    raise Conflict(message)
telegram.error.Conflict: Conflict: terminated by other getUpdates request; make sure that only one bot instance is running
2024-12-06 15:52:28,501 - telegram.ext.Updater - ERROR - Error while getting Updates: Conflict: terminated by other getUpdates request; make sure that only one bot instance is running
2024-12-06 15:52:28,503 - telegram.ext.Application - ERROR - No error handlers are registered, logging exception.
Traceback (most recent call last):
  File "/Users/admin/Library/Python/3.9/lib/python/site-packages/telegram/ext/_updater.py", line 607, in _network_loop_retry
    if not await action_cb():
  File "/Users/admin/Library/Python/3.9/lib/python/site-packages/telegram/ext/_updater.py", line 335, in polling_action_cb
    raise exc
  File "/Users/admin/Library/Python/3.9/lib/python/site-packages/telegram/ext/_updater.py", line 320, in polling_action_cb
    updates = await self.bot.get_updates(
  File "/Users/admin/Library/Python/3.9/lib/python/site-packages/telegram/ext/_extbot.py", line 543, in get_updates
    updates = await super().get_updates(
  File "/Users/admin/Library/Python/3.9/lib/python/site-packages/telegram/_bot.py", line 381, in decorator
    result = await func(self, *args, **kwargs)  # skipcq: PYL-E1102
  File "/Users/admin/Library/Python/3.9/lib/python/site-packages/telegram/_bot.py", line 3661, in get_updates
    await self._post(
  File "/Users/admin/Library/Python/3.9/lib/python/site-packages/telegram/_bot.py", line 469, in _post
    return await self._do_post(
  File "/Users/admin/Library/Python/3.9/lib/python/site-packages/telegram/ext/_extbot.py", line 325, in _do_post
    return await super()._do_post(
  File "/Users/admin/Library/Python/3.9/lib/python/site-packages/telegram/_bot.py", line 497, in _do_post
    return await request.post(
  File "/Users/admin/Library/Python/3.9/lib/python/site-packages/telegram/request/_baserequest.py", line 168, in post
    result = await self._request_wrapper(
  File "/Users/admin/Library/Python/3.9/lib/python/site-packages/telegram/request/_baserequest.py", line 330, in _request_wrapper
    raise Conflict(message)
telegram.error.Conflict: Conflict: terminated by other getUpdates request; make sure that only one bot instance is running
2024-12-06 15:53:02,293 - telegram.ext.Updater - ERROR - Error while getting Updates: Conflict: terminated by other getUpdates request; make sure that only one bot instance is running
2024-12-06 15:53:02,294 - telegram.ext.Application - ERROR - No error handlers are registered, logging exception.
Traceback (most recent call last):
  File "/Users/admin/Library/Python/3.9/lib/python/site-packages/telegram/ext/_updater.py", line 607, in _network_loop_retry
    if not await action_cb():
  File "/Users/admin/Library/Python/3.9/lib/python/site-packages/telegram/ext/_updater.py", line 335, in polling_action_cb
    raise exc
  File "/Users/admin/Library/Python/3.9/lib/python/site-packages/telegram/ext/_updater.py", line 320, in polling_action_cb
    updates = await self.bot.get_updates(
  File "/Users/admin/Library/Python/3.9/lib/python/site-packages/telegram/ext/_extbot.py", line 543, in get_updates
    updates = await super().get_updates(
  File "/Users/admin/Library/Python/3.9/lib/python/site-packages/telegram/_bot.py", line 381, in decorator
    result = await func(self, *args, **kwargs)  # skipcq: PYL-E1102
  File "/Users/admin/Library/Python/3.9/lib/python/site-packages/telegram/_bot.py", line 3661, in get_updates
    await self._post(
  File "/Users/admin/Library/Python/3.9/lib/python/site-packages/telegram/_bot.py", line 469, in _post
    return await self._do_post(
  File "/Users/admin/Library/Python/3.9/lib/python/site-packages/telegram/ext/_extbot.py", line 325, in _do_post
    return await super()._do_post(
  File "/Users/admin/Library/Python/3.9/lib/python/site-packages/telegram/_bot.py", line 497, in _do_post
    return await request.post(
  File "/Users/admin/Library/Python/3.9/lib/python/site-packages/telegram/request/_baserequest.py", line 168, in post
    result = await self._request_wrapper(
  File "/Users/admin/Library/Python/3.9/lib/python/site-packages/telegram/request/_baserequest.py", line 330, in _request_wrapper
    raise Conflict(message)
telegram.error.Conflict: Conflict: terminated by other getUpdates request; make sure that only one bot instance is running
2024-12-06 15:53:37,008 - telegram.ext.Updater - ERROR - Error while getting Updates: Conflict: terminated by other getUpdates request; make sure that only one bot instance is running
2024-12-06 15:53:37,009 - telegram.ext.Application - ERROR - No error handlers are registered, logging exception.
Traceback (most recent call last):
  File "/Users/admin/Library/Python/3.9/lib/python/site-packages/telegram/ext/_updater.py", line 607, in _network_loop_retry
    if not await action_cb():
  File "/Users/admin/Library/Python/3.9/lib/python/site-packages/telegram/ext/_updater.py", line 335, in polling_action_cb
    raise exc
  File "/Users/admin/Library/Python/3.9/lib/python/site-packages/telegram/ext/_updater.py", line 320, in polling_action_cb
    updates = await self.bot.get_updates(
  File "/Users/admin/Library/Python/3.9/lib/python/site-packages/telegram/ext/_extbot.py", line 543, in get_updates
    updates = await super().get_updates(
  File "/Users/admin/Library/Python/3.9/lib/python/site-packages/telegram/_bot.py", line 381, in decorator
    result = await func(self, *args, **kwargs)  # skipcq: PYL-E1102
  File "/Users/admin/Library/Python/3.9/lib/python/site-packages/telegram/_bot.py", line 3661, in get_updates
    await self._post(
  File "/Users/admin/Library/Python/3.9/lib/python/site-packages/telegram/_bot.py", line 469, in _post
    return await self._do_post(
  File "/Users/admin/Library/Python/3.9/lib/python/site-packages/telegram/ext/_extbot.py", line 325, in _do_post
    return await super()._do_post(
  File "/Users/admin/Library/Python/3.9/lib/python/site-packages/telegram/_bot.py", line 497, in _do_post
    return await request.post(
  File "/Users/admin/Library/Python/3.9/lib/python/site-packages/telegram/request/_baserequest.py", line 168, in post
    result = await self._request_wrapper(
  File "/Users/admin/Library/Python/3.9/lib/python/site-packages/telegram/request/_baserequest.py", line 330, in _request_wrapper
    raise Conflict(message)
telegram.error.Conflict: Conflict: terminated by other getUpdates request; make sure that only one bot instance is running
2024-12-06 15:54:12,130 - telegram.ext.Updater - ERROR - Error while getting Updates: Conflict: terminated by other getUpdates request; make sure that only one bot instance is running
2024-12-06 15:54:12,132 - telegram.ext.Application - ERROR - No error handlers are registered, logging exception.
Traceback (most recent call last):
  File "/Users/admin/Library/Python/3.9/lib/python/site-packages/telegram/ext/_updater.py", line 607, in _network_loop_retry
    if not await action_cb():
  File "/Users/admin/Library/Python/3.9/lib/python/site-packages/telegram/ext/_updater.py", line 335, in polling_action_cb
    raise exc
  File "/Users/admin/Library/Python/3.9/lib/python/site-packages/telegram/ext/_updater.py", line 320, in polling_action_cb
    updates = await self.bot.get_updates(
  File "/Users/admin/Library/Python/3.9/lib/python/site-packages/telegram/ext/_extbot.py", line 543, in get_updates
    updates = await super().get_updates(
  File "/Users/admin/Library/Python/3.9/lib/python/site-packages/telegram/_bot.py", line 381, in decorator
    result = await func(self, *args, **kwargs)  # skipcq: PYL-E1102
  File "/Users/admin/Library/Python/3.9/lib/python/site-packages/telegram/_bot.py", line 3661, in get_updates
    await self._post(
  File "/Users/admin/Library/Python/3.9/lib/python/site-packages/telegram/_bot.py", line 469, in _post
    return await self._do_post(
  File "/Users/admin/Library/Python/3.9/lib/python/site-packages/telegram/ext/_extbot.py", line 325, in _do_post
    return await super()._do_post(
  File "/Users/admin/Library/Python/3.9/lib/python/site-packages/telegram/_bot.py", line 497, in _do_post
    return await request.post(
  File "/Users/admin/Library/Python/3.9/lib/python/site-packages/telegram/request/_baserequest.py", line 168, in post
    result = await self._request_wrapper(
  File "/Users/admin/Library/Python/3.9/lib/python/site-packages/telegram/request/_baserequest.py", line 330, in _request_wrapper
    raise Conflict(message)
telegram.error.Conflict: Conflict: terminated by other getUpdates request; make sure that only one bot instance is running
2024-12-06 15:54:47,150 - telegram.ext.Updater - ERROR - Error while getting Updates: Conflict: terminated by other getUpdates request; make sure that only one bot instance is running
2024-12-06 15:54:47,151 - telegram.ext.Application - ERROR - No error handlers are registered, logging exception.
Traceback (most recent call last):
  File "/Users/admin/Library/Python/3.9/lib/python/site-packages/telegram/ext/_updater.py", line 607, in _network_loop_retry
    if not await action_cb():
  File "/Users/admin/Library/Python/3.9/lib/python/site-packages/telegram/ext/_updater.py", line 335, in polling_action_cb
    raise exc
  File "/Users/admin/Library/Python/3.9/lib/python/site-packages/telegram/ext/_updater.py", line 320, in polling_action_cb
    updates = await self.bot.get_updates(
  File "/Users/admin/Library/Python/3.9/lib/python/site-packages/telegram/ext/_extbot.py", line 543, in get_updates
    updates = await super().get_updates(
  File "/Users/admin/Library/Python/3.9/lib/python/site-packages/telegram/_bot.py", line 381, in decorator
    result = await func(self, *args, **kwargs)  # skipcq: PYL-E1102
  File "/Users/admin/Library/Python/3.9/lib/python/site-packages/telegram/_bot.py", line 3661, in get_updates
    await self._post(
  File "/Users/admin/Library/Python/3.9/lib/python/site-packages/telegram/_bot.py", line 469, in _post
    return await self._do_post(
  File "/Users/admin/Library/Python/3.9/lib/python/site-packages/telegram/ext/_extbot.py", line 325, in _do_post
    return await super()._do_post(
  File "/Users/admin/Library/Python/3.9/lib/python/site-packages/telegram/_bot.py", line 497, in _do_post
    return await request.post(
  File "/Users/admin/Library/Python/3.9/lib/python/site-packages/telegram/request/_baserequest.py", line 168, in post
    result = await self._request_wrapper(
  File "/Users/admin/Library/Python/3.9/lib/python/site-packages/telegram/request/_baserequest.py", line 330, in _request_wrapper
    raise Conflict(message)
telegram.error.Conflict: Conflict: terminated by other getUpdates request; make sure that only one bot instance is running
2024-12-06 15:55:22,306 - telegram.ext.Updater - ERROR - Error while getting Updates: Conflict: terminated by other getUpdates request; make sure that only one bot instance is running
2024-12-06 15:55:22,307 - telegram.ext.Application - ERROR - No error handlers are registered, logging exception.
Traceback (most recent call last):
  File "/Users/admin/Library/Python/3.9/lib/python/site-packages/telegram/ext/_updater.py", line 607, in _network_loop_retry
    if not await action_cb():
  File "/Users/admin/Library/Python/3.9/lib/python/site-packages/telegram/ext/_updater.py", line 335, in polling_action_cb
    raise exc
  File "/Users/admin/Library/Python/3.9/lib/python/site-packages/telegram/ext/_updater.py", line 320, in polling_action_cb
    updates = await self.bot.get_updates(
  File "/Users/admin/Library/Python/3.9/lib/python/site-packages/telegram/ext/_extbot.py", line 543, in get_updates
    updates = await super().get_updates(
  File "/Users/admin/Library/Python/3.9/lib/python/site-packages/telegram/_bot.py", line 381, in decorator
    result = await func(self, *args, **kwargs)  # skipcq: PYL-E1102
  File "/Users/admin/Library/Python/3.9/lib/python/site-packages/telegram/_bot.py", line 3661, in get_updates
    await self._post(
  File "/Users/admin/Library/Python/3.9/lib/python/site-packages/telegram/_bot.py", line 469, in _post
    return await self._do_post(
  File "/Users/admin/Library/Python/3.9/lib/python/site-packages/telegram/ext/_extbot.py", line 325, in _do_post
    return await super()._do_post(
  File "/Users/admin/Library/Python/3.9/lib/python/site-packages/telegram/_bot.py", line 497, in _do_post
    return await request.post(
  File "/Users/admin/Library/Python/3.9/lib/python/site-packages/telegram/request/_baserequest.py", line 168, in post
    result = await self._request_wrapper(
  File "/Users/admin/Library/Python/3.9/lib/python/site-packages/telegram/request/_baserequest.py", line 330, in _request_wrapper
    raise Conflict(message)
telegram.error.Conflict: Conflict: terminated by other getUpdates request; make sure that only one bot instance is running
2024-12-06 19:56:22,339 - telegram.ext.Updater - ERROR - Error while getting Updates: Conflict: terminated by other getUpdates request; make sure that only one bot instance is running
2024-12-06 19:56:22,343 - telegram.ext.Application - ERROR - No error handlers are registered, logging exception.
Traceback (most recent call last):
  File "/Users/admin/Library/Python/3.9/lib/python/site-packages/telegram/ext/_updater.py", line 607, in _network_loop_retry
    if not await action_cb():
  File "/Users/admin/Library/Python/3.9/lib/python/site-packages/telegram/ext/_updater.py", line 335, in polling_action_cb
    raise exc
  File "/Users/admin/Library/Python/3.9/lib/python/site-packages/telegram/ext/_updater.py", line 320, in polling_action_cb
    updates = await self.bot.get_updates(
  File "/Users/admin/Library/Python/3.9/lib/python/site-packages/telegram/ext/_extbot.py", line 543, in get_updates
    updates = await super().get_updates(
  File "/Users/admin/Library/Python/3.9/lib/python/site-packages/telegram/_bot.py", line 381, in decorator
    result = await func(self, *args, **kwargs)  # skipcq: PYL-E1102
  File "/Users/admin/Library/Python/3.9/lib/python/site-packages/telegram/_bot.py", line 3661, in get_updates
    await self._post(
  File "/Users/admin/Library/Python/3.9/lib/python/site-packages/telegram/_bot.py", line 469, in _post
    return await self._do_post(
  File "/Users/admin/Library/Python/3.9/lib/python/site-packages/telegram/ext/_extbot.py", line 325, in _do_post
    return await super()._do_post(
  File "/Users/admin/Library/Python/3.9/lib/python/site-packages/telegram/_bot.py", line 497, in _do_post
    return await request.post(
  File "/Users/admin/Library/Python/3.9/lib/python/site-packages/telegram/request/_baserequest.py", line 168, in post
    result = await self._request_wrapper(
  File "/Users/admin/Library/Python/3.9/lib/python/site-packages/telegram/request/_baserequest.py", line 330, in _request_wrapper
    raise Conflict(message)
telegram.error.Conflict: Conflict: terminated by other getUpdates request; make sure that only one bot instance is running
2024-12-06 19:56:27,264 - telegram.ext.Updater - ERROR - Error while getting Updates: Conflict: terminated by other getUpdates request; make sure that only one bot instance is running
2024-12-06 19:56:27,265 - telegram.ext.Application - ERROR - No error handlers are registered, logging exception.
Traceback (most recent call last):
  File "/Users/admin/Library/Python/3.9/lib/python/site-packages/telegram/ext/_updater.py", line 607, in _network_loop_retry
    if not await action_cb():
  File "/Users/admin/Library/Python/3.9/lib/python/site-packages/telegram/ext/_updater.py", line 335, in polling_action_cb
    raise exc
  File "/Users/admin/Library/Python/3.9/lib/python/site-packages/telegram/ext/_updater.py", line 320, in polling_action_cb
    updates = await self.bot.get_updates(
  File "/Users/admin/Library/Python/3.9/lib/python/site-packages/telegram/ext/_extbot.py", line 543, in get_updates
    updates = await super().get_updates(
  File "/Users/admin/Library/Python/3.9/lib/python/site-packages/telegram/_bot.py", line 381, in decorator
    result = await func(self, *args, **kwargs)  # skipcq: PYL-E1102
  File "/Users/admin/Library/Python/3.9/lib/python/site-packages/telegram/_bot.py", line 3661, in get_updates
    await self._post(
  File "/Users/admin/Library/Python/3.9/lib/python/site-packages/telegram/_bot.py", line 469, in _post
    return await self._do_post(
  File "/Users/admin/Library/Python/3.9/lib/python/site-packages/telegram/ext/_extbot.py", line 325, in _do_post
    return await super()._do_post(
  File "/Users/admin/Library/Python/3.9/lib/python/site-packages/telegram/_bot.py", line 497, in _do_post
    return await request.post(
  File "/Users/admin/Library/Python/3.9/lib/python/site-packages/telegram/request/_baserequest.py", line 168, in post
    result = await self._request_wrapper(
  File "/Users/admin/Library/Python/3.9/lib/python/site-packages/telegram/request/_baserequest.py", line 330, in _request_wrapper
    raise Conflict(message)
telegram.error.Conflict: Conflict: terminated by other getUpdates request; make sure that only one bot instance is running
2024-12-06 19:56:34,232 - telegram.ext.Updater - ERROR - Error while getting Updates: Conflict: terminated by other getUpdates request; make sure that only one bot instance is running
2024-12-06 19:56:34,232 - telegram.ext.Application - ERROR - No error handlers are registered, logging exception.
Traceback (most recent call last):
  File "/Users/admin/Library/Python/3.9/lib/python/site-packages/telegram/ext/_updater.py", line 607, in _network_loop_retry
    if not await action_cb():
  File "/Users/admin/Library/Python/3.9/lib/python/site-packages/telegram/ext/_updater.py", line 335, in polling_action_cb
    raise exc
  File "/Users/admin/Library/Python/3.9/lib/python/site-packages/telegram/ext/_updater.py", line 320, in polling_action_cb
    updates = await self.bot.get_updates(
  File "/Users/admin/Library/Python/3.9/lib/python/site-packages/telegram/ext/_extbot.py", line 543, in get_updates
    updates = await super().get_updates(
  File "/Users/admin/Library/Python/3.9/lib/python/site-packages/telegram/_bot.py", line 381, in decorator
    result = await func(self, *args, **kwargs)  # skipcq: PYL-E1102
  File "/Users/admin/Library/Python/3.9/lib/python/site-packages/telegram/_bot.py", line 3661, in get_updates
    await self._post(
  File "/Users/admin/Library/Python/3.9/lib/python/site-packages/telegram/_bot.py", line 469, in _post
    return await self._do_post(
  File "/Users/admin/Library/Python/3.9/lib/python/site-packages/telegram/ext/_extbot.py", line 325, in _do_post
    return await super()._do_post(
  File "/Users/admin/Library/Python/3.9/lib/python/site-packages/telegram/_bot.py", line 497, in _do_post
    return await request.post(
  File "/Users/admin/Library/Python/3.9/lib/python/site-packages/telegram/request/_baserequest.py", line 168, in post
    result = await self._request_wrapper(
  File "/Users/admin/Library/Python/3.9/lib/python/site-packages/telegram/request/_baserequest.py", line 330, in _request_wrapper
    raise Conflict(message)
telegram.error.Conflict: Conflict: terminated by other getUpdates request; make sure that only one bot instance is running
2024-12-06 19:56:40,127 - telegram.ext.Updater - ERROR - Error while getting Updates: Conflict: terminated by other getUpdates request; make sure that only one bot instance is running
2024-12-06 19:56:40,127 - telegram.ext.Application - ERROR - No error handlers are registered, logging exception.
Traceback (most recent call last):
  File "/Users/admin/Library/Python/3.9/lib/python/site-packages/telegram/ext/_updater.py", line 607, in _network_loop_retry
    if not await action_cb():
  File "/Users/admin/Library/Python/3.9/lib/python/site-packages/telegram/ext/_updater.py", line 335, in polling_action_cb
    raise exc
  File "/Users/admin/Library/Python/3.9/lib/python/site-packages/telegram/ext/_updater.py", line 320, in polling_action_cb
    updates = await self.bot.get_updates(
  File "/Users/admin/Library/Python/3.9/lib/python/site-packages/telegram/ext/_extbot.py", line 543, in get_updates
    updates = await super().get_updates(
  File "/Users/admin/Library/Python/3.9/lib/python/site-packages/telegram/_bot.py", line 381, in decorator
    result = await func(self, *args, **kwargs)  # skipcq: PYL-E1102
  File "/Users/admin/Library/Python/3.9/lib/python/site-packages/telegram/_bot.py", line 3661, in get_updates
    await self._post(
  File "/Users/admin/Library/Python/3.9/lib/python/site-packages/telegram/_bot.py", line 469, in _post
    return await self._do_post(
  File "/Users/admin/Library/Python/3.9/lib/python/site-packages/telegram/ext/_extbot.py", line 325, in _do_post
    return await super()._do_post(
  File "/Users/admin/Library/Python/3.9/lib/python/site-packages/telegram/_bot.py", line 497, in _do_post
    return await request.post(
  File "/Users/admin/Library/Python/3.9/lib/python/site-packages/telegram/request/_baserequest.py", line 168, in post
    result = await self._request_wrapper(
  File "/Users/admin/Library/Python/3.9/lib/python/site-packages/telegram/request/_baserequest.py", line 330, in _request_wrapper
    raise Conflict(message)
telegram.error.Conflict: Conflict: terminated by other getUpdates request; make sure that only one bot instance is running
2024-12-06 19:56:49,052 - telegram.ext.Updater - ERROR - Error while getting Updates: Conflict: terminated by other getUpdates request; make sure that only one bot instance is running
2024-12-06 19:56:49,053 - telegram.ext.Application - ERROR - No error handlers are registered, logging exception.
Traceback (most recent call last):
  File "/Users/admin/Library/Python/3.9/lib/python/site-packages/telegram/ext/_updater.py", line 607, in _network_loop_retry
    if not await action_cb():
  File "/Users/admin/Library/Python/3.9/lib/python/site-packages/telegram/ext/_updater.py", line 335, in polling_action_cb
    raise exc
  File "/Users/admin/Library/Python/3.9/lib/python/site-packages/telegram/ext/_updater.py", line 320, in polling_action_cb
    updates = await self.bot.get_updates(
  File "/Users/admin/Library/Python/3.9/lib/python/site-packages/telegram/ext/_extbot.py", line 543, in get_updates
    updates = await super().get_updates(
  File "/Users/admin/Library/Python/3.9/lib/python/site-packages/telegram/_bot.py", line 381, in decorator
    result = await func(self, *args, **kwargs)  # skipcq: PYL-E1102
  File "/Users/admin/Library/Python/3.9/lib/python/site-packages/telegram/_bot.py", line 3661, in get_updates
    await self._post(
  File "/Users/admin/Library/Python/3.9/lib/python/site-packages/telegram/_bot.py", line 469, in _post
    return await self._do_post(
  File "/Users/admin/Library/Python/3.9/lib/python/site-packages/telegram/ext/_extbot.py", line 325, in _do_post
    return await super()._do_post(
  File "/Users/admin/Library/Python/3.9/lib/python/site-packages/telegram/_bot.py", line 497, in _do_post
    return await request.post(
  File "/Users/admin/Library/Python/3.9/lib/python/site-packages/telegram/request/_baserequest.py", line 168, in post
    result = await self._request_wrapper(
  File "/Users/admin/Library/Python/3.9/lib/python/site-packages/telegram/request/_baserequest.py", line 330, in _request_wrapper
    raise Conflict(message)
telegram.error.Conflict: Conflict: terminated by other getUpdates request; make sure that only one bot instance is running
2024-12-06 19:56:58,173 - telegram.ext.Updater - ERROR - Error while getting Updates: Conflict: terminated by other getUpdates request; make sure that only one bot instance is running
2024-12-06 19:56:58,173 - telegram.ext.Application - ERROR - No error handlers are registered, logging exception.
Traceback (most recent call last):
  File "/Users/admin/Library/Python/3.9/lib/python/site-packages/telegram/ext/_updater.py", line 607, in _network_loop_retry
    if not await action_cb():
  File "/Users/admin/Library/Python/3.9/lib/python/site-packages/telegram/ext/_updater.py", line 335, in polling_action_cb
    raise exc
  File "/Users/admin/Library/Python/3.9/lib/python/site-packages/telegram/ext/_updater.py", line 320, in polling_action_cb
    updates = await self.bot.get_updates(
  File "/Users/admin/Library/Python/3.9/lib/python/site-packages/telegram/ext/_extbot.py", line 543, in get_updates
    updates = await super().get_updates(
  File "/Users/admin/Library/Python/3.9/lib/python/site-packages/telegram/_bot.py", line 381, in decorator
    result = await func(self, *args, **kwargs)  # skipcq: PYL-E1102
  File "/Users/admin/Library/Python/3.9/lib/python/site-packages/telegram/_bot.py", line 3661, in get_updates
    await self._post(
  File "/Users/admin/Library/Python/3.9/lib/python/site-packages/telegram/_bot.py", line 469, in _post
    return await self._do_post(
  File "/Users/admin/Library/Python/3.9/lib/python/site-packages/telegram/ext/_extbot.py", line 325, in _do_post
    return await super()._do_post(
  File "/Users/admin/Library/Python/3.9/lib/python/site-packages/telegram/_bot.py", line 497, in _do_post
    return await request.post(
  File "/Users/admin/Library/Python/3.9/lib/python/site-packages/telegram/request/_baserequest.py", line 168, in post
    result = await self._request_wrapper(
  File "/Users/admin/Library/Python/3.9/lib/python/site-packages/telegram/request/_baserequest.py", line 330, in _request_wrapper
    raise Conflict(message)
telegram.error.Conflict: Conflict: terminated by other getUpdates request; make sure that only one bot instance is running
2024-12-06 20:57:34,434 - telegram.ext.Updater - ERROR - Error while getting Updates: Conflict: terminated by other getUpdates request; make sure that only one bot instance is running
2024-12-06 20:57:34,437 - telegram.ext.Application - ERROR - No error handlers are registered, logging exception.
Traceback (most recent call last):
  File "/Users/admin/Library/Python/3.9/lib/python/site-packages/telegram/ext/_updater.py", line 607, in _network_loop_retry
    if not await action_cb():
  File "/Users/admin/Library/Python/3.9/lib/python/site-packages/telegram/ext/_updater.py", line 335, in polling_action_cb
    raise exc
  File "/Users/admin/Library/Python/3.9/lib/python/site-packages/telegram/ext/_updater.py", line 320, in polling_action_cb
    updates = await self.bot.get_updates(
  File "/Users/admin/Library/Python/3.9/lib/python/site-packages/telegram/ext/_extbot.py", line 543, in get_updates
    updates = await super().get_updates(
  File "/Users/admin/Library/Python/3.9/lib/python/site-packages/telegram/_bot.py", line 381, in decorator
    result = await func(self, *args, **kwargs)  # skipcq: PYL-E1102
  File "/Users/admin/Library/Python/3.9/lib/python/site-packages/telegram/_bot.py", line 3661, in get_updates
    await self._post(
  File "/Users/admin/Library/Python/3.9/lib/python/site-packages/telegram/_bot.py", line 469, in _post
    return await self._do_post(
  File "/Users/admin/Library/Python/3.9/lib/python/site-packages/telegram/ext/_extbot.py", line 325, in _do_post
    return await super()._do_post(
  File "/Users/admin/Library/Python/3.9/lib/python/site-packages/telegram/_bot.py", line 497, in _do_post
    return await request.post(
  File "/Users/admin/Library/Python/3.9/lib/python/site-packages/telegram/request/_baserequest.py", line 168, in post
    result = await self._request_wrapper(
  File "/Users/admin/Library/Python/3.9/lib/python/site-packages/telegram/request/_baserequest.py", line 330, in _request_wrapper
    raise Conflict(message)
telegram.error.Conflict: Conflict: terminated by other getUpdates request; make sure that only one bot instance is running
2024-12-06 20:57:41,428 - telegram.ext.Updater - ERROR - Error while getting Updates: Conflict: terminated by other getUpdates request; make sure that only one bot instance is running
2024-12-06 20:57:41,430 - telegram.ext.Application - ERROR - No error handlers are registered, logging exception.
Traceback (most recent call last):
  File "/Users/admin/Library/Python/3.9/lib/python/site-packages/telegram/ext/_updater.py", line 607, in _network_loop_retry
    if not await action_cb():
  File "/Users/admin/Library/Python/3.9/lib/python/site-packages/telegram/ext/_updater.py", line 335, in polling_action_cb
    raise exc
  File "/Users/admin/Library/Python/3.9/lib/python/site-packages/telegram/ext/_updater.py", line 320, in polling_action_cb
    updates = await self.bot.get_updates(
  File "/Users/admin/Library/Python/3.9/lib/python/site-packages/telegram/ext/_extbot.py", line 543, in get_updates
    updates = await super().get_updates(
  File "/Users/admin/Library/Python/3.9/lib/python/site-packages/telegram/_bot.py", line 381, in decorator
    result = await func(self, *args, **kwargs)  # skipcq: PYL-E1102
  File "/Users/admin/Library/Python/3.9/lib/python/site-packages/telegram/_bot.py", line 3661, in get_updates
    await self._post(
  File "/Users/admin/Library/Python/3.9/lib/python/site-packages/telegram/_bot.py", line 469, in _post
    return await self._do_post(
  File "/Users/admin/Library/Python/3.9/lib/python/site-packages/telegram/ext/_extbot.py", line 325, in _do_post
    return await super()._do_post(
  File "/Users/admin/Library/Python/3.9/lib/python/site-packages/telegram/_bot.py", line 497, in _do_post
    return await request.post(
  File "/Users/admin/Library/Python/3.9/lib/python/site-packages/telegram/request/_baserequest.py", line 168, in post
    result = await self._request_wrapper(
  File "/Users/admin/Library/Python/3.9/lib/python/site-packages/telegram/request/_baserequest.py", line 330, in _request_wrapper
    raise Conflict(message)
telegram.error.Conflict: Conflict: terminated by other getUpdates request; make sure that only one bot instance is running
2024-12-06 20:57:45,873 - telegram.ext.Updater - ERROR - Error while getting Updates: Conflict: terminated by other getUpdates request; make sure that only one bot instance is running
2024-12-06 20:57:45,873 - telegram.ext.Application - ERROR - No error handlers are registered, logging exception.
Traceback (most recent call last):
  File "/Users/admin/Library/Python/3.9/lib/python/site-packages/telegram/ext/_updater.py", line 607, in _network_loop_retry
    if not await action_cb():
  File "/Users/admin/Library/Python/3.9/lib/python/site-packages/telegram/ext/_updater.py", line 335, in polling_action_cb
    raise exc
  File "/Users/admin/Library/Python/3.9/lib/python/site-packages/telegram/ext/_updater.py", line 320, in polling_action_cb
    updates = await self.bot.get_updates(
  File "/Users/admin/Library/Python/3.9/lib/python/site-packages/telegram/ext/_extbot.py", line 543, in get_updates
    updates = await super().get_updates(
  File "/Users/admin/Library/Python/3.9/lib/python/site-packages/telegram/_bot.py", line 381, in decorator
    result = await func(self, *args, **kwargs)  # skipcq: PYL-E1102
  File "/Users/admin/Library/Python/3.9/lib/python/site-packages/telegram/_bot.py", line 3661, in get_updates
    await self._post(
  File "/Users/admin/Library/Python/3.9/lib/python/site-packages/telegram/_bot.py", line 469, in _post
    return await self._do_post(
  File "/Users/admin/Library/Python/3.9/lib/python/site-packages/telegram/ext/_extbot.py", line 325, in _do_post
    return await super()._do_post(
  File "/Users/admin/Library/Python/3.9/lib/python/site-packages/telegram/_bot.py", line 497, in _do_post
    return await request.post(
  File "/Users/admin/Library/Python/3.9/lib/python/site-packages/telegram/request/_baserequest.py", line 168, in post
    result = await self._request_wrapper(
  File "/Users/admin/Library/Python/3.9/lib/python/site-packages/telegram/request/_baserequest.py", line 330, in _request_wrapper
    raise Conflict(message)
telegram.error.Conflict: Conflict: terminated by other getUpdates request; make sure that only one bot instance is running
2024-12-06 20:58:08,288 - telegram.ext.Updater - ERROR - Error while getting Updates: Conflict: terminated by other getUpdates request; make sure that only one bot instance is running
2024-12-06 20:58:08,288 - telegram.ext.Application - ERROR - No error handlers are registered, logging exception.
Traceback (most recent call last):
  File "/Users/admin/Library/Python/3.9/lib/python/site-packages/telegram/ext/_updater.py", line 607, in _network_loop_retry
    if not await action_cb():
  File "/Users/admin/Library/Python/3.9/lib/python/site-packages/telegram/ext/_updater.py", line 335, in polling_action_cb
    raise exc
  File "/Users/admin/Library/Python/3.9/lib/python/site-packages/telegram/ext/_updater.py", line 320, in polling_action_cb
    updates = await self.bot.get_updates(
  File "/Users/admin/Library/Python/3.9/lib/python/site-packages/telegram/ext/_extbot.py", line 543, in get_updates
    updates = await super().get_updates(
  File "/Users/admin/Library/Python/3.9/lib/python/site-packages/telegram/_bot.py", line 381, in decorator
    result = await func(self, *args, **kwargs)  # skipcq: PYL-E1102
  File "/Users/admin/Library/Python/3.9/lib/python/site-packages/telegram/_bot.py", line 3661, in get_updates
    await self._post(
  File "/Users/admin/Library/Python/3.9/lib/python/site-packages/telegram/_bot.py", line 469, in _post
    return await self._do_post(
  File "/Users/admin/Library/Python/3.9/lib/python/site-packages/telegram/ext/_extbot.py", line 325, in _do_post
    return await super()._do_post(
  File "/Users/admin/Library/Python/3.9/lib/python/site-packages/telegram/_bot.py", line 497, in _do_post
    return await request.post(
  File "/Users/admin/Library/Python/3.9/lib/python/site-packages/telegram/request/_baserequest.py", line 168, in post
    result = await self._request_wrapper(
  File "/Users/admin/Library/Python/3.9/lib/python/site-packages/telegram/request/_baserequest.py", line 330, in _request_wrapper
    raise Conflict(message)
telegram.error.Conflict: Conflict: terminated by other getUpdates request; make sure that only one bot instance is running
2024-12-06 21:04:25,309 - telegram.ext.Updater - ERROR - Error while getting Updates: Conflict: terminated by other getUpdates request; make sure that only one bot instance is running
2024-12-06 21:04:25,311 - telegram.ext.Application - ERROR - No error handlers are registered, logging exception.
Traceback (most recent call last):
  File "/Users/admin/Library/Python/3.9/lib/python/site-packages/telegram/ext/_updater.py", line 607, in _network_loop_retry
    if not await action_cb():
  File "/Users/admin/Library/Python/3.9/lib/python/site-packages/telegram/ext/_updater.py", line 335, in polling_action_cb
    raise exc
  File "/Users/admin/Library/Python/3.9/lib/python/site-packages/telegram/ext/_updater.py", line 320, in polling_action_cb
    updates = await self.bot.get_updates(
  File "/Users/admin/Library/Python/3.9/lib/python/site-packages/telegram/ext/_extbot.py", line 543, in get_updates
    updates = await super().get_updates(
  File "/Users/admin/Library/Python/3.9/lib/python/site-packages/telegram/_bot.py", line 381, in decorator
    result = await func(self, *args, **kwargs)  # skipcq: PYL-E1102
  File "/Users/admin/Library/Python/3.9/lib/python/site-packages/telegram/_bot.py", line 3661, in get_updates
    await self._post(
  File "/Users/admin/Library/Python/3.9/lib/python/site-packages/telegram/_bot.py", line 469, in _post
    return await self._do_post(
  File "/Users/admin/Library/Python/3.9/lib/python/site-packages/telegram/ext/_extbot.py", line 325, in _do_post
    return await super()._do_post(
  File "/Users/admin/Library/Python/3.9/lib/python/site-packages/telegram/_bot.py", line 497, in _do_post
    return await request.post(
  File "/Users/admin/Library/Python/3.9/lib/python/site-packages/telegram/request/_baserequest.py", line 168, in post
    result = await self._request_wrapper(
  File "/Users/admin/Library/Python/3.9/lib/python/site-packages/telegram/request/_baserequest.py", line 330, in _request_wrapper
    raise Conflict(message)
telegram.error.Conflict: Conflict: terminated by other getUpdates request; make sure that only one bot instance is running
2024-12-06 21:04:33,938 - telegram.ext.Updater - ERROR - Error while getting Updates: Conflict: terminated by other getUpdates request; make sure that only one bot instance is running
2024-12-06 21:04:33,938 - telegram.ext.Application - ERROR - No error handlers are registered, logging exception.
Traceback (most recent call last):
  File "/Users/admin/Library/Python/3.9/lib/python/site-packages/telegram/ext/_updater.py", line 607, in _network_loop_retry
    if not await action_cb():
  File "/Users/admin/Library/Python/3.9/lib/python/site-packages/telegram/ext/_updater.py", line 335, in polling_action_cb
    raise exc
  File "/Users/admin/Library/Python/3.9/lib/python/site-packages/telegram/ext/_updater.py", line 320, in polling_action_cb
    updates = await self.bot.get_updates(
  File "/Users/admin/Library/Python/3.9/lib/python/site-packages/telegram/ext/_extbot.py", line 543, in get_updates
    updates = await super().get_updates(
  File "/Users/admin/Library/Python/3.9/lib/python/site-packages/telegram/_bot.py", line 381, in decorator
    result = await func(self, *args, **kwargs)  # skipcq: PYL-E1102
  File "/Users/admin/Library/Python/3.9/lib/python/site-packages/telegram/_bot.py", line 3661, in get_updates
    await self._post(
  File "/Users/admin/Library/Python/3.9/lib/python/site-packages/telegram/_bot.py", line 469, in _post
    return await self._do_post(
  File "/Users/admin/Library/Python/3.9/lib/python/site-packages/telegram/ext/_extbot.py", line 325, in _do_post
    return await super()._do_post(
  File "/Users/admin/Library/Python/3.9/lib/python/site-packages/telegram/_bot.py", line 497, in _do_post
    return await request.post(
  File "/Users/admin/Library/Python/3.9/lib/python/site-packages/telegram/request/_baserequest.py", line 168, in post
    result = await self._request_wrapper(
  File "/Users/admin/Library/Python/3.9/lib/python/site-packages/telegram/request/_baserequest.py", line 330, in _request_wrapper
    raise Conflict(message)
telegram.error.Conflict: Conflict: terminated by other getUpdates request; make sure that only one bot instance is running
2024-12-06 21:04:37,564 - telegram.ext.Updater - ERROR - Error while getting Updates: Conflict: terminated by other getUpdates request; make sure that only one bot instance is running
2024-12-06 21:04:37,564 - telegram.ext.Application - ERROR - No error handlers are registered, logging exception.
Traceback (most recent call last):
  File "/Users/admin/Library/Python/3.9/lib/python/site-packages/telegram/ext/_updater.py", line 607, in _network_loop_retry
    if not await action_cb():
  File "/Users/admin/Library/Python/3.9/lib/python/site-packages/telegram/ext/_updater.py", line 335, in polling_action_cb
    raise exc
  File "/Users/admin/Library/Python/3.9/lib/python/site-packages/telegram/ext/_updater.py", line 320, in polling_action_cb
    updates = await self.bot.get_updates(
  File "/Users/admin/Library/Python/3.9/lib/python/site-packages/telegram/ext/_extbot.py", line 543, in get_updates
    updates = await super().get_updates(
  File "/Users/admin/Library/Python/3.9/lib/python/site-packages/telegram/_bot.py", line 381, in decorator
    result = await func(self, *args, **kwargs)  # skipcq: PYL-E1102
  File "/Users/admin/Library/Python/3.9/lib/python/site-packages/telegram/_bot.py", line 3661, in get_updates
    await self._post(
  File "/Users/admin/Library/Python/3.9/lib/python/site-packages/telegram/_bot.py", line 469, in _post
    return await self._do_post(
  File "/Users/admin/Library/Python/3.9/lib/python/site-packages/telegram/ext/_extbot.py", line 325, in _do_post
    return await super()._do_post(
  File "/Users/admin/Library/Python/3.9/lib/python/site-packages/telegram/_bot.py", line 497, in _do_post
    return await request.post(
  File "/Users/admin/Library/Python/3.9/lib/python/site-packages/telegram/request/_baserequest.py", line 168, in post
    result = await self._request_wrapper(
  File "/Users/admin/Library/Python/3.9/lib/python/site-packages/telegram/request/_baserequest.py", line 330, in _request_wrapper
    raise Conflict(message)
telegram.error.Conflict: Conflict: terminated by other getUpdates request; make sure that only one bot instance is running
2024-12-06 21:04:59,084 - telegram.ext.Updater - ERROR - Error while getting Updates: Conflict: terminated by other getUpdates request; make sure that only one bot instance is running
2024-12-06 21:04:59,085 - telegram.ext.Application - ERROR - No error handlers are registered, logging exception.
Traceback (most recent call last):
  File "/Users/admin/Library/Python/3.9/lib/python/site-packages/telegram/ext/_updater.py", line 607, in _network_loop_retry
    if not await action_cb():
  File "/Users/admin/Library/Python/3.9/lib/python/site-packages/telegram/ext/_updater.py", line 335, in polling_action_cb
    raise exc
  File "/Users/admin/Library/Python/3.9/lib/python/site-packages/telegram/ext/_updater.py", line 320, in polling_action_cb
    updates = await self.bot.get_updates(
  File "/Users/admin/Library/Python/3.9/lib/python/site-packages/telegram/ext/_extbot.py", line 543, in get_updates
    updates = await super().get_updates(
  File "/Users/admin/Library/Python/3.9/lib/python/site-packages/telegram/_bot.py", line 381, in decorator
    result = await func(self, *args, **kwargs)  # skipcq: PYL-E1102
  File "/Users/admin/Library/Python/3.9/lib/python/site-packages/telegram/_bot.py", line 3661, in get_updates
    await self._post(
  File "/Users/admin/Library/Python/3.9/lib/python/site-packages/telegram/_bot.py", line 469, in _post
    return await self._do_post(
  File "/Users/admin/Library/Python/3.9/lib/python/site-packages/telegram/ext/_extbot.py", line 325, in _do_post
    return await super()._do_post(
  File "/Users/admin/Library/Python/3.9/lib/python/site-packages/telegram/_bot.py", line 497, in _do_post
    return await request.post(
  File "/Users/admin/Library/Python/3.9/lib/python/site-packages/telegram/request/_baserequest.py", line 168, in post
    result = await self._request_wrapper(
  File "/Users/admin/Library/Python/3.9/lib/python/site-packages/telegram/request/_baserequest.py", line 330, in _request_wrapper
    raise Conflict(message)
telegram.error.Conflict: Conflict: terminated by other getUpdates request; make sure that only one bot instance is running
2024-12-06 21:05:09,075 - telegram.ext.Updater - ERROR - Error while getting Updates: Conflict: terminated by other getUpdates request; make sure that only one bot instance is running
2024-12-06 21:05:09,075 - telegram.ext.Application - ERROR - No error handlers are registered, logging exception.
Traceback (most recent call last):
  File "/Users/admin/Library/Python/3.9/lib/python/site-packages/telegram/ext/_updater.py", line 607, in _network_loop_retry
    if not await action_cb():
  File "/Users/admin/Library/Python/3.9/lib/python/site-packages/telegram/ext/_updater.py", line 335, in polling_action_cb
    raise exc
  File "/Users/admin/Library/Python/3.9/lib/python/site-packages/telegram/ext/_updater.py", line 320, in polling_action_cb
    updates = await self.bot.get_updates(
  File "/Users/admin/Library/Python/3.9/lib/python/site-packages/telegram/ext/_extbot.py", line 543, in get_updates
    updates = await super().get_updates(
  File "/Users/admin/Library/Python/3.9/lib/python/site-packages/telegram/_bot.py", line 381, in decorator
    result = await func(self, *args, **kwargs)  # skipcq: PYL-E1102
  File "/Users/admin/Library/Python/3.9/lib/python/site-packages/telegram/_bot.py", line 3661, in get_updates
    await self._post(
  File "/Users/admin/Library/Python/3.9/lib/python/site-packages/telegram/_bot.py", line 469, in _post
    return await self._do_post(
  File "/Users/admin/Library/Python/3.9/lib/python/site-packages/telegram/ext/_extbot.py", line 325, in _do_post
    return await super()._do_post(
  File "/Users/admin/Library/Python/3.9/lib/python/site-packages/telegram/_bot.py", line 497, in _do_post
    return await request.post(
  File "/Users/admin/Library/Python/3.9/lib/python/site-packages/telegram/request/_baserequest.py", line 168, in post
    result = await self._request_wrapper(
  File "/Users/admin/Library/Python/3.9/lib/python/site-packages/telegram/request/_baserequest.py", line 330, in _request_wrapper
    raise Conflict(message)
telegram.error.Conflict: Conflict: terminated by other getUpdates request; make sure that only one bot instance is running
2024-12-06 21:05:12,479 - telegram.ext.Updater - ERROR - Error while getting Updates: Conflict: terminated by other getUpdates request; make sure that only one bot instance is running
2024-12-06 21:05:12,480 - telegram.ext.Application - ERROR - No error handlers are registered, logging exception.
Traceback (most recent call last):
  File "/Users/admin/Library/Python/3.9/lib/python/site-packages/telegram/ext/_updater.py", line 607, in _network_loop_retry
    if not await action_cb():
  File "/Users/admin/Library/Python/3.9/lib/python/site-packages/telegram/ext/_updater.py", line 335, in polling_action_cb
    raise exc
  File "/Users/admin/Library/Python/3.9/lib/python/site-packages/telegram/ext/_updater.py", line 320, in polling_action_cb
    updates = await self.bot.get_updates(
  File "/Users/admin/Library/Python/3.9/lib/python/site-packages/telegram/ext/_extbot.py", line 543, in get_updates
    updates = await super().get_updates(
  File "/Users/admin/Library/Python/3.9/lib/python/site-packages/telegram/_bot.py", line 381, in decorator
    result = await func(self, *args, **kwargs)  # skipcq: PYL-E1102
  File "/Users/admin/Library/Python/3.9/lib/python/site-packages/telegram/_bot.py", line 3661, in get_updates
    await self._post(
  File "/Users/admin/Library/Python/3.9/lib/python/site-packages/telegram/_bot.py", line 469, in _post
    return await self._do_post(
  File "/Users/admin/Library/Python/3.9/lib/python/site-packages/telegram/ext/_extbot.py", line 325, in _do_post
    return await super()._do_post(
  File "/Users/admin/Library/Python/3.9/lib/python/site-packages/telegram/_bot.py", line 497, in _do_post
    return await request.post(
  File "/Users/admin/Library/Python/3.9/lib/python/site-packages/telegram/request/_baserequest.py", line 168, in post
    result = await self._request_wrapper(
  File "/Users/admin/Library/Python/3.9/lib/python/site-packages/telegram/request/_baserequest.py", line 330, in _request_wrapper
    raise Conflict(message)
telegram.error.Conflict: Conflict: terminated by other getUpdates request; make sure that only one bot instance is running
2024-12-06 21:05:33,609 - telegram.ext.Updater - ERROR - Error while getting Updates: Conflict: terminated by other getUpdates request; make sure that only one bot instance is running
2024-12-06 21:05:33,609 - telegram.ext.Application - ERROR - No error handlers are registered, logging exception.
Traceback (most recent call last):
  File "/Users/admin/Library/Python/3.9/lib/python/site-packages/telegram/ext/_updater.py", line 607, in _network_loop_retry
    if not await action_cb():
  File "/Users/admin/Library/Python/3.9/lib/python/site-packages/telegram/ext/_updater.py", line 335, in polling_action_cb
    raise exc
  File "/Users/admin/Library/Python/3.9/lib/python/site-packages/telegram/ext/_updater.py", line 320, in polling_action_cb
    updates = await self.bot.get_updates(
  File "/Users/admin/Library/Python/3.9/lib/python/site-packages/telegram/ext/_extbot.py", line 543, in get_updates
    updates = await super().get_updates(
  File "/Users/admin/Library/Python/3.9/lib/python/site-packages/telegram/_bot.py", line 381, in decorator
    result = await func(self, *args, **kwargs)  # skipcq: PYL-E1102
  File "/Users/admin/Library/Python/3.9/lib/python/site-packages/telegram/_bot.py", line 3661, in get_updates
    await self._post(
  File "/Users/admin/Library/Python/3.9/lib/python/site-packages/telegram/_bot.py", line 469, in _post
    return await self._do_post(
  File "/Users/admin/Library/Python/3.9/lib/python/site-packages/telegram/ext/_extbot.py", line 325, in _do_post
    return await super()._do_post(
  File "/Users/admin/Library/Python/3.9/lib/python/site-packages/telegram/_bot.py", line 497, in _do_post
    return await request.post(
  File "/Users/admin/Library/Python/3.9/lib/python/site-packages/telegram/request/_baserequest.py", line 168, in post
    result = await self._request_wrapper(
  File "/Users/admin/Library/Python/3.9/lib/python/site-packages/telegram/request/_baserequest.py", line 330, in _request_wrapper
    raise Conflict(message)
telegram.error.Conflict: Conflict: terminated by other getUpdates request; make sure that only one bot instance is running
2024-12-06 21:05:44,068 - telegram.ext.Updater - ERROR - Error while getting Updates: Conflict: terminated by other getUpdates request; make sure that only one bot instance is running
2024-12-06 21:05:44,068 - telegram.ext.Application - ERROR - No error handlers are registered, logging exception.
Traceback (most recent call last):
  File "/Users/admin/Library/Python/3.9/lib/python/site-packages/telegram/ext/_updater.py", line 607, in _network_loop_retry
    if not await action_cb():
  File "/Users/admin/Library/Python/3.9/lib/python/site-packages/telegram/ext/_updater.py", line 335, in polling_action_cb
    raise exc
  File "/Users/admin/Library/Python/3.9/lib/python/site-packages/telegram/ext/_updater.py", line 320, in polling_action_cb
    updates = await self.bot.get_updates(
  File "/Users/admin/Library/Python/3.9/lib/python/site-packages/telegram/ext/_extbot.py", line 543, in get_updates
    updates = await super().get_updates(
  File "/Users/admin/Library/Python/3.9/lib/python/site-packages/telegram/_bot.py", line 381, in decorator
    result = await func(self, *args, **kwargs)  # skipcq: PYL-E1102
  File "/Users/admin/Library/Python/3.9/lib/python/site-packages/telegram/_bot.py", line 3661, in get_updates
    await self._post(
  File "/Users/admin/Library/Python/3.9/lib/python/site-packages/telegram/_bot.py", line 469, in _post
    return await self._do_post(
  File "/Users/admin/Library/Python/3.9/lib/python/site-packages/telegram/ext/_extbot.py", line 325, in _do_post
    return await super()._do_post(
  File "/Users/admin/Library/Python/3.9/lib/python/site-packages/telegram/_bot.py", line 497, in _do_post
    return await request.post(
  File "/Users/admin/Library/Python/3.9/lib/python/site-packages/telegram/request/_baserequest.py", line 168, in post
    result = await self._request_wrapper(
  File "/Users/admin/Library/Python/3.9/lib/python/site-packages/telegram/request/_baserequest.py", line 330, in _request_wrapper
    raise Conflict(message)
telegram.error.Conflict: Conflict: terminated by other getUpdates request; make sure that only one bot instance is running
2024-12-06 21:05:50,009 - telegram.ext.Updater - ERROR - Error while getting Updates: Conflict: terminated by other getUpdates request; make sure that only one bot instance is running
2024-12-06 21:05:50,009 - telegram.ext.Application - ERROR - No error handlers are registered, logging exception.
Traceback (most recent call last):
  File "/Users/admin/Library/Python/3.9/lib/python/site-packages/telegram/ext/_updater.py", line 607, in _network_loop_retry
    if not await action_cb():
  File "/Users/admin/Library/Python/3.9/lib/python/site-packages/telegram/ext/_updater.py", line 335, in polling_action_cb
    raise exc
  File "/Users/admin/Library/Python/3.9/lib/python/site-packages/telegram/ext/_updater.py", line 320, in polling_action_cb
    updates = await self.bot.get_updates(
  File "/Users/admin/Library/Python/3.9/lib/python/site-packages/telegram/ext/_extbot.py", line 543, in get_updates
    updates = await super().get_updates(
  File "/Users/admin/Library/Python/3.9/lib/python/site-packages/telegram/_bot.py", line 381, in decorator
    result = await func(self, *args, **kwargs)  # skipcq: PYL-E1102
  File "/Users/admin/Library/Python/3.9/lib/python/site-packages/telegram/_bot.py", line 3661, in get_updates
    await self._post(
  File "/Users/admin/Library/Python/3.9/lib/python/site-packages/telegram/_bot.py", line 469, in _post
    return await self._do_post(
  File "/Users/admin/Library/Python/3.9/lib/python/site-packages/telegram/ext/_extbot.py", line 325, in _do_post
    return await super()._do_post(
  File "/Users/admin/Library/Python/3.9/lib/python/site-packages/telegram/_bot.py", line 497, in _do_post
    return await request.post(
  File "/Users/admin/Library/Python/3.9/lib/python/site-packages/telegram/request/_baserequest.py", line 168, in post
    result = await self._request_wrapper(
  File "/Users/admin/Library/Python/3.9/lib/python/site-packages/telegram/request/_baserequest.py", line 330, in _request_wrapper
    raise Conflict(message)
telegram.error.Conflict: Conflict: terminated by other getUpdates request; make sure that only one bot instance is running
2024-12-06 21:06:07,275 - telegram.ext.Updater - ERROR - Error while getting Updates: Conflict: terminated by other getUpdates request; make sure that only one bot instance is running
2024-12-06 21:06:07,275 - telegram.ext.Application - ERROR - No error handlers are registered, logging exception.
Traceback (most recent call last):
  File "/Users/admin/Library/Python/3.9/lib/python/site-packages/telegram/ext/_updater.py", line 607, in _network_loop_retry
    if not await action_cb():
  File "/Users/admin/Library/Python/3.9/lib/python/site-packages/telegram/ext/_updater.py", line 335, in polling_action_cb
    raise exc
  File "/Users/admin/Library/Python/3.9/lib/python/site-packages/telegram/ext/_updater.py", line 320, in polling_action_cb
    updates = await self.bot.get_updates(
  File "/Users/admin/Library/Python/3.9/lib/python/site-packages/telegram/ext/_extbot.py", line 543, in get_updates
    updates = await super().get_updates(
  File "/Users/admin/Library/Python/3.9/lib/python/site-packages/telegram/_bot.py", line 381, in decorator
    result = await func(self, *args, **kwargs)  # skipcq: PYL-E1102
  File "/Users/admin/Library/Python/3.9/lib/python/site-packages/telegram/_bot.py", line 3661, in get_updates
    await self._post(
  File "/Users/admin/Library/Python/3.9/lib/python/site-packages/telegram/_bot.py", line 469, in _post
    return await self._do_post(
  File "/Users/admin/Library/Python/3.9/lib/python/site-packages/telegram/ext/_extbot.py", line 325, in _do_post
    return await super()._do_post(
  File "/Users/admin/Library/Python/3.9/lib/python/site-packages/telegram/_bot.py", line 497, in _do_post
    return await request.post(
  File "/Users/admin/Library/Python/3.9/lib/python/site-packages/telegram/request/_baserequest.py", line 168, in post
    result = await self._request_wrapper(
  File "/Users/admin/Library/Python/3.9/lib/python/site-packages/telegram/request/_baserequest.py", line 330, in _request_wrapper
    raise Conflict(message)
telegram.error.Conflict: Conflict: terminated by other getUpdates request; make sure that only one bot instance is running
2024-12-06 21:06:18,709 - telegram.ext.Updater - ERROR - Error while getting Updates: Conflict: terminated by other getUpdates request; make sure that only one bot instance is running
2024-12-06 21:06:18,709 - telegram.ext.Application - ERROR - No error handlers are registered, logging exception.
Traceback (most recent call last):
  File "/Users/admin/Library/Python/3.9/lib/python/site-packages/telegram/ext/_updater.py", line 607, in _network_loop_retry
    if not await action_cb():
  File "/Users/admin/Library/Python/3.9/lib/python/site-packages/telegram/ext/_updater.py", line 335, in polling_action_cb
    raise exc
  File "/Users/admin/Library/Python/3.9/lib/python/site-packages/telegram/ext/_updater.py", line 320, in polling_action_cb
    updates = await self.bot.get_updates(
  File "/Users/admin/Library/Python/3.9/lib/python/site-packages/telegram/ext/_extbot.py", line 543, in get_updates
    updates = await super().get_updates(
  File "/Users/admin/Library/Python/3.9/lib/python/site-packages/telegram/_bot.py", line 381, in decorator
    result = await func(self, *args, **kwargs)  # skipcq: PYL-E1102
  File "/Users/admin/Library/Python/3.9/lib/python/site-packages/telegram/_bot.py", line 3661, in get_updates
    await self._post(
  File "/Users/admin/Library/Python/3.9/lib/python/site-packages/telegram/_bot.py", line 469, in _post
    return await self._do_post(
  File "/Users/admin/Library/Python/3.9/lib/python/site-packages/telegram/ext/_extbot.py", line 325, in _do_post
    return await super()._do_post(
  File "/Users/admin/Library/Python/3.9/lib/python/site-packages/telegram/_bot.py", line 497, in _do_post
    return await request.post(
  File "/Users/admin/Library/Python/3.9/lib/python/site-packages/telegram/request/_baserequest.py", line 168, in post
    result = await self._request_wrapper(
  File "/Users/admin/Library/Python/3.9/lib/python/site-packages/telegram/request/_baserequest.py", line 330, in _request_wrapper
    raise Conflict(message)
telegram.error.Conflict: Conflict: terminated by other getUpdates request; make sure that only one bot instance is running
2024-12-06 21:06:22,763 - telegram.ext.Updater - ERROR - Error while getting Updates: Conflict: terminated by other getUpdates request; make sure that only one bot instance is running
2024-12-06 21:06:22,764 - telegram.ext.Application - ERROR - No error handlers are registered, logging exception.
Traceback (most recent call last):
  File "/Users/admin/Library/Python/3.9/lib/python/site-packages/telegram/ext/_updater.py", line 607, in _network_loop_retry
    if not await action_cb():
  File "/Users/admin/Library/Python/3.9/lib/python/site-packages/telegram/ext/_updater.py", line 335, in polling_action_cb
    raise exc
  File "/Users/admin/Library/Python/3.9/lib/python/site-packages/telegram/ext/_updater.py", line 320, in polling_action_cb
    updates = await self.bot.get_updates(
  File "/Users/admin/Library/Python/3.9/lib/python/site-packages/telegram/ext/_extbot.py", line 543, in get_updates
    updates = await super().get_updates(
  File "/Users/admin/Library/Python/3.9/lib/python/site-packages/telegram/_bot.py", line 381, in decorator
    result = await func(self, *args, **kwargs)  # skipcq: PYL-E1102
  File "/Users/admin/Library/Python/3.9/lib/python/site-packages/telegram/_bot.py", line 3661, in get_updates
    await self._post(
  File "/Users/admin/Library/Python/3.9/lib/python/site-packages/telegram/_bot.py", line 469, in _post
    return await self._do_post(
  File "/Users/admin/Library/Python/3.9/lib/python/site-packages/telegram/ext/_extbot.py", line 325, in _do_post
    return await super()._do_post(
  File "/Users/admin/Library/Python/3.9/lib/python/site-packages/telegram/_bot.py", line 497, in _do_post
    return await request.post(
  File "/Users/admin/Library/Python/3.9/lib/python/site-packages/telegram/request/_baserequest.py", line 168, in post
    result = await self._request_wrapper(
  File "/Users/admin/Library/Python/3.9/lib/python/site-packages/telegram/request/_baserequest.py", line 330, in _request_wrapper
    raise Conflict(message)
telegram.error.Conflict: Conflict: terminated by other getUpdates request; make sure that only one bot instance is running
2024-12-06 21:06:41,586 - telegram.ext.Updater - ERROR - Error while getting Updates: Conflict: terminated by other getUpdates request; make sure that only one bot instance is running
2024-12-06 21:06:41,587 - telegram.ext.Application - ERROR - No error handlers are registered, logging exception.
Traceback (most recent call last):
  File "/Users/admin/Library/Python/3.9/lib/python/site-packages/telegram/ext/_updater.py", line 607, in _network_loop_retry
    if not await action_cb():
  File "/Users/admin/Library/Python/3.9/lib/python/site-packages/telegram/ext/_updater.py", line 335, in polling_action_cb
    raise exc
  File "/Users/admin/Library/Python/3.9/lib/python/site-packages/telegram/ext/_updater.py", line 320, in polling_action_cb
    updates = await self.bot.get_updates(
  File "/Users/admin/Library/Python/3.9/lib/python/site-packages/telegram/ext/_extbot.py", line 543, in get_updates
    updates = await super().get_updates(
  File "/Users/admin/Library/Python/3.9/lib/python/site-packages/telegram/_bot.py", line 381, in decorator
    result = await func(self, *args, **kwargs)  # skipcq: PYL-E1102
  File "/Users/admin/Library/Python/3.9/lib/python/site-packages/telegram/_bot.py", line 3661, in get_updates
    await self._post(
  File "/Users/admin/Library/Python/3.9/lib/python/site-packages/telegram/_bot.py", line 469, in _post
    return await self._do_post(
  File "/Users/admin/Library/Python/3.9/lib/python/site-packages/telegram/ext/_extbot.py", line 325, in _do_post
    return await super()._do_post(
  File "/Users/admin/Library/Python/3.9/lib/python/site-packages/telegram/_bot.py", line 497, in _do_post
    return await request.post(
  File "/Users/admin/Library/Python/3.9/lib/python/site-packages/telegram/request/_baserequest.py", line 168, in post
    result = await self._request_wrapper(
  File "/Users/admin/Library/Python/3.9/lib/python/site-packages/telegram/request/_baserequest.py", line 330, in _request_wrapper
    raise Conflict(message)
telegram.error.Conflict: Conflict: terminated by other getUpdates request; make sure that only one bot instance is running
2024-12-06 21:06:52,543 - telegram.ext.Updater - ERROR - Error while getting Updates: Conflict: terminated by other getUpdates request; make sure that only one bot instance is running
2024-12-06 21:06:52,543 - telegram.ext.Application - ERROR - No error handlers are registered, logging exception.
Traceback (most recent call last):
  File "/Users/admin/Library/Python/3.9/lib/python/site-packages/telegram/ext/_updater.py", line 607, in _network_loop_retry
    if not await action_cb():
  File "/Users/admin/Library/Python/3.9/lib/python/site-packages/telegram/ext/_updater.py", line 335, in polling_action_cb
    raise exc
  File "/Users/admin/Library/Python/3.9/lib/python/site-packages/telegram/ext/_updater.py", line 320, in polling_action_cb
    updates = await self.bot.get_updates(
  File "/Users/admin/Library/Python/3.9/lib/python/site-packages/telegram/ext/_extbot.py", line 543, in get_updates
    updates = await super().get_updates(
  File "/Users/admin/Library/Python/3.9/lib/python/site-packages/telegram/_bot.py", line 381, in decorator
    result = await func(self, *args, **kwargs)  # skipcq: PYL-E1102
  File "/Users/admin/Library/Python/3.9/lib/python/site-packages/telegram/_bot.py", line 3661, in get_updates
    await self._post(
  File "/Users/admin/Library/Python/3.9/lib/python/site-packages/telegram/_bot.py", line 469, in _post
    return await self._do_post(
  File "/Users/admin/Library/Python/3.9/lib/python/site-packages/telegram/ext/_extbot.py", line 325, in _do_post
    return await super()._do_post(
  File "/Users/admin/Library/Python/3.9/lib/python/site-packages/telegram/_bot.py", line 497, in _do_post
    return await request.post(
  File "/Users/admin/Library/Python/3.9/lib/python/site-packages/telegram/request/_baserequest.py", line 168, in post
    result = await self._request_wrapper(
  File "/Users/admin/Library/Python/3.9/lib/python/site-packages/telegram/request/_baserequest.py", line 330, in _request_wrapper
    raise Conflict(message)
telegram.error.Conflict: Conflict: terminated by other getUpdates request; make sure that only one bot instance is running
2024-12-06 21:06:57,376 - telegram.ext.Updater - ERROR - Error while getting Updates: Conflict: terminated by other getUpdates request; make sure that only one bot instance is running
2024-12-06 21:06:57,377 - telegram.ext.Application - ERROR - No error handlers are registered, logging exception.
Traceback (most recent call last):
  File "/Users/admin/Library/Python/3.9/lib/python/site-packages/telegram/ext/_updater.py", line 607, in _network_loop_retry
    if not await action_cb():
  File "/Users/admin/Library/Python/3.9/lib/python/site-packages/telegram/ext/_updater.py", line 335, in polling_action_cb
    raise exc
  File "/Users/admin/Library/Python/3.9/lib/python/site-packages/telegram/ext/_updater.py", line 320, in polling_action_cb
    updates = await self.bot.get_updates(
  File "/Users/admin/Library/Python/3.9/lib/python/site-packages/telegram/ext/_extbot.py", line 543, in get_updates
    updates = await super().get_updates(
  File "/Users/admin/Library/Python/3.9/lib/python/site-packages/telegram/_bot.py", line 381, in decorator
    result = await func(self, *args, **kwargs)  # skipcq: PYL-E1102
  File "/Users/admin/Library/Python/3.9/lib/python/site-packages/telegram/_bot.py", line 3661, in get_updates
    await self._post(
  File "/Users/admin/Library/Python/3.9/lib/python/site-packages/telegram/_bot.py", line 469, in _post
    return await self._do_post(
  File "/Users/admin/Library/Python/3.9/lib/python/site-packages/telegram/ext/_extbot.py", line 325, in _do_post
    return await super()._do_post(
  File "/Users/admin/Library/Python/3.9/lib/python/site-packages/telegram/_bot.py", line 497, in _do_post
    return await request.post(
  File "/Users/admin/Library/Python/3.9/lib/python/site-packages/telegram/request/_baserequest.py", line 168, in post
    result = await self._request_wrapper(
  File "/Users/admin/Library/Python/3.9/lib/python/site-packages/telegram/request/_baserequest.py", line 330, in _request_wrapper
    raise Conflict(message)
telegram.error.Conflict: Conflict: terminated by other getUpdates request; make sure that only one bot instance is running
2024-12-06 21:07:15,172 - telegram.ext.Updater - ERROR - Error while getting Updates: Conflict: terminated by other getUpdates request; make sure that only one bot instance is running
2024-12-06 21:07:15,173 - telegram.ext.Application - ERROR - No error handlers are registered, logging exception.
Traceback (most recent call last):
  File "/Users/admin/Library/Python/3.9/lib/python/site-packages/telegram/ext/_updater.py", line 607, in _network_loop_retry
    if not await action_cb():
  File "/Users/admin/Library/Python/3.9/lib/python/site-packages/telegram/ext/_updater.py", line 335, in polling_action_cb
    raise exc
  File "/Users/admin/Library/Python/3.9/lib/python/site-packages/telegram/ext/_updater.py", line 320, in polling_action_cb
    updates = await self.bot.get_updates(
  File "/Users/admin/Library/Python/3.9/lib/python/site-packages/telegram/ext/_extbot.py", line 543, in get_updates
    updates = await super().get_updates(
  File "/Users/admin/Library/Python/3.9/lib/python/site-packages/telegram/_bot.py", line 381, in decorator
    result = await func(self, *args, **kwargs)  # skipcq: PYL-E1102
  File "/Users/admin/Library/Python/3.9/lib/python/site-packages/telegram/_bot.py", line 3661, in get_updates
    await self._post(
  File "/Users/admin/Library/Python/3.9/lib/python/site-packages/telegram/_bot.py", line 469, in _post
    return await self._do_post(
  File "/Users/admin/Library/Python/3.9/lib/python/site-packages/telegram/ext/_extbot.py", line 325, in _do_post
    return await super()._do_post(
  File "/Users/admin/Library/Python/3.9/lib/python/site-packages/telegram/_bot.py", line 497, in _do_post
    return await request.post(
  File "/Users/admin/Library/Python/3.9/lib/python/site-packages/telegram/request/_baserequest.py", line 168, in post
    result = await self._request_wrapper(
  File "/Users/admin/Library/Python/3.9/lib/python/site-packages/telegram/request/_baserequest.py", line 330, in _request_wrapper
    raise Conflict(message)
telegram.error.Conflict: Conflict: terminated by other getUpdates request; make sure that only one bot instance is running
2024-12-06 21:07:27,544 - telegram.ext.Updater - ERROR - Error while getting Updates: Conflict: terminated by other getUpdates request; make sure that only one bot instance is running
2024-12-06 21:07:27,544 - telegram.ext.Application - ERROR - No error handlers are registered, logging exception.
Traceback (most recent call last):
  File "/Users/admin/Library/Python/3.9/lib/python/site-packages/telegram/ext/_updater.py", line 607, in _network_loop_retry
    if not await action_cb():
  File "/Users/admin/Library/Python/3.9/lib/python/site-packages/telegram/ext/_updater.py", line 335, in polling_action_cb
    raise exc
  File "/Users/admin/Library/Python/3.9/lib/python/site-packages/telegram/ext/_updater.py", line 320, in polling_action_cb
    updates = await self.bot.get_updates(
  File "/Users/admin/Library/Python/3.9/lib/python/site-packages/telegram/ext/_extbot.py", line 543, in get_updates
    updates = await super().get_updates(
  File "/Users/admin/Library/Python/3.9/lib/python/site-packages/telegram/_bot.py", line 381, in decorator
    result = await func(self, *args, **kwargs)  # skipcq: PYL-E1102
  File "/Users/admin/Library/Python/3.9/lib/python/site-packages/telegram/_bot.py", line 3661, in get_updates
    await self._post(
  File "/Users/admin/Library/Python/3.9/lib/python/site-packages/telegram/_bot.py", line 469, in _post
    return await self._do_post(
  File "/Users/admin/Library/Python/3.9/lib/python/site-packages/telegram/ext/_extbot.py", line 325, in _do_post
    return await super()._do_post(
  File "/Users/admin/Library/Python/3.9/lib/python/site-packages/telegram/_bot.py", line 497, in _do_post
    return await request.post(
  File "/Users/admin/Library/Python/3.9/lib/python/site-packages/telegram/request/_baserequest.py", line 168, in post
    result = await self._request_wrapper(
  File "/Users/admin/Library/Python/3.9/lib/python/site-packages/telegram/request/_baserequest.py", line 330, in _request_wrapper
    raise Conflict(message)
telegram.error.Conflict: Conflict: terminated by other getUpdates request; make sure that only one bot instance is running
2024-12-06 21:07:33,163 - telegram.ext.Updater - ERROR - Error while getting Updates: Conflict: terminated by other getUpdates request; make sure that only one bot instance is running
2024-12-06 21:07:33,163 - telegram.ext.Application - ERROR - No error handlers are registered, logging exception.
Traceback (most recent call last):
  File "/Users/admin/Library/Python/3.9/lib/python/site-packages/telegram/ext/_updater.py", line 607, in _network_loop_retry
    if not await action_cb():
  File "/Users/admin/Library/Python/3.9/lib/python/site-packages/telegram/ext/_updater.py", line 335, in polling_action_cb
    raise exc
  File "/Users/admin/Library/Python/3.9/lib/python/site-packages/telegram/ext/_updater.py", line 320, in polling_action_cb
    updates = await self.bot.get_updates(
  File "/Users/admin/Library/Python/3.9/lib/python/site-packages/telegram/ext/_extbot.py", line 543, in get_updates
    updates = await super().get_updates(
  File "/Users/admin/Library/Python/3.9/lib/python/site-packages/telegram/_bot.py", line 381, in decorator
    result = await func(self, *args, **kwargs)  # skipcq: PYL-E1102
  File "/Users/admin/Library/Python/3.9/lib/python/site-packages/telegram/_bot.py", line 3661, in get_updates
    await self._post(
  File "/Users/admin/Library/Python/3.9/lib/python/site-packages/telegram/_bot.py", line 469, in _post
    return await self._do_post(
  File "/Users/admin/Library/Python/3.9/lib/python/site-packages/telegram/ext/_extbot.py", line 325, in _do_post
    return await super()._do_post(
  File "/Users/admin/Library/Python/3.9/lib/python/site-packages/telegram/_bot.py", line 497, in _do_post
    return await request.post(
  File "/Users/admin/Library/Python/3.9/lib/python/site-packages/telegram/request/_baserequest.py", line 168, in post
    result = await self._request_wrapper(
  File "/Users/admin/Library/Python/3.9/lib/python/site-packages/telegram/request/_baserequest.py", line 330, in _request_wrapper
    raise Conflict(message)
telegram.error.Conflict: Conflict: terminated by other getUpdates request; make sure that only one bot instance is running
2024-12-06 21:07:49,673 - telegram.ext.Updater - ERROR - Error while getting Updates: Conflict: terminated by other getUpdates request; make sure that only one bot instance is running
2024-12-06 21:07:49,673 - telegram.ext.Application - ERROR - No error handlers are registered, logging exception.
Traceback (most recent call last):
  File "/Users/admin/Library/Python/3.9/lib/python/site-packages/telegram/ext/_updater.py", line 607, in _network_loop_retry
    if not await action_cb():
  File "/Users/admin/Library/Python/3.9/lib/python/site-packages/telegram/ext/_updater.py", line 335, in polling_action_cb
    raise exc
  File "/Users/admin/Library/Python/3.9/lib/python/site-packages/telegram/ext/_updater.py", line 320, in polling_action_cb
    updates = await self.bot.get_updates(
  File "/Users/admin/Library/Python/3.9/lib/python/site-packages/telegram/ext/_extbot.py", line 543, in get_updates
    updates = await super().get_updates(
  File "/Users/admin/Library/Python/3.9/lib/python/site-packages/telegram/_bot.py", line 381, in decorator
    result = await func(self, *args, **kwargs)  # skipcq: PYL-E1102
  File "/Users/admin/Library/Python/3.9/lib/python/site-packages/telegram/_bot.py", line 3661, in get_updates
    await self._post(
  File "/Users/admin/Library/Python/3.9/lib/python/site-packages/telegram/_bot.py", line 469, in _post
    return await self._do_post(
  File "/Users/admin/Library/Python/3.9/lib/python/site-packages/telegram/ext/_extbot.py", line 325, in _do_post
    return await super()._do_post(
  File "/Users/admin/Library/Python/3.9/lib/python/site-packages/telegram/_bot.py", line 497, in _do_post
    return await request.post(
  File "/Users/admin/Library/Python/3.9/lib/python/site-packages/telegram/request/_baserequest.py", line 168, in post
    result = await self._request_wrapper(
  File "/Users/admin/Library/Python/3.9/lib/python/site-packages/telegram/request/_baserequest.py", line 330, in _request_wrapper
    raise Conflict(message)
telegram.error.Conflict: Conflict: terminated by other getUpdates request; make sure that only one bot instance is running
2024-12-06 21:08:01,701 - telegram.ext.Updater - ERROR - Error while getting Updates: Conflict: terminated by other getUpdates request; make sure that only one bot instance is running
2024-12-06 21:08:01,702 - telegram.ext.Application - ERROR - No error handlers are registered, logging exception.
Traceback (most recent call last):
  File "/Users/admin/Library/Python/3.9/lib/python/site-packages/telegram/ext/_updater.py", line 607, in _network_loop_retry
    if not await action_cb():
  File "/Users/admin/Library/Python/3.9/lib/python/site-packages/telegram/ext/_updater.py", line 335, in polling_action_cb
    raise exc
  File "/Users/admin/Library/Python/3.9/lib/python/site-packages/telegram/ext/_updater.py", line 320, in polling_action_cb
    updates = await self.bot.get_updates(
  File "/Users/admin/Library/Python/3.9/lib/python/site-packages/telegram/ext/_extbot.py", line 543, in get_updates
    updates = await super().get_updates(
  File "/Users/admin/Library/Python/3.9/lib/python/site-packages/telegram/_bot.py", line 381, in decorator
    result = await func(self, *args, **kwargs)  # skipcq: PYL-E1102
  File "/Users/admin/Library/Python/3.9/lib/python/site-packages/telegram/_bot.py", line 3661, in get_updates
    await self._post(
  File "/Users/admin/Library/Python/3.9/lib/python/site-packages/telegram/_bot.py", line 469, in _post
    return await self._do_post(
  File "/Users/admin/Library/Python/3.9/lib/python/site-packages/telegram/ext/_extbot.py", line 325, in _do_post
    return await super()._do_post(
  File "/Users/admin/Library/Python/3.9/lib/python/site-packages/telegram/_bot.py", line 497, in _do_post
    return await request.post(
  File "/Users/admin/Library/Python/3.9/lib/python/site-packages/telegram/request/_baserequest.py", line 168, in post
    result = await self._request_wrapper(
  File "/Users/admin/Library/Python/3.9/lib/python/site-packages/telegram/request/_baserequest.py", line 330, in _request_wrapper
    raise Conflict(message)
telegram.error.Conflict: Conflict: terminated by other getUpdates request; make sure that only one bot instance is running
2024-12-06 21:08:08,222 - telegram.ext.Updater - ERROR - Error while getting Updates: Conflict: terminated by other getUpdates request; make sure that only one bot instance is running
2024-12-06 21:08:08,222 - telegram.ext.Application - ERROR - No error handlers are registered, logging exception.
Traceback (most recent call last):
  File "/Users/admin/Library/Python/3.9/lib/python/site-packages/telegram/ext/_updater.py", line 607, in _network_loop_retry
    if not await action_cb():
  File "/Users/admin/Library/Python/3.9/lib/python/site-packages/telegram/ext/_updater.py", line 335, in polling_action_cb
    raise exc
  File "/Users/admin/Library/Python/3.9/lib/python/site-packages/telegram/ext/_updater.py", line 320, in polling_action_cb
    updates = await self.bot.get_updates(
  File "/Users/admin/Library/Python/3.9/lib/python/site-packages/telegram/ext/_extbot.py", line 543, in get_updates
    updates = await super().get_updates(
  File "/Users/admin/Library/Python/3.9/lib/python/site-packages/telegram/_bot.py", line 381, in decorator
    result = await func(self, *args, **kwargs)  # skipcq: PYL-E1102
  File "/Users/admin/Library/Python/3.9/lib/python/site-packages/telegram/_bot.py", line 3661, in get_updates
    await self._post(
  File "/Users/admin/Library/Python/3.9/lib/python/site-packages/telegram/_bot.py", line 469, in _post
    return await self._do_post(
  File "/Users/admin/Library/Python/3.9/lib/python/site-packages/telegram/ext/_extbot.py", line 325, in _do_post
    return await super()._do_post(
  File "/Users/admin/Library/Python/3.9/lib/python/site-packages/telegram/_bot.py", line 497, in _do_post
    return await request.post(
  File "/Users/admin/Library/Python/3.9/lib/python/site-packages/telegram/request/_baserequest.py", line 168, in post
    result = await self._request_wrapper(
  File "/Users/admin/Library/Python/3.9/lib/python/site-packages/telegram/request/_baserequest.py", line 330, in _request_wrapper
    raise Conflict(message)
telegram.error.Conflict: Conflict: terminated by other getUpdates request; make sure that only one bot instance is running
2024-12-06 21:08:23,100 - telegram.ext.Updater - ERROR - Error while getting Updates: Conflict: terminated by other getUpdates request; make sure that only one bot instance is running
2024-12-06 21:08:23,100 - telegram.ext.Application - ERROR - No error handlers are registered, logging exception.
Traceback (most recent call last):
  File "/Users/admin/Library/Python/3.9/lib/python/site-packages/telegram/ext/_updater.py", line 607, in _network_loop_retry
    if not await action_cb():
  File "/Users/admin/Library/Python/3.9/lib/python/site-packages/telegram/ext/_updater.py", line 335, in polling_action_cb
    raise exc
  File "/Users/admin/Library/Python/3.9/lib/python/site-packages/telegram/ext/_updater.py", line 320, in polling_action_cb
    updates = await self.bot.get_updates(
  File "/Users/admin/Library/Python/3.9/lib/python/site-packages/telegram/ext/_extbot.py", line 543, in get_updates
    updates = await super().get_updates(
  File "/Users/admin/Library/Python/3.9/lib/python/site-packages/telegram/_bot.py", line 381, in decorator
    result = await func(self, *args, **kwargs)  # skipcq: PYL-E1102
  File "/Users/admin/Library/Python/3.9/lib/python/site-packages/telegram/_bot.py", line 3661, in get_updates
    await self._post(
  File "/Users/admin/Library/Python/3.9/lib/python/site-packages/telegram/_bot.py", line 469, in _post
    return await self._do_post(
  File "/Users/admin/Library/Python/3.9/lib/python/site-packages/telegram/ext/_extbot.py", line 325, in _do_post
    return await super()._do_post(
  File "/Users/admin/Library/Python/3.9/lib/python/site-packages/telegram/_bot.py", line 497, in _do_post
    return await request.post(
  File "/Users/admin/Library/Python/3.9/lib/python/site-packages/telegram/request/_baserequest.py", line 168, in post
    result = await self._request_wrapper(
  File "/Users/admin/Library/Python/3.9/lib/python/site-packages/telegram/request/_baserequest.py", line 330, in _request_wrapper
    raise Conflict(message)
telegram.error.Conflict: Conflict: terminated by other getUpdates request; make sure that only one bot instance is running
2024-12-06 21:08:27,308 - telegram.ext.Updater - ERROR - Error while getting Updates: Conflict: terminated by other getUpdates request; make sure that only one bot instance is running
2024-12-06 21:08:27,309 - telegram.ext.Application - ERROR - No error handlers are registered, logging exception.
Traceback (most recent call last):
  File "/Users/admin/Library/Python/3.9/lib/python/site-packages/telegram/ext/_updater.py", line 607, in _network_loop_retry
    if not await action_cb():
  File "/Users/admin/Library/Python/3.9/lib/python/site-packages/telegram/ext/_updater.py", line 335, in polling_action_cb
    raise exc
  File "/Users/admin/Library/Python/3.9/lib/python/site-packages/telegram/ext/_updater.py", line 320, in polling_action_cb
    updates = await self.bot.get_updates(
  File "/Users/admin/Library/Python/3.9/lib/python/site-packages/telegram/ext/_extbot.py", line 543, in get_updates
    updates = await super().get_updates(
  File "/Users/admin/Library/Python/3.9/lib/python/site-packages/telegram/_bot.py", line 381, in decorator
    result = await func(self, *args, **kwargs)  # skipcq: PYL-E1102
  File "/Users/admin/Library/Python/3.9/lib/python/site-packages/telegram/_bot.py", line 3661, in get_updates
    await self._post(
  File "/Users/admin/Library/Python/3.9/lib/python/site-packages/telegram/_bot.py", line 469, in _post
    return await self._do_post(
  File "/Users/admin/Library/Python/3.9/lib/python/site-packages/telegram/ext/_extbot.py", line 325, in _do_post
    return await super()._do_post(
  File "/Users/admin/Library/Python/3.9/lib/python/site-packages/telegram/_bot.py", line 497, in _do_post
    return await request.post(
  File "/Users/admin/Library/Python/3.9/lib/python/site-packages/telegram/request/_baserequest.py", line 168, in post
    result = await self._request_wrapper(
  File "/Users/admin/Library/Python/3.9/lib/python/site-packages/telegram/request/_baserequest.py", line 330, in _request_wrapper
    raise Conflict(message)
telegram.error.Conflict: Conflict: terminated by other getUpdates request; make sure that only one bot instance is running
2024-12-06 21:08:35,524 - telegram.ext.Updater - ERROR - Error while getting Updates: Conflict: terminated by other getUpdates request; make sure that only one bot instance is running
2024-12-06 21:08:35,524 - telegram.ext.Application - ERROR - No error handlers are registered, logging exception.
Traceback (most recent call last):
  File "/Users/admin/Library/Python/3.9/lib/python/site-packages/telegram/ext/_updater.py", line 607, in _network_loop_retry
    if not await action_cb():
  File "/Users/admin/Library/Python/3.9/lib/python/site-packages/telegram/ext/_updater.py", line 335, in polling_action_cb
    raise exc
  File "/Users/admin/Library/Python/3.9/lib/python/site-packages/telegram/ext/_updater.py", line 320, in polling_action_cb
    updates = await self.bot.get_updates(
  File "/Users/admin/Library/Python/3.9/lib/python/site-packages/telegram/ext/_extbot.py", line 543, in get_updates
    updates = await super().get_updates(
  File "/Users/admin/Library/Python/3.9/lib/python/site-packages/telegram/_bot.py", line 381, in decorator
    result = await func(self, *args, **kwargs)  # skipcq: PYL-E1102
  File "/Users/admin/Library/Python/3.9/lib/python/site-packages/telegram/_bot.py", line 3661, in get_updates
    await self._post(
  File "/Users/admin/Library/Python/3.9/lib/python/site-packages/telegram/_bot.py", line 469, in _post
    return await self._do_post(
  File "/Users/admin/Library/Python/3.9/lib/python/site-packages/telegram/ext/_extbot.py", line 325, in _do_post
    return await super()._do_post(
  File "/Users/admin/Library/Python/3.9/lib/python/site-packages/telegram/_bot.py", line 497, in _do_post
    return await request.post(
  File "/Users/admin/Library/Python/3.9/lib/python/site-packages/telegram/request/_baserequest.py", line 168, in post
    result = await self._request_wrapper(
  File "/Users/admin/Library/Python/3.9/lib/python/site-packages/telegram/request/_baserequest.py", line 330, in _request_wrapper
    raise Conflict(message)
telegram.error.Conflict: Conflict: terminated by other getUpdates request; make sure that only one bot instance is running
2024-12-06 21:08:43,212 - telegram.ext.Updater - ERROR - Error while getting Updates: Conflict: terminated by other getUpdates request; make sure that only one bot instance is running
2024-12-06 21:08:43,213 - telegram.ext.Application - ERROR - No error handlers are registered, logging exception.
Traceback (most recent call last):
  File "/Users/admin/Library/Python/3.9/lib/python/site-packages/telegram/ext/_updater.py", line 607, in _network_loop_retry
    if not await action_cb():
  File "/Users/admin/Library/Python/3.9/lib/python/site-packages/telegram/ext/_updater.py", line 335, in polling_action_cb
    raise exc
  File "/Users/admin/Library/Python/3.9/lib/python/site-packages/telegram/ext/_updater.py", line 320, in polling_action_cb
    updates = await self.bot.get_updates(
  File "/Users/admin/Library/Python/3.9/lib/python/site-packages/telegram/ext/_extbot.py", line 543, in get_updates
    updates = await super().get_updates(
  File "/Users/admin/Library/Python/3.9/lib/python/site-packages/telegram/_bot.py", line 381, in decorator
    result = await func(self, *args, **kwargs)  # skipcq: PYL-E1102
  File "/Users/admin/Library/Python/3.9/lib/python/site-packages/telegram/_bot.py", line 3661, in get_updates
    await self._post(
  File "/Users/admin/Library/Python/3.9/lib/python/site-packages/telegram/_bot.py", line 469, in _post
    return await self._do_post(
  File "/Users/admin/Library/Python/3.9/lib/python/site-packages/telegram/ext/_extbot.py", line 325, in _do_post
    return await super()._do_post(
  File "/Users/admin/Library/Python/3.9/lib/python/site-packages/telegram/_bot.py", line 497, in _do_post
    return await request.post(
  File "/Users/admin/Library/Python/3.9/lib/python/site-packages/telegram/request/_baserequest.py", line 168, in post
    result = await self._request_wrapper(
  File "/Users/admin/Library/Python/3.9/lib/python/site-packages/telegram/request/_baserequest.py", line 330, in _request_wrapper
    raise Conflict(message)
telegram.error.Conflict: Conflict: terminated by other getUpdates request; make sure that only one bot instance is running
2024-12-06 21:08:57,676 - telegram.ext.Updater - ERROR - Error while getting Updates: Conflict: terminated by other getUpdates request; make sure that only one bot instance is running
2024-12-06 21:08:57,677 - telegram.ext.Application - ERROR - No error handlers are registered, logging exception.
Traceback (most recent call last):
  File "/Users/admin/Library/Python/3.9/lib/python/site-packages/telegram/ext/_updater.py", line 607, in _network_loop_retry
    if not await action_cb():
  File "/Users/admin/Library/Python/3.9/lib/python/site-packages/telegram/ext/_updater.py", line 335, in polling_action_cb
    raise exc
  File "/Users/admin/Library/Python/3.9/lib/python/site-packages/telegram/ext/_updater.py", line 320, in polling_action_cb
    updates = await self.bot.get_updates(
  File "/Users/admin/Library/Python/3.9/lib/python/site-packages/telegram/ext/_extbot.py", line 543, in get_updates
    updates = await super().get_updates(
  File "/Users/admin/Library/Python/3.9/lib/python/site-packages/telegram/_bot.py", line 381, in decorator
    result = await func(self, *args, **kwargs)  # skipcq: PYL-E1102
  File "/Users/admin/Library/Python/3.9/lib/python/site-packages/telegram/_bot.py", line 3661, in get_updates
    await self._post(
  File "/Users/admin/Library/Python/3.9/lib/python/site-packages/telegram/_bot.py", line 469, in _post
    return await self._do_post(
  File "/Users/admin/Library/Python/3.9/lib/python/site-packages/telegram/ext/_extbot.py", line 325, in _do_post
    return await super()._do_post(
  File "/Users/admin/Library/Python/3.9/lib/python/site-packages/telegram/_bot.py", line 497, in _do_post
    return await request.post(
  File "/Users/admin/Library/Python/3.9/lib/python/site-packages/telegram/request/_baserequest.py", line 168, in post
    result = await self._request_wrapper(
  File "/Users/admin/Library/Python/3.9/lib/python/site-packages/telegram/request/_baserequest.py", line 330, in _request_wrapper
    raise Conflict(message)
telegram.error.Conflict: Conflict: terminated by other getUpdates request; make sure that only one bot instance is running
2024-12-06 21:09:02,405 - telegram.ext.Updater - ERROR - Error while getting Updates: Conflict: terminated by other getUpdates request; make sure that only one bot instance is running
2024-12-06 21:09:02,405 - telegram.ext.Application - ERROR - No error handlers are registered, logging exception.
Traceback (most recent call last):
  File "/Users/admin/Library/Python/3.9/lib/python/site-packages/telegram/ext/_updater.py", line 607, in _network_loop_retry
    if not await action_cb():
  File "/Users/admin/Library/Python/3.9/lib/python/site-packages/telegram/ext/_updater.py", line 335, in polling_action_cb
    raise exc
  File "/Users/admin/Library/Python/3.9/lib/python/site-packages/telegram/ext/_updater.py", line 320, in polling_action_cb
    updates = await self.bot.get_updates(
  File "/Users/admin/Library/Python/3.9/lib/python/site-packages/telegram/ext/_extbot.py", line 543, in get_updates
    updates = await super().get_updates(
  File "/Users/admin/Library/Python/3.9/lib/python/site-packages/telegram/_bot.py", line 381, in decorator
    result = await func(self, *args, **kwargs)  # skipcq: PYL-E1102
  File "/Users/admin/Library/Python/3.9/lib/python/site-packages/telegram/_bot.py", line 3661, in get_updates
    await self._post(
  File "/Users/admin/Library/Python/3.9/lib/python/site-packages/telegram/_bot.py", line 469, in _post
    return await self._do_post(
  File "/Users/admin/Library/Python/3.9/lib/python/site-packages/telegram/ext/_extbot.py", line 325, in _do_post
    return await super()._do_post(
  File "/Users/admin/Library/Python/3.9/lib/python/site-packages/telegram/_bot.py", line 497, in _do_post
    return await request.post(
  File "/Users/admin/Library/Python/3.9/lib/python/site-packages/telegram/request/_baserequest.py", line 168, in post
    result = await self._request_wrapper(
  File "/Users/admin/Library/Python/3.9/lib/python/site-packages/telegram/request/_baserequest.py", line 330, in _request_wrapper
    raise Conflict(message)
telegram.error.Conflict: Conflict: terminated by other getUpdates request; make sure that only one bot instance is running
2024-12-06 21:09:09,684 - telegram.ext.Updater - ERROR - Error while getting Updates: Conflict: terminated by other getUpdates request; make sure that only one bot instance is running
2024-12-06 21:09:09,684 - telegram.ext.Application - ERROR - No error handlers are registered, logging exception.
Traceback (most recent call last):
  File "/Users/admin/Library/Python/3.9/lib/python/site-packages/telegram/ext/_updater.py", line 607, in _network_loop_retry
    if not await action_cb():
  File "/Users/admin/Library/Python/3.9/lib/python/site-packages/telegram/ext/_updater.py", line 335, in polling_action_cb
    raise exc
  File "/Users/admin/Library/Python/3.9/lib/python/site-packages/telegram/ext/_updater.py", line 320, in polling_action_cb
    updates = await self.bot.get_updates(
  File "/Users/admin/Library/Python/3.9/lib/python/site-packages/telegram/ext/_extbot.py", line 543, in get_updates
    updates = await super().get_updates(
  File "/Users/admin/Library/Python/3.9/lib/python/site-packages/telegram/_bot.py", line 381, in decorator
    result = await func(self, *args, **kwargs)  # skipcq: PYL-E1102
  File "/Users/admin/Library/Python/3.9/lib/python/site-packages/telegram/_bot.py", line 3661, in get_updates
    await self._post(
  File "/Users/admin/Library/Python/3.9/lib/python/site-packages/telegram/_bot.py", line 469, in _post
    return await self._do_post(
  File "/Users/admin/Library/Python/3.9/lib/python/site-packages/telegram/ext/_extbot.py", line 325, in _do_post
    return await super()._do_post(
  File "/Users/admin/Library/Python/3.9/lib/python/site-packages/telegram/_bot.py", line 497, in _do_post
    return await request.post(
  File "/Users/admin/Library/Python/3.9/lib/python/site-packages/telegram/request/_baserequest.py", line 168, in post
    result = await self._request_wrapper(
  File "/Users/admin/Library/Python/3.9/lib/python/site-packages/telegram/request/_baserequest.py", line 330, in _request_wrapper
    raise Conflict(message)
telegram.error.Conflict: Conflict: terminated by other getUpdates request; make sure that only one bot instance is running
2024-12-06 21:09:17,175 - telegram.ext.Updater - ERROR - Error while getting Updates: Conflict: terminated by other getUpdates request; make sure that only one bot instance is running
2024-12-06 21:09:17,176 - telegram.ext.Application - ERROR - No error handlers are registered, logging exception.
Traceback (most recent call last):
  File "/Users/admin/Library/Python/3.9/lib/python/site-packages/telegram/ext/_updater.py", line 607, in _network_loop_retry
    if not await action_cb():
  File "/Users/admin/Library/Python/3.9/lib/python/site-packages/telegram/ext/_updater.py", line 335, in polling_action_cb
    raise exc
  File "/Users/admin/Library/Python/3.9/lib/python/site-packages/telegram/ext/_updater.py", line 320, in polling_action_cb
    updates = await self.bot.get_updates(
  File "/Users/admin/Library/Python/3.9/lib/python/site-packages/telegram/ext/_extbot.py", line 543, in get_updates
    updates = await super().get_updates(
  File "/Users/admin/Library/Python/3.9/lib/python/site-packages/telegram/_bot.py", line 381, in decorator
    result = await func(self, *args, **kwargs)  # skipcq: PYL-E1102
  File "/Users/admin/Library/Python/3.9/lib/python/site-packages/telegram/_bot.py", line 3661, in get_updates
    await self._post(
  File "/Users/admin/Library/Python/3.9/lib/python/site-packages/telegram/_bot.py", line 469, in _post
    return await self._do_post(
  File "/Users/admin/Library/Python/3.9/lib/python/site-packages/telegram/ext/_extbot.py", line 325, in _do_post
    return await super()._do_post(
  File "/Users/admin/Library/Python/3.9/lib/python/site-packages/telegram/_bot.py", line 497, in _do_post
    return await request.post(
  File "/Users/admin/Library/Python/3.9/lib/python/site-packages/telegram/request/_baserequest.py", line 168, in post
    result = await self._request_wrapper(
  File "/Users/admin/Library/Python/3.9/lib/python/site-packages/telegram/request/_baserequest.py", line 330, in _request_wrapper
    raise Conflict(message)
telegram.error.Conflict: Conflict: terminated by other getUpdates request; make sure that only one bot instance is running
